Workbook

Sheet Dane
B2: ID | C2: 3
B3: Wyniki pomiaru wyjściowego | F3: Wyniki pomiaru aktualnego | L3: Współrzedne przybliżone
B4: c | C4: l | D4: p | E4: Lobs. [m] | F4: c | G4: l | H4: p | I4: Lobs. [m] | L4: NR | M4: Xo | N4: Yo
B5: 7 | C5: 1 | D5: 0 | E5: 271.7062 | F5: 7 | G5: 1 | H5: 0 | I5: 271.702 | L5: 1 | M5: 240 | N5: 120
B6: 7 | C6: 5 | D6: 0 | E6: 155.7243 | F6: 7 | G6: 5 | H6: 0 | I6: 155.7279 | L6: 2 | M6: 385 | N6: 145
B7: 7 | C7: 6 | D7: 0 | E7: 178.4659 | F7: 7 | G7: 6 | H7: 0 | I7: 178.4685 | L7: 3 | M7: 475 | N7: 245
B8: 7 | C8: 8 | D8: 0 | E8: 148.0717 | F8: 7 | G8: 8 | H8: 0 | I8: 148.0689 | L8: 4 | M8: 435 | N8: 435
B9: 7 | C9: 9 | D9: 0 | E9: 174.5226 | F9: 7 | G9: 9 | H9: 0 | I9: 174.522 | L9: 5 | M9: 295 | N9: 490
B10: 8 | C10: 1 | D10: 0 | E10: 149.9983 | F10: 8 | G10: 1 | H10: 0 | I10: 150.0006 | L10: 6 | M10: 145 | N10: 560
B11: 8 | C11: 9 | D11: 0 | E11: 166.1118 | F11: 8 | G11: 9 | H11: 0 | I11: 166.1145 | L11: 7 | M11: 180 | N11: 385
B12: 8 | C12: 7 | D12: 0 | E12: 148.0732 | F12: 8 | G12: 7 | H12: 0 | I12: 148.0712 | L12: 8 | M12: 150 | N12: 240
B13: 8 | C13: 6 | D13: 0 | E13: 320.0413 | F13: 8 | G13: 6 | H13: 0 | I13: 320.0445 | L13: 9 | M13: 313 | N13: 272
B14: 1 | C14: 3 | D14: 0 | E14: 266.1756 | F14: 1 | G14: 2 | H14: 0 | I14: 147.1241
B15: 1 | C15: 9 | D15: 0 | E15: 168.6215 | F15: 1 | G15: 9 | H15: 0 | I15: 168.6108 | L15: σβ | M15: 3 | N15: cc
B16: 1 | C16: 7 | D16: 0 | E16: 271.7081 | F16: 1 | G16: 7 | H16: 0 | I16: 271.7008 | L16: σd | M16: 0,001+10-6d | N16: m
B17: 3 | C17: 5 | D17: 0 | E17: 304.0138 | F17: 2 | G17: 8 | H17: 0 | I17: 253.4723
B18: 3 | C18: 9 | D18: 0 | E18: 164.2349 | F18: 2 | G18: 9 | H18: 0 | I18: 145.9865
B19: 3 | C19: 4 | D19: 0 | E19: 194.1629 | F19: 2 | G19: 4 | H19: 0 | I19: 294.2725
B20: 4 | C20: 5 | D20: 0 | E20: 150.4167 | F20: 4 | G20: 5 | H20: 0 | I20: 150.4243
B21: 4 | C21: 7 | D21: 0 | E21: 259.8561 | F21: 4 | G21: 7 | H21: 0 | I21: 259.868
B22: 4 | C22: 9 | D22: 0 | E22: 203.6004 | F22: 4 | G22: 9 | H22: 0 | I22: 203.6019
B23: 6 | C23: 9 | D23: 0 | E23: 333.4194 | F23: 6 | G23: 9 | H23: 0 | I23: 333.4174
B24: 6 | C24: 5 | D24: 0 | E24: 165.528 | F24: 6 | G24: 5 | H24: 0 | I24: 165.5303
B25: 9 | C25: 1 | D25: 3 | E25: 117.9893 | F25: 9 | G25: 1 | H25: 2 | I25: 61.3342
B26: 9 | C26: 3 | D26: 4 | E26: 69.6093 | F26: 9 | G26: 2 | H26: 4 | I26: 126.2606
B27: 9 | C27: 4 | D27: 5 | E27: 46.1487 | F27: 9 | G27: 4 | H27: 5 | I27: 46.1513
B28: 9 | C28: 5 | D28: 7 | E28: 49.92 | F28: 9 | G28: 5 | H28: 7 | I28: 49.9219
... B36: 5 | C36: 9 | D36: 4 | E36: 70.9251 | F36: 5 | G36: 9 | H36: 4 | I36: 70.9246

Sheet Wyrównanie wstępne - wyjściowy
B3: c | C3: l | D3: p | E3: L obs [m] | F3: ∆x | G3: ∆y | H3: L przyb [m] | I3: Az [g] | J3: Sin Az | K3: Cos Az | L3: Błąd [m] | M3: l [m] | P3: Współrzedne przybliżone
B4: =Dane!B5 -> 7 | C4: =Dane!C5 -> 1 | D4: =Dane!D5 -> 0 | E4: =Dane!E5 -> 271.7062 | F4: =Dane!M5-Dane!M11 -> 60 | G4: =Dane!N5-Dane!N11 -> -265 | H4: =SQRT(F4^2+G4^2) -> 271.70756 | I4: =IF(ATAN2(F4,G4)*200/PI()<0,ATAN2(F4,G4)*200/PI()+400) -> 314.17504 | J4: =SIN(I4*PI()/200) -> -0.9753133 | K4: =COS(I4*PI()/200) -> 0.22082565 | L4: =0.001+0.000001*E4 -> 0.0012717062 | M4: =H4-E4 -> 0.0013633839 | P4: NR | Q4: Xo | R4: Yo
B5: =Dane!B6 -> 7 | C5: =Dane!C6 -> 5 | D5: =Dane!D6 -> 0 | E5: =Dane!E6 -> 155.7243 | F5: =Dane!M9-Dane!M11 -> 115 | G5: =Dane!N9-Dane!N11 -> 105 | H5: =SQRT(F5^2+G5^2) -> 155.72412 | I5: =IF(ATAN2(F5,G5)*200/PI()<0,ATAN2(F5,G5)*200/PI()+400,ATAN2(F5,G5)*200/PI()) -> 47.108264 | J5: =SIN(I5*PI()/200) -> 0.67426936 | K5: =COS(I5*PI()/200) -> 0.73848549 | L5: =0.001+0.000001*E5 -> 0.0011557243 | M5: =H5-E5 -> -0.00018497603 | P5: 1 | Q5: 240 | R5: 120
B6: =Dane!B7 -> 7 | C6: =Dane!C7 -> 6 | D6: =Dane!D7 -> 0 | E6: =Dane!E7 -> 178.4659 | F6: =Dane!M10-Dane!M11 -> -35 | G6: =Dane!N10-Dane!N11 -> 175 | H6: =SQRT(F6^2+G6^2) -> 178.46568 | I6: =IF(ATAN2(F6,G6)*200/PI()<0,ATAN2(F6,G6)*200/PI()+400,ATAN2(F6,G6)*200/PI()) -> 112.56659 | J6: =SIN(I6*PI()/200) -> 0.98058068 | K6: =COS(I6*PI()/200) -> -0.19611614 | L6: =0.001+0.000001*E6 -> 0.0011784659 | M6: =H6-E6 -> -0.00021702425 | P6: 2 | Q6: 385 | R6: 145
B7: =Dane!B8 -> 7 | C7: =Dane!C8 -> 8 | D7: =Dane!D8 -> 0 | E7: =Dane!E8 -> 148.0717 | F7: =Dane!M12-Dane!M11 -> -30 | G7: =Dane!N12-Dane!N11 -> -145 | H7: =SQRT(F7^2+G7^2) -> 148.07093 | I7: =IF(ATAN2(F7,G7)*200/PI()<0,ATAN2(F7,G7)*200/PI()+400) -> 287.01181 | J7: =SIN(I7*PI()/200) -> -0.97926042 | K7: =COS(I7*PI()/200) -> -0.2026056 | L7: =0.001+0.000001*E7 -> 0.0011480717 | M7: =H7-E7 -> -0.00077105039 | P7: 3 | Q7: 475 | R7: 245
B8: =Dane!B9 -> 7 | C8: =Dane!C9 -> 9 | D8: =Dane!D9 -> 0 | E8: =Dane!E9 -> 174.5226 | F8: =Dane!M13-Dane!M11 -> 133 | G8: =Dane!N13-Dane!N11 -> -113 | H8: =SQRT(F8^2+G8^2) -> 174.5222 | I8: =IF(ATAN2(F8,G8)*200/PI()<0,ATAN2(F8,G8)*200/PI()+400) -> 355.16441 | J8: =SIN(I8*PI()/200) -> -0.64748208 | K8: =COS(I8*PI()/200) -> 0.76208068 | L8: =0.001+0.000001*E8 -> 0.0011745226 | M8: =H8-E8 -> -0.00039510905 | P8: 4 | Q8: 435 | R8: 435
B9: =Dane!B10 -> 8 | C9: =Dane!C10 -> 1 | D9: =Dane!D10 -> 0 | E9: =Dane!E10 -> 149.9983 | F9: =Dane!M5-Dane!M12 -> 90 | G9: =Dane!N5-Dane!N12 -> -120 | H9: =SQRT(F9^2+G9^2) -> 150 | I9: =IF(ATAN2(F9,G9)*200/PI()<0,ATAN2(F9,G9)*200/PI()+400) -> 340.96655 | J9: =SIN(I9*PI()/200) -> -0.8 | K9: =COS(I9*PI()/200) -> 0.6 | L9: =0.001+0.000001*E9 -> 0.0011499983 | M9: =H9-E9 -> 0.0017 | P9: 5 | Q9: 295 | R9: 490
B10: =Dane!B11 -> 8 | C10: =Dane!C11 -> 9 | D10: =Dane!D11 -> 0 | E10: =Dane!E11 -> 166.1118 | F10: =Dane!M13-Dane!M12 -> 163 | G10: =Dane!N13-Dane!N12 -> 32 | H10: =SQRT(F10^2+G10^2) -> 166.11141 | I10: =IF(ATAN2(F10,G10)*200/PI()<0,ATAN2(F10,G10)*200/PI()+400,ATAN2(F10,G10)*200/PI()) -> 12.341107 | J10: =SIN(I10*PI()/200) -> 0.1926418 | K10: =COS(I10*PI()/200) -> 0.98126915 | L10: =0.001+0.000001*E10 -> 0.0011661118 | M10: =H10-E10 -> -0.0003916019 | P10: 6 | Q10: 145 | R10: 560
B11: =Dane!B12 -> 8 | C11: =Dane!C12 -> 7 | D11: =Dane!D12 -> 0 | E11: =Dane!E12 -> 148.0732 | F11: =Dane!M11-Dane!M12 -> 30 | G11: =Dane!N11-Dane!N12 -> 145 | H11: =SQRT(F11^2+G11^2) -> 148.07093 | I11: =IF(ATAN2(F11,G11)*200/PI()<0,ATAN2(F11,G11)*200/PI()+400,ATAN2(F11,G11)*200/PI()) -> 87.011812 | J11: =SIN(I11*PI()/200) -> 0.97926042 | K11: =COS(I11*PI()/200) -> 0.2026056 | L11: =0.001+0.000001*E11 -> 0.0011480732 | M11: =H11-E11 -> -0.0022710504 | P11: 7 | Q11: 180 | R11: 385
B12: =Dane!B13 -> 8 | C12: =Dane!C13 -> 6 | D12: =Dane!D13 -> 0 | E12: =Dane!E13 -> 320.0413 | F12: =Dane!M10-Dane!M12 -> -5 | G12: =Dane!N10-Dane!N12 -> 320 | H12: =SQRT(F12^2+G12^2) -> 320.03906 | I12: =IF(ATAN2(F12,G12)*200/PI()<0,ATAN2(F12,G12)*200/PI()+400,ATAN2(F12,G12)*200/PI()) -> 100.99464 | J12: =SIN(I12*PI()/200) -> 0.99987795 | K12: =COS(I12*PI()/200) -> -0.015623093 | L12: =0.001+0.000001*E12 -> 0.0013200413 | M12: =H12-E12 -> -0.0022398839 | P12: 8 | Q12: 150 | R12: 240
B13: =Dane!B14 -> 1 | C13: =Dane!C14 -> 3 | D13: =Dane!D14 -> 0 | E13: =Dane!E14 -> 266.1756 | F13: =Dane!M7-Dane!M5 -> 235 | G13: =Dane!N7-Dane!N5 -> 125 | H13: =SQRT(F13^2+G13^2) -> 266.17663 | I13: =IF(ATAN2(F13,G13)*200/PI()<0,ATAN2(F13,G13)*200/PI()+400,ATAN2(F13,G13)*200/PI()) -> 31.121307 | J13: =SIN(I13*PI()/200) -> 0.46961297 | K13: =COS(I13*PI()/200) -> 0.88287239 | L13: =0.001+0.000001*E13 -> 0.0012661756 | M13: =H13-E13 -> 0.0010330841 | P13: 9 | Q13: 314 | R13: 271
B14: =Dane!B15 -> 1 | C14: =Dane!C15 -> 9 | D14: =Dane!D15 -> 0 | E14: =Dane!E15 -> 168.6215 | F14: =Dane!M13-Dane!M5 -> 73 | G14: =Dane!N13-Dane!N5 -> 152 | H14: =SQRT(F14^2+G14^2) -> 168.62088 | I14: =IF(ATAN2(F14,G14)*200/PI()<0,ATAN2(F14,G14)*200/PI()+400,ATAN2(F14,G14)*200/PI()) -> 71.496379 | J14: =SIN(I14*PI()/200) -> 0.90143049 | K14: =COS(I14*PI()/200) -> 0.43292386 | L14: =0.001+0.000001*E14 -> 0.0011686215 | M14: =H14-E14 -> -0.00062347518
B15: =Dane!B16 -> 1 | C15: =Dane!C16 -> 7 | D15: =Dane!D16 -> 0 | E15: =Dane!E16 -> 271.7081 | F15: =Dane!M11-Dane!M5 -> -60 | G15: =Dane!N11-Dane!N5 -> 265 | H15: =SQRT(F15^2+G15^2) -> 271.70756 | I15: =IF(ATAN2(F15,G15)*200/PI()<0,ATAN2(F15,G15)*200/PI()+400,ATAN2(F15,G15)*200/PI()) -> 114.17504 | J15: =SIN(I15*PI()/200) -> 0.9753133 | K15: =COS(I15*PI()/200) -> -0.22082565 | L15: =0.001+0.000001*E15 -> 0.0012717081 | M15: =H15-E15 -> -0.00053661613
B16: =Dane!B17 -> 3 | C16: =Dane!C17 -> 5 | D16: =Dane!D17 -> 0 | E16: =Dane!E17 -> 304.0138 | F16: =Dane!M9-Dane!M7 -> -180 | G16: =Dane!N9-Dane!N7 -> 245 | H16: =SQRT(F16^2+G16^2) -> 304.0148 | I16: =IF(ATAN2(F16,G16)*200/PI()<0,ATAN2(F16,G16)*200/PI()+400,ATAN2(F16,G16)*200/PI()) -> 140.33833 | J16: =SIN(I16*PI()/200) -> 0.80588181 | K16: =COS(I16*PI()/200) -> -0.59207643 | L16: =0.001+0.000001*E16 -> 0.0013040138 | M16: =H16-E16 -> 0.0010022712
B17: =Dane!B18 -> 3 | C17: =Dane!C18 -> 9 | D17: =Dane!D18 -> 0 | E17: =Dane!E18 -> 164.2349 | F17: =Dane!M13-Dane!M7 -> -162 | G17: =Dane!N13-Dane!N7 -> 27 | H17: =SQRT(F17^2+G17^2) -> 164.23459 | I17: =IF(ATAN2(F17,G17)*200/PI()<0,ATAN2(F17,G17)*200/PI()+400,ATAN2(F17,G17)*200/PI()) -> 189.48631 | J17: =SIN(I17*PI()/200) -> 0.16439899 | K17: =COS(I17*PI()/200) -> -0.98639392 | L17: =0.001+0.000001*E17 -> 0.0011642349 | M17: =H17-E17 -> -0.00031168195
B18: =Dane!B19 -> 3 | C18: =Dane!C19 -> 4 | D18: =Dane!D19 -> 0 | E18: =Dane!E19 -> 194.1629 | F18: =Dane!M8-Dane!M7 -> -40 | G18: =Dane!N8-Dane!N7 -> 190 | H18: =SQRT(F18^2+G18^2) -> 194.16488 | I18: =IF(ATAN2(F18,G18)*200/PI()<0,ATAN2(F18,G18)*200/PI()+400,ATAN2(F18,G18)*200/PI()) -> 113.20962 | J18: =SIN(I18*PI()/200) -> 0.97854978 | K18: =COS(I18*PI()/200) -> -0.20601048 | L18: =0.001+0.000001*E18 -> 0.0011941629 | M18: =H18-E18 -> 0.0019783895
B19: =Dane!B20 -> 4 | C19: =Dane!C20 -> 5 | D19: =Dane!D20 -> 0 | E19: =Dane!E20 -> 150.4167 | F19: =Dane!M9-Dane!M8 -> -140 | G19: =Dane!N9-Dane!N8 -> 55 | H19: =SQRT(F19^2+G19^2) -> 150.41609 | I19: =IF(ATAN2(F19,G19)*200/PI()<0,ATAN2(F19,G19)*200/PI()+400,ATAN2(F19,G19)*200/PI()) -> 176.16918 | J19: =SIN(I19*PI()/200) -> 0.36565237 | K19: =COS(I19*PI()/200) -> -0.93075149 | L19: =0.001+0.000001*E19 -> 0.0011504167 | M19: =H19-E19 -> -0.00061043509
B20: =Dane!B21 -> 4 | C20: =Dane!C21 -> 7 | D20: =Dane!D21 -> 0 | E20: =Dane!E21 -> 259.8561 | F20: =Dane!M11-Dane!M8 -> -255 | G20: =Dane!N11-Dane!N8 -> -50 | H20: =SQRT(F20^2+G20^2) -> 259.85573 | I20: =IF(ATAN2(F20,G20)*200/PI()<0,ATAN2(F20,G20)*200/PI()+400) -> 212.32636 | J20: =SIN(I20*PI()/200) -> -0.19241446 | K20: =COS(I20*PI()/200) -> -0.98131375 | L20: =0.001+0.000001*E20 -> 0.0012598561 | M20: =H20-E20 -> -0.00037079627
B21: =Dane!B22 -> 4 | C21: =Dane!C22 -> 9 | D21: =Dane!D22 -> 0 | E21: =Dane!E22 -> 203.6004 | F21: =Dane!M13-Dane!M8 -> -122 | G21: =Dane!N13-Dane!N8 -> -163 | H21: =SQRT(F21^2+G21^2) -> 203.6001 | I21: =IF(ATAN2(F21,G21)*200/PI()<0,ATAN2(F21,G21)*200/PI()+400) -> 259.09598 | J21: =SIN(I21*PI()/200) -> -0.800589 | K21: =COS(I21*PI()/200) -> -0.59921386 | L21: =0.001+0.000001*E21 -> 0.0012036004 | M21: =H21-E21 -> -0.0003017682
B22: =Dane!B23 -> 6 | C22: =Dane!C23 -> 9 | D22: =Dane!D23 -> 0 | E22: =Dane!E23 -> 333.4194 | F22: =Dane!M13-Dane!M10 -> 168 | G22: =Dane!N13-Dane!N10 -> -288 | H22: =SQRT(F22^2+G22^2) -> 333.41866 | I22: =IF(ATAN2(F22,G22)*200/PI()<0,ATAN2(F22,G22)*200/PI()+400) -> 333.61826 | J22: =SIN(I22*PI()/200) -> -0.8637789 | K22: =COS(I22*PI()/200) -> 0.50387103 | L22: =0.001+0.000001*E22 -> 0.0013334194 | M22: =H22-E22 -> -0.0007442532
B23: =Dane!B24 -> 6 | C23: =Dane!C24 -> 5 | D23: =Dane!D24 -> 0 | E23: =Dane!E24 -> 165.528 | F23: =Dane!M9-Dane!M10 -> 150 | G23: =Dane!N9-Dane!N10 -> -70 | H23: =SQRT(F23^2+G23^2) -> 165.52945 | I23: =IF(ATAN2(F23,G23)*200/PI()<0,ATAN2(F23,G23)*200/PI()+400) -> 372.20345 | J23: =SIN(I23*PI()/200) -> -0.42288547 | K23: =COS(I23*PI()/200) -> 0.90618314 | L23: =0.001+0.000001*E23 -> 0.001165528 | M23: =H23-E23 -> 0.0014535725
B25: c | C25: l | D25: p | E25: b obs [g] | F25: ∆xcl | G25: ∆ycl | H25: ∆xcp | I25: ∆ycp | J25: d²cl | K25: d²cp | L25: Az cl [g] | M25: Az cp [g] | N25: b przyb [g] | O25: Błąd [cc] | P25: l [g] | Q25: Al. | R25: Bl | S25: Ap | T25: Bp
B26: =Dane!B25 -> 9 | C26: =Dane!C25 -> 1 | D26: =Dane!D25 -> 3 | E26: =Dane!E25 -> 117.9893 | F26: =Dane!M5-Dane!M13 -> -73 | G26: =Dane!N5-Dane!N13 -> -152 | H26: =Dane!M7-Dane!M13 -> 162 | I26: =Dane!N7-Dane!N13 -> -27 | J26: =F26^2+G26^2 -> 28433 | K26: =H26^2+I26^2 -> 26973 | L26: =IF(ATAN2(F26,G26)*200/PI()<0,ATAN2(F26,G26)*200/PI()+400,ATAN2(F26,G26)*200/PI()) -> 271.49638 | M26: =IF(ATAN2(H26,I26)*200/PI()<0,ATAN2(H26,I26)*200/PI()+400,ATAN2(H26,I26)*200/PI()) -> 389.48631 | N26: =IF(M26-L26<0,M26-L26+400,M26-L26) -> 117.98993 | O26: =Dane!$M$15 -> 3 | P26: =N26-E26 -> 0.00062975201 | Q26: =F26/J26*2000000/PI() -> -1634.4826 | R26: =G26/J26*2000000/PI() -> -3403.3062 | S26: =H26/K26*2000000/PI() -> 3823.5422 | T26: =I26/K26*2000000/PI() -> -637.25703
B27: =Dane!B26 -> 9 | C27: =Dane!C26 -> 3 | D27: =Dane!D26 -> 4 | E27: =Dane!E26 -> 69.6093 | F27: =Dane!M7-Dane!M13 -> 162 | G27: =Dane!N7-Dane!N13 -> -27 | H27: =Dane!M8-Dane!M13 -> 122 | I27: =Dane!N8-Dane!N13 -> 163 | J27: =F27^2+G27^2 -> 26973 | K27: =H27^2+I27^2 -> 41453 | L27: =IF(ATAN2(F27,G27)*200/PI()<0,ATAN2(F27,G27)*200/PI()+400,ATAN2(F27,G27)*200/PI()) -> 389.48631 | M27: =IF(ATAN2(H27,I27)*200/PI()<0,ATAN2(H27,I27)*200/PI()+400,ATAN2(H27,I27)*200/PI()) -> 59.095983 | N27: =IF(M27-L27<0,M27-L27+400,M27-L27) -> 69.609675 | O27: =Dane!$M$15 -> 3 | P27: =N27-E27 -> 0.00037470572 | Q27: =F27/J27*2000000/PI() -> 3823.5422 | R27: =G27/J27*2000000/PI() -> -637.25703 | S27: =H27/K27*2000000/PI() -> 1873.6307 | T27: =I27/K27*2000000/PI() -> 2503.2934
B28: =Dane!B27 -> 9 | C28: =Dane!C27 -> 4 | D28: =Dane!D27 -> 5 | E28: =Dane!E27 -> 46.1487 | F28: =Dane!M8-Dane!M13 -> 122 | G28: =Dane!N8-Dane!N13 -> 163 | H28: =Dane!M9-Dane!M13 -> -18 | I28: =Dane!N9-Dane!N13 -> 218 | J28: =F28^2+G28^2 -> 41453 | K28: =H28^2+I28^2 -> 47848 | L28: =IF(ATAN2(F28,G28)*200/PI()<0,ATAN2(F28,G28)*200/PI()+400,ATAN2(F28,G28)*200/PI()) -> 59.095983 | M28: =IF(ATAN2(H28,I28)*200/PI()<0,ATAN2(H28,I28)*200/PI()+400,ATAN2(H28,I28)*200/PI()) -> 105.2446 | N28: =IF(M28-L28<0,M28-L28+400,M28-L28) -> 46.148613 | O28: =Dane!$M$15 -> 3 | P28: =N28-E28 -> -8.6773425e-05 | Q28: =F28/J28*2000000/PI() -> 1873.6307 | R28: =G28/J28*2000000/PI() -> 2503.2934 | S28: =H28/K28*2000000/PI() -> -239.4908 | T28: =I28/K28*2000000/PI() -> 2900.4997
B29: =Dane!B28 -> 9 | C29: =Dane!C28 -> 5 | D29: =Dane!D28 -> 7 | E29: =Dane!E28 -> 49.92 | F29: =Dane!M9-Dane!M13 -> -18 | G29: =Dane!N9-Dane!N13 -> 218 | H29: =Dane!M11-Dane!M13 -> -133 | I29: =Dane!N11-Dane!N13 -> 113 | J29: =F29^2+G29^2 -> 47848 | K29: =H29^2+I29^2 -> 30458 | L29: =IF(ATAN2(F29,G29)*200/PI()<0,ATAN2(F29,G29)*200/PI()+400,ATAN2(F29,G29)*200/PI()) -> 105.2446 | M29: =IF(ATAN2(H29,I29)*200/PI()<0,ATAN2(H29,I29)*200/PI()+400,ATAN2(H29,I29)*200/PI()) -> 155.16441 | N29: =IF(M29-L29<0,M29-L29+400,M29-L29) -> 49.919815 | O29: =Dane!$M$15 -> 3 | P29: =N29-E29 -> -0.00018471073 | Q29: =F29/J29*2000000/PI() -> -239.4908 | R29: =G29/J29*2000000/PI() -> 2900.4997 | S29: =H29/K29*2000000/PI() -> -2779.9077 | T29: =I29/K29*2000000/PI() -> 2361.8765
B30: =Dane!B29 -> 9 | C30: =Dane!C29 -> 7 | D30: =Dane!D29 -> 8 | E30: =Dane!E29 -> 57.1766 | F30: =Dane!M11-Dane!M13 -> -133 | G30: =Dane!N11-Dane!N13 -> 113 | H30: =Dane!M12-Dane!M13 -> -163 | I30: =Dane!N12-Dane!N13 -> -32 | J30: =F30^2+G30^2 -> 30458 | K30: =H30^2+I30^2 -> 27593 | L30: =IF(ATAN2(F30,G30)*200/PI()<0,ATAN2(F30,G30)*200/PI()+400,ATAN2(F30,G30)*200/PI()) -> 155.16441 | M30: =IF(ATAN2(H30,I30)*200/PI()<0,ATAN2(H30,I30)*200/PI()+400,ATAN2(H30,I30)*200/PI()) -> 212.34111 | N30: =IF(M30-L30<0,M30-L30+400,M30-L30) -> 57.176696 | O30: =Dane!$M$15 -> 3 | P30: =N30-E30 -> 9.5539984e-05 | Q30: =F30/J30*2000000/PI() -> -2779.9077 | R30: =G30/J30*2000000/PI() -> 2361.8765 | S30: =H30/K30*2000000/PI() -> -3760.701 | T30: =I30/K30*2000000/PI() -> -738.29713
B31: =Dane!B30 -> 9 | C31: =Dane!C30 -> 8 | D31: =Dane!D30 -> 1 | E31: =Dane!E30 -> 59.1555 | F31: =Dane!M12-Dane!M13 -> -163 | G31: =Dane!N12-Dane!N13 -> -32 | H31: =Dane!M5-Dane!M13 -> -73 | I31: =Dane!N5-Dane!N13 -> -152 | J31: =F31^2+G31^2 -> 27593 | K31: =H31^2+I31^2 -> 28433 | L31: =IF(ATAN2(F31,G31)*200/PI()<0,ATAN2(F31,G31)*200/PI()+400,ATAN2(F31,G31)*200/PI()) -> 212.34111 | M31: =IF(ATAN2(H31,I31)*200/PI()<0,ATAN2(H31,I31)*200/PI()+400,ATAN2(H31,I31)*200/PI()) -> 271.49638 | N31: =IF(M31-L31<0,M31-L31+400,M31-L31) -> 59.155271 | O31: =Dane!$M$15 -> 3 | P31: =N31-E31 -> -0.00022851356 | Q31: =F31/J31*2000000/PI() -> -3760.701 | R31: =G31/J31*2000000/PI() -> -738.29713 | S31: =H31/K31*2000000/PI() -> -1634.4826 | T31: =I31/K31*2000000/PI() -> -3403.3062
B32: =Dane!B31 -> 6 | C32: =Dane!C31 -> 8 | D32: =Dane!D31 -> 7 | E32: =Dane!E31 -> 11.5719 | F32: =Dane!M12-Dane!M10 -> 5 | G32: =Dane!N12-Dane!N10 -> -320 | H32: =Dane!M11-Dane!M10 -> 35 | I32: =Dane!N11-Dane!N10 -> -175 | J32: =F32^2+G32^2 -> 102425 | K32: =H32^2+I32^2 -> 31850 | L32: =IF(ATAN2(F32,G32)*200/PI()<0,ATAN2(F32,G32)*200/PI()+400,ATAN2(F32,G32)*200/PI()) -> 300.99464 | M32: =IF(ATAN2(H32,I32)*200/PI()<0,ATAN2(H32,I32)*200/PI()+400,ATAN2(H32,I32)*200/PI()) -> 312.56659 | N32: =IF(M32-L32<0,M32-L32+400,M32-L32) -> 11.571954 | O32: =Dane!$M$15 -> 3 | P32: =N32-E32 -> 5.418201e-05 | Q32: =F32/J32*2000000/PI() -> 31.077363 | R32: =G32/J32*2000000/PI() -> -1988.9512 | S32: =H32/K32*2000000/PI() -> 699.58217 | T32: =I32/K32*2000000/PI() -> -3497.9108
B33: =Dane!B32 -> 6 | C33: =Dane!C32 -> 7 | D33: =Dane!D32 -> 9 | E33: =Dane!E32 -> 21.0515 | F33: =Dane!M11-Dane!M10 -> 35 | G33: =Dane!N11-Dane!N10 -> -175 | H33: =Dane!M13-Dane!M10 -> 168 | I33: =Dane!N13-Dane!N10 -> -288 | J33: =F33^2+G33^2 -> 31850 | K33: =H33^2+I33^2 -> 111168 | L33: =IF(ATAN2(F33,G33)*200/PI()<0,ATAN2(F33,G33)*200/PI()+400,ATAN2(F33,G33)*200/PI()) -> 312.56659 | M33: =IF(ATAN2(H33,I33)*200/PI()<0,ATAN2(H33,I33)*200/PI()+400,ATAN2(H33,I33)*200/PI()) -> 333.61826 | N33: =IF(M33-L33<0,M33-L33+400,M33-L33) -> 21.051672 | O33: =Dane!$M$15 -> 3 | P33: =N33-E33 -> 0.00017187723 | Q33: =F33/J33*2000000/PI() -> 699.58217 | R33: =G33/J33*2000000/PI() -> -3497.9108 | S33: =H33/K33*2000000/PI() -> 962.07651 | T33: =I33/K33*2000000/PI() -> -1649.274
B34: =Dane!B33 -> 6 | C34: =Dane!C33 -> 9 | D34: =Dane!D33 -> 5 | E34: =Dane!E33 -> 38.5847 | F34: =Dane!M13-Dane!M10 -> 168 | G34: =Dane!N13-Dane!N10 -> -288 | H34: =Dane!M9-Dane!M10 -> 150 | I34: =Dane!N9-Dane!N10 -> -70 | J34: =F34^2+G34^2 -> 111168 | K34: =H34^2+I34^2 -> 27400 | L34: =IF(ATAN2(F34,G34)*200/PI()<0,ATAN2(F34,G34)*200/PI()+400,ATAN2(F34,G34)*200/PI()) -> 333.61826 | M34: =IF(ATAN2(H34,I34)*200/PI()<0,ATAN2(H34,I34)*200/PI()+400,ATAN2(H34,I34)*200/PI()) -> 372.20345 | N34: =IF(M34-L34<0,M34-L34+400,M34-L34) -> 38.585188 | O34: =Dane!$M$15 -> 3 | P34: =N34-E34 -> 0.00048817597 | Q34: =F34/J34*2000000/PI() -> 962.07651 | R34: =G34/J34*2000000/PI() -> -1649.274 | S34: =H34/K34*2000000/PI() -> 3485.1447 | T34: =I34/K34*2000000/PI() -> -1626.4009
B35: =Dane!B34 -> 5 | C35: =Dane!C34 -> 6 | D35: =Dane!D34 -> 7 | E35: =Dane!E34 -> 74.9047 | F35: =Dane!M10-Dane!M9 -> -150 | G35: =Dane!N10-Dane!N9 -> 70 | H35: =Dane!M11-Dane!M9 -> -115 | I35: =Dane!N11-Dane!N9 -> -105 | J35: =F35^2+G35^2 -> 27400 | K35: =H35^2+I35^2 -> 24250 | L35: =IF(ATAN2(F35,G35)*200/PI()<0,ATAN2(F35,G35)*200/PI()+400,ATAN2(F35,G35)*200/PI()) -> 172.20345 | M35: =IF(ATAN2(H35,I35)*200/PI()<0,ATAN2(H35,I35)*200/PI()+400,ATAN2(H35,I35)*200/PI()) -> 247.10826 | N35: =IF(M35-L35<0,M35-L35+400,M35-L35) -> 74.904813 | O35: =Dane!$M$15 -> 3 | P35: =N35-E35 -> 0.00011252844 | Q35: =F35/J35*2000000/PI() -> -3485.1447 | R35: =G35/J35*2000000/PI() -> 1626.4009 | S35: =H35/K35*2000000/PI() -> -3019.0216 | T35: =I35/K35*2000000/PI() -> -2756.498
B36: =Dane!B35 -> 5 | C36: =Dane!C35 -> 7 | D36: =Dane!D35 -> 9 | E36: =Dane!E35 -> 58.1366 | F36: =Dane!M11-Dane!M9 -> -115 | G36: =Dane!N11-Dane!N9 -> -105 | H36: =Dane!M13-Dane!M9 -> 18 | I36: =Dane!N13-Dane!N9 -> -218 | J36: =F36^2+G36^2 -> 24250 | K36: =H36^2+I36^2 -> 47848 | L36: =IF(ATAN2(F36,G36)*200/PI()<0,ATAN2(F36,G36)*200/PI()+400,ATAN2(F36,G36)*200/PI()) -> 247.10826 | M36: =IF(ATAN2(H36,I36)*200/PI()<0,ATAN2(H36,I36)*200/PI()+400,ATAN2(H36,I36)*200/PI()) -> 305.2446 | N36: =IF(M36-L36<0,M36-L36+400,M36-L36) -> 58.136332 | O36: =Dane!$M$15 -> 3 | P36: =N36-E36 -> -0.0002676294 | Q36: =F36/J36*2000000/PI() -> -3019.0216 | R36: =G36/J36*2000000/PI() -> -2756.498 | S36: =H36/K36*2000000/PI() -> 239.4908 | T36: =I36/K36*2000000/PI() -> -2900.4997
B37: =Dane!B36 -> 5 | C37: =Dane!C36 -> 9 | D37: =Dane!D36 -> 4 | E37: =Dane!E36 -> 70.9251 | F37: =Dane!M13-Dane!M9 -> 18 | G37: =Dane!N13-Dane!N9 -> -218 | H37: =Dane!M8-Dane!M9 -> 140 | I37: =Dane!N8-Dane!N9 -> -55 | J37: =F37^2+G37^2 -> 47848 | K37: =H37^2+I37^2 -> 22625 | L37: =IF(ATAN2(F37,G37)*200/PI()<0,ATAN2(F37,G37)*200/PI()+400,ATAN2(F37,G37)*200/PI()) -> 305.2446 | M37: =IF(ATAN2(H37,I37)*200/PI()<0,ATAN2(H37,I37)*200/PI()+400,ATAN2(H37,I37)*200/PI()) -> 376.16918 | N37: =IF(M37-L37<0,M37-L37+400,M37-L37) -> 70.924585 | O37: =Dane!$M$15 -> 3 | P37: =N37-E37 -> -0.00051473128 | Q37: =F37/J37*2000000/PI() -> 239.4908 | R37: =G37/J37*2000000/PI() -> -2900.4997 | S37: =H37/K37*2000000/PI() -> 3939.3047 | T37: =I37/K37*2000000/PI() -> -1547.584
B39: a | S39: l [m/cc]
B40: dx | C40: dy | D40: dx | E40: dy | F40: dx | G40: dy | H40: dx | I40: dy | J40: dx | K40: dy | L40: dx | M40: dy | N40: dx | O40: dy | P40: dx | Q40: dy
B41: 1 | C41: 1 | D41: 3 | E41: 3 | F41: 4 | G41: 4 | H41: 5 | I41: 5 | J41: 6 | K41: 6 | L41: 7 | M41: 7 | N41: 8 | O41: 8 | P41: 9 | Q41: 9
B42: =IF(B$41=$B4,IF(B$40="dx",-$K4,-$J4),IF(B$41=$C4,IF(B$40="dx",$K4,$J4),0)) -> 0.22082565 | C42: =IF(C$41=$B4,IF(C$40="dx",-$K4,-$J4),IF(C$41=$C4,IF(C$40="dx",$K4,$J4),0)) -> -0.9753133 | D42: =IF(D$41=$B4,IF(D$40="dx",-$K4,-$J4),IF(D$41=$C4,IF(D$40="dx",$K4,$J4),0)) -> 0 | E42: =IF(E$41=$B4,IF(E$40="dx",-$K4,-$J4),IF(E$41=$C4,IF(E$40="dx",$K4,$J4),0)) -> 0 | F42: =IF(F$41=$B4,IF(F$40="dx",-$K4,-$J4),IF(F$41=$C4,IF(F$40="dx",$K4,$J4),0)) -> 0 | G42: =IF(G$41=$B4,IF(G$40="dx",-$K4,-$J4),IF(G$41=$C4,IF(G$40="dx",$K4,$J4),0)) -> 0 | H42: =IF(H$41=$B4,IF(H$40="dx",-$K4,-$J4),IF(H$41=$C4,IF(H$40="dx",$K4,$J4),0)) -> 0 | I42: =IF(I$41=$B4,IF(I$40="dx",-$K4,-$J4),IF(I$41=$C4,IF(I$40="dx",$K4,$J4),0)) -> 0 | ... Q42: =IF(Q$41=$B4,IF(Q$40="dx",-$K4,-$J4),IF(Q$41=$C4,IF(Q$40="dx",$K4,$J4),0)) -> 0 | S42: =M4 -> 0.0013633839
B43: =IF(B$41=$B5,IF(B$40="dx",-$K5,-$J5),IF(B$41=$C5,IF(B$40="dx",$K5,$J5),0)) -> 0 | C43: =IF(C$41=$B5,IF(C$40="dx",-$K5,-$J5),IF(C$41=$C5,IF(C$40="dx",$K5,$J5),0)) -> 0 | D43: =IF(D$41=$B5,IF(D$40="dx",-$K5,-$J5),IF(D$41=$C5,IF(D$40="dx",$K5,$J5),0)) -> 0 | E43: =IF(E$41=$B5,IF(E$40="dx",-$K5,-$J5),IF(E$41=$C5,IF(E$40="dx",$K5,$J5),0)) -> 0 | F43: =IF(F$41=$B5,IF(F$40="dx",-$K5,-$J5),IF(F$41=$C5,IF(F$40="dx",$K5,$J5),0)) -> 0 | G43: =IF(G$41=$B5,IF(G$40="dx",-$K5,-$J5),IF(G$41=$C5,IF(G$40="dx",$K5,$J5),0)) -> 0 | H43: =IF(H$41=$B5,IF(H$40="dx",-$K5,-$J5),IF(H$41=$C5,IF(H$40="dx",$K5,$J5),0)) -> 0.73848549 | I43: =IF(I$41=$B5,IF(I$40="dx",-$K5,-$J5),IF(I$41=$C5,IF(I$40="dx",$K5,$J5),0)) -> 0.67426936 | ... Q43: =IF(Q$41=$B5,IF(Q$40="dx",-$K5,-$J5),IF(Q$41=$C5,IF(Q$40="dx",$K5,$J5),0)) -> 0 | S43: =M5 -> -0.00018497603
B44: =IF(B$41=$B6,IF(B$40="dx",-$K6,-$J6),IF(B$41=$C6,IF(B$40="dx",$K6,$J6),0)) -> 0 | C44: =IF(C$41=$B6,IF(C$40="dx",-$K6,-$J6),IF(C$41=$C6,IF(C$40="dx",$K6,$J6),0)) -> 0 | D44: =IF(D$41=$B6,IF(D$40="dx",-$K6,-$J6),IF(D$41=$C6,IF(D$40="dx",$K6,$J6),0)) -> 0 | E44: =IF(E$41=$B6,IF(E$40="dx",-$K6,-$J6),IF(E$41=$C6,IF(E$40="dx",$K6,$J6),0)) -> 0 | F44: =IF(F$41=$B6,IF(F$40="dx",-$K6,-$J6),IF(F$41=$C6,IF(F$40="dx",$K6,$J6),0)) -> 0 | G44: =IF(G$41=$B6,IF(G$40="dx",-$K6,-$J6),IF(G$41=$C6,IF(G$40="dx",$K6,$J6),0)) -> 0 | H44: =IF(H$41=$B6,IF(H$40="dx",-$K6,-$J6),IF(H$41=$C6,IF(H$40="dx",$K6,$J6),0)) -> 0 | I44: =IF(I$41=$B6,IF(I$40="dx",-$K6,-$J6),IF(I$41=$C6,IF(I$40="dx",$K6,$J6),0)) -> 0 | ... Q44: =IF(Q$41=$B6,IF(Q$40="dx",-$K6,-$J6),IF(Q$41=$C6,IF(Q$40="dx",$K6,$J6),0)) -> 0 | S44: =M6 -> -0.00021702425
...

Sheet Wyrównanie wstępne - aktualny
B3: c | C3: l | D3: p | E3: L obs [m] | F3: ∆x | G3: ∆y | H3: L przyb [m] | I3: Az [g] | J3: Sin Az | K3: Cos Az | L3: Błąd [m] | M3: l [m] | P3: Współrzedne przybliżone
B4: =Dane!F5 -> 7 | C4: =Dane!G5 -> 1 | D4: =Dane!H5 -> 0 | E4: =Dane!I5 -> 271.702 | F4: =Dane!M5-Dane!M11 -> 60 | G4: =Dane!N5-Dane!N11 -> -265 | H4: =SQRT(F4^2+G4^2) -> 271.70756 | I4: =IF(ATAN2(F4,G4)*200/PI()<0,ATAN2(F4,G4)*200/PI()+400) -> 314.17504 | J4: =SIN(I4*PI()/200) -> -0.9753133 | K4: =COS(I4*PI()/200) -> 0.22082565 | L4: =0.001+0.000001*E4 -> 0.001271702 | M4: =H4-E4 -> 0.0055633839 | P4: NR | Q4: Xo | R4: Yo
B5: =Dane!F6 -> 7 | C5: =Dane!G6 -> 5 | D5: =Dane!H6 -> 0 | E5: =Dane!I6 -> 155.7279 | F5: =Dane!M9-Dane!M11 -> 115 | G5: =Dane!N9-Dane!N11 -> 105 | H5: =SQRT(F5^2+G5^2) -> 155.72412 | I5: =IF(ATAN2(F5,G5)*200/PI()<0,ATAN2(F5,G5)*200/PI()+400,ATAN2(F5,G5)*200/PI()) -> 47.108264 | J5: =SIN(I5*PI()/200) -> 0.67426936 | K5: =COS(I5*PI()/200) -> 0.73848549 | L5: =0.001+0.000001*E5 -> 0.0011557279 | M5: =H5-E5 -> -0.003784976 | P5: 1 | Q5: 240 | R5: 120
B6: =Dane!F7 -> 7 | C6: =Dane!G7 -> 6 | D6: =Dane!H7 -> 0 | E6: =Dane!I7 -> 178.4685 | F6: =Dane!M10-Dane!M11 -> -35 | G6: =Dane!N10-Dane!N11 -> 175 | H6: =SQRT(F6^2+G6^2) -> 178.46568 | I6: =IF(ATAN2(F6,G6)*200/PI()<0,ATAN2(F6,G6)*200/PI()+400,ATAN2(F6,G6)*200/PI()) -> 112.56659 | J6: =SIN(I6*PI()/200) -> 0.98058068 | K6: =COS(I6*PI()/200) -> -0.19611614 | L6: =0.001+0.000001*E6 -> 0.0011784685 | M6: =H6-E6 -> -0.0028170243 | P6: 2 | Q6: 385 | R6: 145
B7: =Dane!F8 -> 7 | C7: =Dane!G8 -> 8 | D7: =Dane!H8 -> 0 | E7: =Dane!I8 -> 148.0689 | F7: =Dane!M12-Dane!M11 -> -30 | G7: =Dane!N12-Dane!N11 -> -145 | H7: =SQRT(F7^2+G7^2) -> 148.07093 | I7: =IF(ATAN2(F7,G7)*200/PI()<0,ATAN2(F7,G7)*200/PI()+400) -> 287.01181 | J7: =SIN(I7*PI()/200) -> -0.97926042 | K7: =COS(I7*PI()/200) -> -0.2026056 | L7: =0.001+0.000001*E7 -> 0.0011480689 | M7: =H7-E7 -> 0.0020289496 | P7: 3 | Q7: 475 | R7: 245
B8: =Dane!F9 -> 7 | C8: =Dane!G9 -> 9 | D8: =Dane!H9 -> 0 | E8: =Dane!I9 -> 174.522 | F8: =Dane!M13-Dane!M11 -> 133 | G8: =Dane!N13-Dane!N11 -> -113 | H8: =SQRT(F8^2+G8^2) -> 174.5222 | I8: =IF(ATAN2(F8,G8)*200/PI()<0,ATAN2(F8,G8)*200/PI()+400) -> 355.16441 | J8: =SIN(I8*PI()/200) -> -0.64748208 | K8: =COS(I8*PI()/200) -> 0.76208068 | L8: =0.001+0.000001*E8 -> 0.001174522 | M8: =H8-E8 -> 0.00020489095 | P8: 4 | Q8: 435 | R8: 435
B9: =Dane!F10 -> 8 | C9: =Dane!G10 -> 1 | D9: =Dane!H10 -> 0 | E9: =Dane!I10 -> 150.0006 | F9: =Dane!M5-Dane!M12 -> 90 | G9: =Dane!N5-Dane!N12 -> -120 | H9: =SQRT(F9^2+G9^2) -> 150 | I9: =IF(ATAN2(F9,G9)*200/PI()<0,ATAN2(F9,G9)*200/PI()+400) -> 340.96655 | J9: =SIN(I9*PI()/200) -> -0.8 | K9: =COS(I9*PI()/200) -> 0.6 | L9: =0.001+0.000001*E9 -> 0.0011500006 | M9: =H9-E9 -> -0.0006 | P9: 5 | Q9: 295 | R9: 490
B10: =Dane!F11 -> 8 | C10: =Dane!G11 -> 9 | D10: =Dane!H11 -> 0 | E10: =Dane!I11 -> 166.1145 | F10: =Dane!M13-Dane!M12 -> 163 | G10: =Dane!N13-Dane!N12 -> 32 | H10: =SQRT(F10^2+G10^2) -> 166.11141 | I10: =IF(ATAN2(F10,G10)*200/PI()<0,ATAN2(F10,G10)*200/PI()+400,ATAN2(F10,G10)*200/PI()) -> 12.341107 | J10: =SIN(I10*PI()/200) -> 0.1926418 | K10: =COS(I10*PI()/200) -> 0.98126915 | L10: =0.001+0.000001*E10 -> 0.0011661145 | M10: =H10-E10 -> -0.0030916019 | P10: 6 | Q10: 145 | R10: 560
B11: =Dane!F12 -> 8 | C11: =Dane!G12 -> 7 | D11: =Dane!H12 -> 0 | E11: =Dane!I12 -> 148.0712 | F11: =Dane!M11-Dane!M12 -> 30 | G11: =Dane!N11-Dane!N12 -> 145 | H11: =SQRT(F11^2+G11^2) -> 148.07093 | I11: =IF(ATAN2(F11,G11)*200/PI()<0,ATAN2(F11,G11)*200/PI()+400,ATAN2(F11,G11)*200/PI()) -> 87.011812 | J11: =SIN(I11*PI()/200) -> 0.97926042 | K11: =COS(I11*PI()/200) -> 0.2026056 | L11: =0.001+0.000001*E11 -> 0.0011480712 | M11: =H11-E11 -> -0.00027105039 | P11: 7 | Q11: 180 | R11: 385
B12: =Dane!F13 -> 8 | C12: =Dane!G13 -> 6 | D12: =Dane!H13 -> 0 | E12: =Dane!I13 -> 320.0445 | F12: =Dane!M10-Dane!M12 -> -5 | G12: =Dane!N10-Dane!N12 -> 320 | H12: =SQRT(F12^2+G12^2) -> 320.03906 | I12: =IF(ATAN2(F12,G12)*200/PI()<0,ATAN2(F12,G12)*200/PI()+400,ATAN2(F12,G12)*200/PI()) -> 100.99464 | J12: =SIN(I12*PI()/200) -> 0.99987795 | K12: =COS(I12*PI()/200) -> -0.015623093 | L12: =0.001+0.000001*E12 -> 0.0013200445 | M12: =H12-E12 -> -0.0054398839 | P12: 8 | Q12: 150 | R12: 240
B13: =Dane!F14 -> 1 | C13: =Dane!G14 -> 2 | D13: =Dane!H14 -> 0 | E13: =Dane!I14 -> 147.1241 | F13: =Dane!M6-Dane!M5 -> 145 | G13: =Dane!N6-Dane!N5 -> 25 | H13: =SQRT(F13^2+G13^2) -> 147.13939 | I13: =IF(ATAN2(F13,G13)*200/PI()<0,ATAN2(F13,G13)*200/PI()+400,ATAN2(F13,G13)*200/PI()) -> 10.869341 | J13: =SIN(I13*PI()/200) -> 0.16990692 | K13: =COS(I13*PI()/200) -> 0.98546012 | L13: =0.001+0.000001*E13 -> 0.0011471241 | M13: =H13-E13 -> 0.015289696 | P13: 9 | Q13: 314 | R13: 271
B14: =Dane!F15 -> 1 | C14: =Dane!G15 -> 9 | D14: =Dane!H15 -> 0 | E14: =Dane!I15 -> 168.6108 | F14: =Dane!M13-Dane!M5 -> 73 | G14: =Dane!N13-Dane!N5 -> 152 | H14: =SQRT(F14^2+G14^2) -> 168.62088 | I14: =IF(ATAN2(F14,G14)*200/PI()<0,ATAN2(F14,G14)*200/PI()+400,ATAN2(F14,G14)*200/PI()) -> 71.496379 | J14: =SIN(I14*PI()/200) -> 0.90143049 | K14: =COS(I14*PI()/200) -> 0.43292386 | L14: =0.001+0.000001*E14 -> 0.0011686108 | M14: =H14-E14 -> 0.010076525
B15: =Dane!F16 -> 1 | C15: =Dane!G16 -> 7 | D15: =Dane!H16 -> 0 | E15: =Dane!I16 -> 271.7008 | F15: =Dane!M11-Dane!M5 -> -60 | G15: =Dane!N11-Dane!N5 -> 265 | H15: =SQRT(F15^2+G15^2) -> 271.70756 | I15: =IF(ATAN2(F15,G15)*200/PI()<0,ATAN2(F15,G15)*200/PI()+400,ATAN2(F15,G15)*200/PI()) -> 114.17504 | J15: =SIN(I15*PI()/200) -> 0.9753133 | K15: =COS(I15*PI()/200) -> -0.22082565 | L15: =0.001+0.000001*E15 -> 0.0012717008 | M15: =H15-E15 -> 0.0067633839
B16: =Dane!F17 -> 2 | C16: =Dane!G17 -> 8 | D16: =Dane!H17 -> 0 | E16: =Dane!I17 -> 253.4723 | F16: =Dane!M12-Dane!M6 -> -235 | G16: =Dane!N12-Dane!N6 -> 95 | H16: =SQRT(F16^2+G16^2) -> 253.47584 | I16: =IF(ATAN2(F16,G16)*200/PI()<0,ATAN2(F16,G16)*200/PI()+400,ATAN2(F16,G16)*200/PI()) -> 175.54302 | J16: =SIN(I16*PI()/200) -> 0.37478918 | K16: =COS(I16*PI()/200) -> -0.92711007 | L16: =0.001+0.000001*E16 -> 0.0012534723 | M16: =H16-E16 -> 0.0035371127
B17: =Dane!F18 -> 2 | C17: =Dane!G18 -> 9 | D17: =Dane!H18 -> 0 | E17: =Dane!I18 -> 145.9865 | F17: =Dane!M13-Dane!M6 -> -72 | G17: =Dane!N13-Dane!N6 -> 127 | H17: =SQRT(F17^2+G17^2) -> 145.98973 | I17: =IF(ATAN2(F17,G17)*200/PI()<0,ATAN2(F17,G17)*200/PI()+400,ATAN2(F17,G17)*200/PI()) -> 132.83352 | J17: =SIN(I17*PI()/200) -> 0.86992423 | K17: =COS(I17*PI()/200) -> -0.49318539 | L17: =0.001+0.000001*E17 -> 0.0011459865 | M17: =H17-E17 -> 0.0032256659
B18: =Dane!F19 -> 2 | C18: =Dane!G19 -> 4 | D18: =Dane!H19 -> 0 | E18: =Dane!I19 -> 294.2725 | F18: =Dane!M8-Dane!M6 -> 50 | G18: =Dane!N8-Dane!N6 -> 290 | H18: =SQRT(F18^2+G18^2) -> 294.27878 | I18: =IF(ATAN2(F18,G18)*200/PI()<0,ATAN2(F18,G18)*200/PI()+400,ATAN2(F18,G18)*200/PI()) -> 89.130659 | J18: =SIN(I18*PI()/200) -> 0.98546012 | K18: =COS(I18*PI()/200) -> 0.16990692 | L18: =0.001+0.000001*E18 -> 0.0012942725 | M18: =H18-E18 -> 0.0062793912
B19: =Dane!F20 -> 4 | C19: =Dane!G20 -> 5 | D19: =Dane!H20 -> 0 | E19: =Dane!I20 -> 150.4243 | F19: =Dane!M9-Dane!M8 -> -140 | G19: =Dane!N9-Dane!N8 -> 55 | H19: =SQRT(F19^2+G19^2) -> 150.41609 | I19: =IF(ATAN2(F19,G19)*200/PI()<0,ATAN2(F19,G19)*200/PI()+400,ATAN2(F19,G19)*200/PI()) -> 176.16918 | J19: =SIN(I19*PI()/200) -> 0.36565237 | K19: =COS(I19*PI()/200) -> -0.93075149 | L19: =0.001+0.000001*E19 -> 0.0011504243 | M19: =H19-E19 -> -0.0082104351
B20: =Dane!F21 -> 4 | C20: =Dane!G21 -> 7 | D20: =Dane!H21 -> 0 | E20: =Dane!I21 -> 259.868 | F20: =Dane!M11-Dane!M8 -> -255 | G20: =Dane!N11-Dane!N8 -> -50 | H20: =SQRT(F20^2+G20^2) -> 259.85573 | I20: =IF(ATAN2(F20,G20)*200/PI()<0,ATAN2(F20,G20)*200/PI()+400) -> 212.32636 | J20: =SIN(I20*PI()/200) -> -0.19241446 | K20: =COS(I20*PI()/200) -> -0.98131375 | L20: =0.001+0.000001*E20 -> 0.001259868 | M20: =H20-E20 -> -0.012270796
B21: =Dane!F22 -> 4 | C21: =Dane!G22 -> 9 | D21: =Dane!H22 -> 0 | E21: =Dane!I22 -> 203.6019 | F21: =Dane!M13-Dane!M8 -> -122 | G21: =Dane!N13-Dane!N8 -> -163 | H21: =SQRT(F21^2+G21^2) -> 203.6001 | I21: =IF(ATAN2(F21,G21)*200/PI()<0,ATAN2(F21,G21)*200/PI()+400) -> 259.09598 | J21: =SIN(I21*PI()/200) -> -0.800589 | K21: =COS(I21*PI()/200) -> -0.59921386 | L21: =0.001+0.000001*E21 -> 0.0012036019 | M21: =H21-E21 -> -0.0018017682
B22: =Dane!F23 -> 6 | C22: =Dane!G23 -> 9 | D22: =Dane!H23 -> 0 | E22: =Dane!I23 -> 333.4174 | F22: =Dane!M13-Dane!M10 -> 168 | G22: =Dane!N13-Dane!N10 -> -288 | H22: =SQRT(F22^2+G22^2) -> 333.41866 | I22: =IF(ATAN2(F22,G22)*200/PI()<0,ATAN2(F22,G22)*200/PI()+400) -> 333.61826 | J22: =SIN(I22*PI()/200) -> -0.8637789 | K22: =COS(I22*PI()/200) -> 0.50387103 | L22: =0.001+0.000001*E22 -> 0.0013334174 | M22: =H22-E22 -> 0.0012557468
B23: =Dane!F24 -> 6 | C23: =Dane!G24 -> 5 | D23: =Dane!H24 -> 0 | E23: =Dane!I24 -> 165.5303 | F23: =Dane!M9-Dane!M10 -> 150 | G23: =Dane!N9-Dane!N10 -> -70 | H23: =SQRT(F23^2+G23^2) -> 165.52945 | I23: =IF(ATAN2(F23,G23)*200/PI()<0,ATAN2(F23,G23)*200/PI()+400) -> 372.20345 | J23: =SIN(I23*PI()/200) -> -0.42288547 | K23: =COS(I23*PI()/200) -> 0.90618314 | L23: =0.001+0.000001*E23 -> 0.0011655303 | M23: =H23-E23 -> -0.00084642753
B25: c | C25: l | D25: p | E25: b obs [g] | F25: ∆xcl | G25: ∆ycl | H25: ∆xcp | I25: ∆ycp | J25: d²cl | K25: d²cp | L25: Az cl [g] | M25: Az cp [g] | N25: b przyb [g] | O25: Błąd [cc] | P25: l [g] | Q25: Acl. | R25: Bcl | S25: Acp | T25: Bcp
B26: =Dane!F25 -> 9 | C26: =Dane!G25 -> 1 | D26: =Dane!H25 -> 2 | E26: =Dane!I25 -> 61.3342 | F26: =Dane!M5-Dane!M13 -> -73 | G26: =Dane!N5-Dane!N13 -> -152 | H26: =Dane!M6-Dane!M13 -> 72 | I26: =Dane!N6-Dane!N13 -> -127 | J26: =F26^2+G26^2 -> 28433 | K26: =H26^2+I26^2 -> 21313 | L26: =IF(ATAN2(F26,G26)*200/PI()<0,ATAN2(F26,G26)*200/PI()+400,ATAN2(F26,G26)*200/PI()) -> 271.49638 | M26: =IF(ATAN2(H26,I26)*200/PI()<0,ATAN2(H26,I26)*200/PI()+400,ATAN2(H26,I26)*200/PI()) -> 332.83352 | N26: =IF(M26-L26<0,M26-L26+400,M26-L26) -> 61.337137 | O26: =Dane!$M$15 -> 3 | P26: =N26-E26 -> 0.0029366713 | Q26: =F26/J26*(2000000/PI()) -> -1634.4826 | R26: =G26/J26*2000000/PI() -> -3403.3062 | S26: =H26/K26*2000000/PI() -> 2150.6416 | T26: =I26/K26*2000000/PI() -> -3793.4928
B27: =Dane!F26 -> 9 | C27: =Dane!G26 -> 2 | D27: =Dane!H26 -> 4 | E27: =Dane!I26 -> 126.2606 | F27: =Dane!M6-Dane!M13 -> 72 | G27: =Dane!N6-Dane!N13 -> -127 | H27: =Dane!M8-Dane!M13 -> 122 | I27: =Dane!N8-Dane!N13 -> 163 | J27: =F27^2+G27^2 -> 21313 | K27: =H27^2+I27^2 -> 41453 | L27: =IF(ATAN2(F27,G27)*200/PI()<0,ATAN2(F27,G27)*200/PI()+400,ATAN2(F27,G27)*200/PI()) -> 332.83352 | M27: =IF(ATAN2(H27,I27)*200/PI()<0,ATAN2(H27,I27)*200/PI()+400,ATAN2(H27,I27)*200/PI()) -> 59.095983 | N27: =IF(M27-L27<0,M27-L27+400,M27-L27) -> 126.26247 | O27: =Dane!$M$15 -> 3 | P27: =N27-E27 -> 0.0018677864 | Q27: =F27/J27*(2000000/PI()) -> 2150.6416 | R27: =G27/J27*2000000/PI() -> -3793.4928 | S27: =H27/K27*2000000/PI() -> 1873.6307 | T27: =I27/K27*2000000/PI() -> 2503.2934
B28: =Dane!F27 -> 9 | C28: =Dane!G27 -> 4 | D28: =Dane!H27 -> 5 | E28: =Dane!I27 -> 46.1513 | F28: =Dane!M8-Dane!M13 -> 122 | G28: =Dane!N8-Dane!N13 -> 163 | H28: =Dane!M9-Dane!M13 -> -18 | I28: =Dane!N9-Dane!N13 -> 218 | J28: =F28^2+G28^2 -> 41453 | K28: =H28^2+I28^2 -> 47848 | L28: =IF(ATAN2(F28,G28)*200/PI()<0,ATAN2(F28,G28)*200/PI()+400,ATAN2(F28,G28)*200/PI()) -> 59.095983 | M28: =IF(ATAN2(H28,I28)*200/PI()<0,ATAN2(H28,I28)*200/PI()+400,ATAN2(H28,I28)*200/PI()) -> 105.2446 | N28: =IF(M28-L28<0,M28-L28+400,M28-L28) -> 46.148613 | O28: =Dane!$M$15 -> 3 | P28: =N28-E28 -> -0.0026867734 | Q28: =F28/J28*(2000000/PI()) -> 1873.6307 | R28: =G28/J28*2000000/PI() -> 2503.2934 | S28: =H28/K28*2000000/PI() -> -239.4908 | T28: =I28/K28*2000000/PI() -> 2900.4997
B29: =Dane!F28 -> 9 | C29: =Dane!G28 -> 5 | D29: =Dane!H28 -> 7 | E29: =Dane!I28 -> 49.9219 | F29: =Dane!M9-Dane!M13 -> -18 | G29: =Dane!N9-Dane!N13 -> 218 | H29: =Dane!M11-Dane!M13 -> -133 | I29: =Dane!N11-Dane!N13 -> 113 | J29: =F29^2+G29^2 -> 47848 | K29: =H29^2+I29^2 -> 30458 | L29: =IF(ATAN2(F29,G29)*200/PI()<0,ATAN2(F29,G29)*200/PI()+400,ATAN2(F29,G29)*200/PI()) -> 105.2446 | M29: =IF(ATAN2(H29,I29)*200/PI()<0,ATAN2(H29,I29)*200/PI()+400,ATAN2(H29,I29)*200/PI()) -> 155.16441 | N29: =IF(M29-L29<0,M29-L29+400,M29-L29) -> 49.919815 | O29: =Dane!$M$15 -> 3 | P29: =N29-E29 -> -0.0020847107 | Q29: =F29/J29*(2000000/PI()) -> -239.4908 | R29: =G29/J29*2000000/PI() -> 2900.4997 | S29: =H29/K29*2000000/PI() -> -2779.9077 | T29: =I29/K29*2000000/PI() -> 2361.8765
B30: =Dane!F29 -> 9 | C30: =Dane!G29 -> 7 | D30: =Dane!H29 -> 8 | E30: =Dane!I29 -> 57.1764 | F30: =Dane!M11-Dane!M13 -> -133 | G30: =Dane!N11-Dane!N13 -> 113 | H30: =Dane!M12-Dane!M13 -> -163 | I30: =Dane!N12-Dane!N13 -> -32 | J30: =F30^2+G30^2 -> 30458 | K30: =H30^2+I30^2 -> 27593 | L30: =IF(ATAN2(F30,G30)*200/PI()<0,ATAN2(F30,G30)*200/PI()+400,ATAN2(F30,G30)*200/PI()) -> 155.16441 | M30: =IF(ATAN2(H30,I30)*200/PI()<0,ATAN2(H30,I30)*200/PI()+400,ATAN2(H30,I30)*200/PI()) -> 212.34111 | N30: =IF(M30-L30<0,M30-L30+400,M30-L30) -> 57.176696 | O30: =Dane!$M$15 -> 3 | P30: =N30-E30 -> 0.00029553998 | Q30: =F30/J30*(2000000/PI()) -> -2779.9077 | R30: =G30/J30*2000000/PI() -> 2361.8765 | S30: =H30/K30*2000000/PI() -> -3760.701 | T30: =I30/K30*2000000/PI() -> -738.29713
B31: =Dane!F30 -> 9 | C31: =Dane!G30 -> 8 | D31: =Dane!H30 -> 1 | E31: =Dane!I30 -> 59.1567 | F31: =Dane!M12-Dane!M13 -> -163 | G31: =Dane!N12-Dane!N13 -> -32 | H31: =Dane!M5-Dane!M13 -> -73 | I31: =Dane!N5-Dane!N13 -> -152 | J31: =F31^2+G31^2 -> 27593 | K31: =H31^2+I31^2 -> 28433 | L31: =IF(ATAN2(F31,G31)*200/PI()<0,ATAN2(F31,G31)*200/PI()+400,ATAN2(F31,G31)*200/PI()) -> 212.34111 | M31: =IF(ATAN2(H31,I31)*200/PI()<0,ATAN2(H31,I31)*200/PI()+400,ATAN2(H31,I31)*200/PI()) -> 271.49638 | N31: =IF(M31-L31<0,M31-L31+400,M31-L31) -> 59.155271 | O31: =Dane!$M$15 -> 3 | P31: =N31-E31 -> -0.0014285136 | Q31: =F31/J31*(2000000/PI()) -> -3760.701 | R31: =G31/J31*2000000/PI() -> -738.29713 | S31: =H31/K31*2000000/PI() -> -1634.4826 | T31: =I31/K31*2000000/PI() -> -3403.3062
B32: =Dane!F31 -> 6 | C32: =Dane!G31 -> 8 | D32: =Dane!H31 -> 7 | E32: =Dane!I31 -> 11.5714 | F32: =Dane!M12-Dane!M10 -> 5 | G32: =Dane!N12-Dane!N10 -> -320 | H32: =Dane!M11-Dane!M10 -> 35 | I32: =Dane!N11-Dane!N10 -> -175 | J32: =F32^2+G32^2 -> 102425 | K32: =H32^2+I32^2 -> 31850 | L32: =IF(ATAN2(F32,G32)*200/PI()<0,ATAN2(F32,G32)*200/PI()+400,ATAN2(F32,G32)*200/PI()) -> 300.99464 | M32: =IF(ATAN2(H32,I32)*200/PI()<0,ATAN2(H32,I32)*200/PI()+400,ATAN2(H32,I32)*200/PI()) -> 312.56659 | N32: =IF(M32-L32<0,M32-L32+400,M32-L32) -> 11.571954 | O32: =Dane!$M$15 -> 3 | P32: =N32-E32 -> 0.00055418201 | Q32: =F32/J32*(2000000/PI()) -> 31.077363 | R32: =G32/J32*2000000/PI() -> -1988.9512 | S32: =H32/K32*2000000/PI() -> 699.58217 | T32: =I32/K32*2000000/PI() -> -3497.9108
B33: =Dane!F32 -> 6 | C33: =Dane!G32 -> 7 | D33: =Dane!H32 -> 9 | E33: =Dane!I32 -> 21.0531 | F33: =Dane!M11-Dane!M10 -> 35 | G33: =Dane!N11-Dane!N10 -> -175 | H33: =Dane!M13-Dane!M10 -> 168 | I33: =Dane!N13-Dane!N10 -> -288 | J33: =F33^2+G33^2 -> 31850 | K33: =H33^2+I33^2 -> 111168 | L33: =IF(ATAN2(F33,G33)*200/PI()<0,ATAN2(F33,G33)*200/PI()+400,ATAN2(F33,G33)*200/PI()) -> 312.56659 | M33: =IF(ATAN2(H33,I33)*200/PI()<0,ATAN2(H33,I33)*200/PI()+400,ATAN2(H33,I33)*200/PI()) -> 333.61826 | N33: =IF(M33-L33<0,M33-L33+400,M33-L33) -> 21.051672 | O33: =Dane!$M$15 -> 3 | P33: =N33-E33 -> -0.0014281228 | Q33: =F33/J33*(2000000/PI()) -> 699.58217 | R33: =G33/J33*2000000/PI() -> -3497.9108 | S33: =H33/K33*2000000/PI() -> 962.07651 | T33: =I33/K33*2000000/PI() -> -1649.274
B34: =Dane!F33 -> 6 | C34: =Dane!G33 -> 9 | D34: =Dane!H33 -> 5 | E34: =Dane!I33 -> 38.5857 | F34: =Dane!M13-Dane!M10 -> 168 | G34: =Dane!N13-Dane!N10 -> -288 | H34: =Dane!M9-Dane!M10 -> 150 | I34: =Dane!N9-Dane!N10 -> -70 | J34: =F34^2+G34^2 -> 111168 | K34: =H34^2+I34^2 -> 27400 | L34: =IF(ATAN2(F34,G34)*200/PI()<0,ATAN2(F34,G34)*200/PI()+400,ATAN2(F34,G34)*200/PI()) -> 333.61826 | M34: =IF(ATAN2(H34,I34)*200/PI()<0,ATAN2(H34,I34)*200/PI()+400,ATAN2(H34,I34)*200/PI()) -> 372.20345 | N34: =IF(M34-L34<0,M34-L34+400,M34-L34) -> 38.585188 | O34: =Dane!$M$15 -> 3 | P34: =N34-E34 -> -0.00051182403 | Q34: =F34/J34*(2000000/PI()) -> 962.07651 | R34: =G34/J34*2000000/PI() -> -1649.274 | S34: =H34/K34*2000000/PI() -> 3485.1447 | T34: =I34/K34*2000000/PI() -> -1626.4009
B35: =Dane!F34 -> 5 | C35: =Dane!G34 -> 6 | D35: =Dane!H34 -> 7 | E35: =Dane!I34 -> 74.9054 | F35: =Dane!M10-Dane!M9 -> -150 | G35: =Dane!N10-Dane!N9 -> 70 | H35: =Dane!M11-Dane!M9 -> -115 | I35: =Dane!N11-Dane!N9 -> -105 | J35: =F35^2+G35^2 -> 27400 | K35: =H35^2+I35^2 -> 24250 | L35: =IF(ATAN2(F35,G35)*200/PI()<0,ATAN2(F35,G35)*200/PI()+400,ATAN2(F35,G35)*200/PI()) -> 172.20345 | M35: =IF(ATAN2(H35,I35)*200/PI()<0,ATAN2(H35,I35)*200/PI()+400,ATAN2(H35,I35)*200/PI()) -> 247.10826 | N35: =IF(M35-L35<0,M35-L35+400,M35-L35) -> 74.904813 | O35: =Dane!$M$15 -> 3 | P35: =N35-E35 -> -0.00058747156 | Q35: =F35/J35*(2000000/PI()) -> -3485.1447 | R35: =G35/J35*2000000/PI() -> 1626.4009 | S35: =H35/K35*2000000/PI() -> -3019.0216 | T35: =I35/K35*2000000/PI() -> -2756.498
B36: =Dane!F35 -> 5 | C36: =Dane!G35 -> 7 | D36: =Dane!H35 -> 9 | E36: =Dane!I35 -> 58.1359 | F36: =Dane!M11-Dane!M9 -> -115 | G36: =Dane!N11-Dane!N9 -> -105 | H36: =Dane!M13-Dane!M9 -> 18 | I36: =Dane!N13-Dane!N9 -> -218 | J36: =F36^2+G36^2 -> 24250 | K36: =H36^2+I36^2 -> 47848 | L36: =IF(ATAN2(F36,G36)*200/PI()<0,ATAN2(F36,G36)*200/PI()+400,ATAN2(F36,G36)*200/PI()) -> 247.10826 | M36: =IF(ATAN2(H36,I36)*200/PI()<0,ATAN2(H36,I36)*200/PI()+400,ATAN2(H36,I36)*200/PI()) -> 305.2446 | N36: =IF(M36-L36<0,M36-L36+400,M36-L36) -> 58.136332 | O36: =Dane!$M$15 -> 3 | P36: =N36-E36 -> 0.0004323706 | Q36: =F36/J36*(2000000/PI()) -> -3019.0216 | R36: =G36/J36*2000000/PI() -> -2756.498 | S36: =H36/K36*2000000/PI() -> 239.4908 | T36: =I36/K36*2000000/PI() -> -2900.4997
B37: =Dane!F36 -> 5 | C37: =Dane!G36 -> 9 | D37: =Dane!H36 -> 4 | E37: =Dane!I36 -> 70.9246 | F37: =Dane!M13-Dane!M9 -> 18 | G37: =Dane!N13-Dane!N9 -> -218 | H37: =Dane!M8-Dane!M9 -> 140 | I37: =Dane!N8-Dane!N9 -> -55 | J37: =F37^2+G37^2 -> 47848 | K37: =H37^2+I37^2 -> 22625 | L37: =IF(ATAN2(F37,G37)*200/PI()<0,ATAN2(F37,G37)*200/PI()+400,ATAN2(F37,G37)*200/PI()) -> 305.2446 | M37: =IF(ATAN2(H37,I37)*200/PI()<0,ATAN2(H37,I37)*200/PI()+400,ATAN2(H37,I37)*200/PI()) -> 376.16918 | N37: =IF(M37-L37<0,M37-L37+400,M37-L37) -> 70.924585 | O37: =Dane!$M$15 -> 3 | P37: =N37-E37 -> -1.4731277e-05 | Q37: =F37/J37*(2000000/PI()) -> 239.4908 | R37: =G37/J37*2000000/PI() -> -2900.4997 | S37: =H37/K37*2000000/PI() -> 3939.3047 | T37: =I37/K37*2000000/PI() -> -1547.584
B39: a | S39: l [m/cc]
B40: dx | C40: dy | D40: dx | E40: dy | F40: dx | G40: dy | H40: dx | I40: dy | J40: dx | K40: dy | L40: dx | M40: dy | N40: dx | O40: dy | P40: dx | Q40: dy
B41: 1 | C41: 1 | D41: 2 | E41: 2 | F41: 4 | G41: 4 | H41: 5 | I41: 5 | J41: 6 | K41: 6 | L41: 7 | M41: 7 | N41: 8 | O41: 8 | P41: 9 | Q41: 9
B42: =IF(B$41=$B4,IF(B$40="dx",-$K4,-$J4),IF(B$41=$C4,IF(B$40="dx",$K4,$J4),0)) -> 0.22082565 | C42: =IF(C$41=$B4,IF(C$40="dx",-$K4,-$J4),IF(C$41=$C4,IF(C$40="dx",$K4,$J4),0)) -> -0.9753133 | D42: =IF(D$41=$B4,IF(D$40="dx",-$K4,-$J4),IF(D$41=$C4,IF(D$40="dx",$K4,$J4),0)) -> 0 | E42: =IF(E$41=$B4,IF(E$40="dx",-$K4,-$J4),IF(E$41=$C4,IF(E$40="dx",$K4,$J4),0)) -> 0 | F42: =IF(F$41=$B4,IF(F$40="dx",-$K4,-$J4),IF(F$41=$C4,IF(F$40="dx",$K4,$J4),0)) -> 0 | G42: =IF(G$41=$B4,IF(G$40="dx",-$K4,-$J4),IF(G$41=$C4,IF(G$40="dx",$K4,$J4),0)) -> 0 | H42: =IF(H$41=$B4,IF(H$40="dx",-$K4,-$J4),IF(H$41=$C4,IF(H$40="dx",$K4,$J4),0)) -> 0 | I42: =IF(I$41=$B4,IF(I$40="dx",-$K4,-$J4),IF(I$41=$C4,IF(I$40="dx",$K4,$J4),0)) -> 0 | ... Q42: =IF(Q$41=$B4,IF(Q$40="dx",-$K4,-$J4),IF(Q$41=$C4,IF(Q$40="dx",$K4,$J4),0)) -> 0 | S42: =M4 -> 0.0055633839
B43: =IF(B$41=$B5,IF(B$40="dx",-$K5,-$J5),IF(B$41=$C5,IF(B$40="dx",$K5,$J5),0)) -> 0 | C43: =IF(C$41=$B5,IF(C$40="dx",-$K5,-$J5),IF(C$41=$C5,IF(C$40="dx",$K5,$J5),0)) -> 0 | D43: =IF(D$41=$B5,IF(D$40="dx",-$K5,-$J5),IF(D$41=$C5,IF(D$40="dx",$K5,$J5),0)) -> 0 | E43: =IF(E$41=$B5,IF(E$40="dx",-$K5,-$J5),IF(E$41=$C5,IF(E$40="dx",$K5,$J5),0)) -> 0 | F43: =IF(F$41=$B5,IF(F$40="dx",-$K5,-$J5),IF(F$41=$C5,IF(F$40="dx",$K5,$J5),0)) -> 0 | G43: =IF(G$41=$B5,IF(G$40="dx",-$K5,-$J5),IF(G$41=$C5,IF(G$40="dx",$K5,$J5),0)) -> 0 | H43: =IF(H$41=$B5,IF(H$40="dx",-$K5,-$J5),IF(H$41=$C5,IF(H$40="dx",$K5,$J5),0)) -> 0.73848549 | I43: =IF(I$41=$B5,IF(I$40="dx",-$K5,-$J5),IF(I$41=$C5,IF(I$40="dx",$K5,$J5),0)) -> 0.67426936 | ... Q43: =IF(Q$41=$B5,IF(Q$40="dx",-$K5,-$J5),IF(Q$41=$C5,IF(Q$40="dx",$K5,$J5),0)) -> 0 | S43: =M5 -> -0.003784976
B44: =IF(B$41=$B6,IF(B$40="dx",-$K6,-$J6),IF(B$41=$C6,IF(B$40="dx",$K6,$J6),0)) -> 0 | C44: =IF(C$41=$B6,IF(C$40="dx",-$K6,-$J6),IF(C$41=$C6,IF(C$40="dx",$K6,$J6),0)) -> 0 | D44: =IF(D$41=$B6,IF(D$40="dx",-$K6,-$J6),IF(D$41=$C6,IF(D$40="dx",$K6,$J6),0)) -> 0 | E44: =IF(E$41=$B6,IF(E$40="dx",-$K6,-$J6),IF(E$41=$C6,IF(E$40="dx",$K6,$J6),0)) -> 0 | F44: =IF(F$41=$B6,IF(F$40="dx",-$K6,-$J6),IF(F$41=$C6,IF(F$40="dx",$K6,$J6),0)) -> 0 | G44: =IF(G$41=$B6,IF(G$40="dx",-$K6,-$J6),IF(G$41=$C6,IF(G$40="dx",$K6,$J6),0)) -> 0 | H44: =IF(H$41=$B6,IF(H$40="dx",-$K6,-$J6),IF(H$41=$C6,IF(H$40="dx",$K6,$J6),0)) -> 0 | I44: =IF(I$41=$B6,IF(I$40="dx",-$K6,-$J6),IF(I$41=$C6,IF(I$40="dx",$K6,$J6),0)) -> 0 | ... Q44: =IF(Q$41=$B6,IF(Q$40="dx",-$K6,-$J6),IF(Q$41=$C6,IF(Q$40="dx",$K6,$J6),0)) -> 0 | S44: =M6 -> -0.0028170243
...

Sheet Identyfikacja
B2: ATA Wyjściowy | R2: ST | W2: (ATA)-1 | AM2: ST(-1) | AQ2: X | AR2: m0 | AS2: mx
B3: {=_xlfn.ANCHORARRAY('Wyrównanie wstępne - wyjściowy'!B110)} -> 3529835.6 | C3: -1321072 | D3: -727167.85 | E3: -1704466.7 | F3: 0 | G3: 0 | H3: 0 | I3: 0 | J3: 0 | K3: 0 | L3: -60305.207 | M3: 266348 | N3: -551395.99 | O3: 1785040.8 | P3: -2190966.5 | Q3: 974149.92 | R3: {=TRANSPOSE(B19:Q21)} -> 0 | S3: 0 | T3: 0 | W3: {=MINVERSE(B3:T21)} -> 1.2554878e-06 | X3: 3.0503499e-07 | Y3: 8.0476354e-07 | Z3: 7.1121386e-07 | AA3: 2.9044386e-08 | AB3: 4.5835186e-07 | AC3: 7.5628589e-25 | AD3: 0 | AE3: -5.2969972e-08 | AF3: -2.1385782e-07 | AG3: 1.8340734e-07 | AH3: -1.3557894e-07 | AI3: -1.2827387e-07 | AJ3: -2.2116184e-07 | AK3: 4.9816519e-07 | AL3: 2.3757557e-07 | AM3: 1 | AN3: -6.5960762e-16 | AO3: 0.00058119464 | AQ3: {=-MMULT(W3:AL18,_xlfn.ANCHORARRAY('Wyrównanie wstępne - wyjściowy'!V110))} -> 0.001597367 | AR3: ='Wyrównanie wstępne - wyjściowy'!AB131 -> 0.92409858 | AS3: =SQRT(ROUND(W3,10))*$AR$3 -> 0.0010354441
B4: -1321072 | C4: 2986537.5 | D4: -142881.15 | E4: 556830.31 | F4: 0 | G4: 0 | H4: 0 | I4: 0 | J4: 0 | K4: 0 | L4: 266348 | M4: -1176370.3 | N4: 497031.57 | O4: -1166911.2 | P4: 700573.58 | Q4: -1200086.3 | R4: 0 | S4: 0 | T4: 0 | W4: 3.0503499e-07 | X4: 6.8049576e-07 | Y4: 2.767557e-07 | Z4: 2.8212662e-07 | AA4: -1.3430043e-08 | AB4: 1.7923364e-07 | AC4: -4.9659963e-25 | AD4: 0 | AE4: 6.7850241e-09 | AF4: 1.2180243e-07 | AG4: 6.1089864e-08 | AH4: 2.2813556e-07 | AI4: 1.378884e-07 | AJ4: 2.3773862e-07 | AK4: 8.2062481e-08 | AL4: 2.8615567e-07 | AM4: 4.2940048e-16 | AN4: 1 | AO4: -8.6393798e-05 | AQ4: 0.0010198994 | AS4: =SQRT(ROUND(X4,10))*$AR$3 -> 0.00076231132
B5: -727167.85 | C5: -142881.15 | D5: 1530177.5 | E5: 258472.98 | F5: 147487.77 | G5: 8701.1162 | H5: -206153.72 | I5: 280598.12 | J5: 0 | K5: 0 | L5: 0 | M5: 0 | N5: 0 | O5: 0 | P5: -744343.67 | Q5: -404891.06 | R5: 0 | S5: 0 | T5: 0 | W5: 8.0476354e-07 | X5: 2.767557e-07 | Y5: 1.234531e-06 | Z5: 4.754452e-07 | AA5: 4.2119237e-08 | AB5: 3.4002796e-07 | AC5: -1.6950924e-24 | AD5: 0 | AE5: -3.2546628e-08 | AF5: -1.303087e-07 | AG5: 1.6896215e-07 | AH5: -4.2844472e-08 | AI5: -3.8342344e-08 | AJ5: -6.610749e-08 | AK5: 4.0236917e-07 | AL5: 2.3924857e-07 | AM5: 1 | AN5: -3.9951618e-16 | AO5: 0.0003848451 | AQ5: 5.0089691e-05 | AS5: =SQRT(ROUND(Y5,10))*$AR$3 -> 0.001026748
B6: -1704466.7 | C6: 556830.31 | D6: 258472.98 | E6: 4459685.7 | F6: 1204860.3 | G6: -1467478.2 | H6: 280598.12 | I6: -381925.22 | J6: 0 | K6: 0 | L6: 0 | M6: 0 | N6: 0 | O6: 0 | P6: -39464.619 | Q6: -3167112.6 | R6: 0 | S6: 0 | T6: 0 | W6: 7.1121386e-07 | X6: 2.8212662e-07 | Y6: 4.754452e-07 | Z6: 9.5235436e-07 | AA6: -1.1396677e-07 | AB6: 5.1928925e-07 | AC6: -3.1931846e-25 | AD6: 0 | AE6: -6.8177416e-08 | AF6: -4.3629493e-08 | AG6: 1.4097498e-07 | AH6: 4.0461408e-08 | AI6: 2.2906047e-08 | AJ6: 3.9493185e-08 | AK6: 3.0154083e-07 | AL6: 4.4320726e-07 | AM6: 1.4236539e-15 | AN6: 1 | AO6: 0.00028274334 | AQ6: 0.0013991059 | AS6: =SQRT(ROUND(Z6,10))*$AR$3 -> 0.00090183689
B7: 0 | C7: 0 | D7: 147487.77 | E7: 1204860.3 | F7: 3197552 | G7: -313305.71 | H7: -1228688.4 | I7: -445656.71 | J7: 0 | K7: 0 | L7: -606699.84 | M7: -118960.75 | N7: 0 | O7: 0 | P7: -1509651.6 | Q7: -326937.09 | R7: 0 | S7: 0 | T7: 0 | W7: 2.9044386e-08 | X7: -1.3430043e-08 | Y7: 4.2119237e-08 | Z7: -1.1396677e-07 | AA7: 4.2674811e-07 | AB7: 2.2800094e-08 | AC7: 1.2923634e-25 | AD7: 0 | AE7: 3.1575849e-08 | AF7: -5.1664134e-08 | AG7: 9.1816797e-08 | AH7: -1.4390688e-08 | AI7: 4.5111618e-09 | AJ7: 7.7778652e-09 | AK7: 1.1949721e-07 | AL7: -2.4740349e-08 | AM7: 1 | AN7: 0 | AO7: 8.6393798e-05 | AQ7: 0.00059326847 | AS7: =SQRT(ROUND(AA7,10))*$AR$3 -> 0.00060364224
B8: 0 | C8: 0 | D8: 8701.1162 | E8: -1467478.2 | F8: -313305.71 | G8: 3742624 | H8: 1453154.5 | I8: -1670577.4 | J8: 0 | K8: 0 | L8: -118960.75 | M8: -23325.638 | N8: 0 | O8: 0 | P8: -1029589.2 | Q8: -581242.71 | R8: 0 | S8: 0 | T8: 0 | W8: 4.5835186e-07 | X8: 1.7923364e-07 | Y8: 3.4002796e-07 | Z8: 5.1928925e-07 | AA8: 2.2800094e-08 | AB8: 5.9024536e-07 | AC8: 3.1992334e-24 | AD8: 0 | AE8: -3.0826013e-08 | AF8: -5.1702816e-08 | AG8: 1.3311119e-07 | AH8: 2.1377321e-08 | AI8: 2.0357266e-08 | AJ8: 3.5098734e-08 | AK8: 2.5856024e-07 | AL8: 2.7577385e-07 | AM8: 1.0220788e-15 | AN8: 1 | AO8: 0.00021991149 | AQ8: 0.0007324952 | AS8: =SQRT(ROUND(AB8,10))*$AR$3 -> 0.00070993389
B9: 0 | C9: 0 | D9: -206153.72 | E9: 280598.12 | F9: -1228688.4 | G9: 1453154.5 | H9: 6377052.1 | I9: 60080.069 | J9: -1392391.9 | K9: -1871079.4 | L9: -2467755.6 | M9: 153229.99 | N9: 0 | O9: 0 | P9: -1082062.5 | Q9: -75983.3 | R9: 1 | S9: 0 | T9: -1905.4767 | W9: -4.5691407e-23 | X9: 0 | Y9: 2.2845703e-23 | Z9: 1.8276563e-22 | AA9: -2.8557129e-23 | AB9: 2.2845703e-23 | AC9: -4.2737398e-24 | AD9: 0 | AE9: 2.2845703e-23 | AF9: -4.5691407e-23 | AG9: 4.5691407e-23 | AH9: 3.4268555e-23 | AI9: -9.1382814e-23 | AJ9: -2.0561133e-22 | AK9: 2.2845703e-23 | AL9: -1.0423352e-22 | AM9: 1 | AN9: -5.7968386e-17 | AO9: -5.6141612e-20 | AQ9: 1.7352572e-20 | AS9: =SQRT(ROUND(AC9,10))*$AR$3 -> 0
B10: 0 | C10: 0 | D10: 280598.12 | E10: -381925.22 | F10: -445656.71 | G10: -1670577.4 | H10: 60080.069 | I10: 5042162.5 | J10: 206717.33 | K10: -1289173.1 | L10: 419604.13 | M10: -1351047.3 | N10: 0 | O10: 0 | P10: -521342.94 | Q10: -349439.44 | R10: 0 | S10: 1 | T10: 1105.1765 | W10: -2.9960929e-23 | X10: 6.741209e-23 | Y10: 0 | Z10: -2.9960929e-23 | AA10: -1.4980464e-23 | AB10: 8.9882786e-23 | AC10: 4.2939767e-24 | AD10: 0 | AE10: -1.4980464e-23 | AF10: -1.4980464e-23 | AG10: -7.4902322e-24 | AH10: 2.9960929e-23 | AI10: 0 | AJ10: 0 | AK10: -1.4980464e-23 | AL10: -1.4980464e-23 | AM10: 1.1128048e-17 | AN10: 1 | AO10: 7.0109116e-21 | AQ10: -1.1657132e-19 | AS10: =SQRT(ROUND(AD10,10))*$AR$3 -> 0
B11: 0 | C11: 0 | D11: 0 | E11: 0 | F11: 0 | G11: 0 | H11: -1392391.9 | I11: 206717.33 | J11: 1701793.4 | K11: 7240.326 | L11: -834516.91 | M11: -668089.35 | N11: 333331.82 | O11: 14175.265 | P11: 191783.62 | Q11: 439956.42 | R11: 0 | S11: 0 | T11: 0 | W11: -5.2969972e-08 | X11: 6.7850241e-09 | Y11: -3.2546628e-08 | Z11: -6.8177416e-08 | AA11: 3.1575849e-08 | AB11: -3.0826013e-08 | AC11: 8.7343438e-24 | AD11: 0 | AE11: 6.6033256e-07 | AF11: 1.8384598e-08 | AG11: 7.53799e-08 | AH11: 7.2457265e-08 | AI11: 2.311642e-08 | AJ11: 3.9855897e-08 | AK11: -1.1109107e-08 | AL11: -4.2524288e-08 | AM11: 1 | AN11: 1.2601777e-16 | AO11: -0.00010995574 | AQ11: -1.5341974e-05 | AS11: =SQRT(ROUND(AE11,10))*$AR$3 -> 0.00075091184
B12: 0 | C12: 0 | D12: 0 | E12: 0 | F12: 0 | G12: 0 | H12: -1871079.4 | I12: -1289173.1 | J12: 7240.326 | K12: 3931596.8 | L12: 1048095.1 | M12: -1893001.6 | N12: 156700.7 | O12: -571436.67 | P12: 659043.25 | Q12: -177985.49 | R12: 0 | S12: 0 | T12: 0 | W12: -2.1385782e-07 | X12: 1.2180243e-07 | Y12: -1.303087e-07 | Z12: -4.3629493e-08 | AA12: -5.1664134e-08 | AB12: -5.1702816e-08 | AC12: -1.2669869e-25 | AD12: 0 | AE12: 1.8384598e-08 | AF12: 4.3250519e-07 | AG12: -7.9505397e-08 | AH12: 2.1745467e-07 | AI12: 1.1628424e-07 | AJ12: 2.0049007e-07 | AK12: -1.4671616e-07 | AL12: 7.056791e-08 | AM12: -5.2724016e-16 | AN12: 1 | AO12: -0.00023561945 | AQ12: 0.0010149922 | AS12: =SQRT(ROUND(AF12,10))*$AR$3 -> 0.00060773096
B13: -60305.207 | C13: 266348 | D13: 0 | E13: 0 | F13: -606699.84 | G13: -118960.75 | H13: -2467755.6 | I13: 419604.13 | J13: -834516.91 | K13: 1048095.1 | L13: 7233417.7 | M13: 183839.17 | N13: -641554.04 | O13: -1300053.6 | P13: -2622586.1 | Q13: -498872.06 | R13: 0 | S13: 0 | T13: 0 | W13: 1.8340734e-07 | X13: 6.1089864e-08 | Y13: 1.6896215e-07 | Z13: 1.4097498e-07 | AA13: 9.1816797e-08 | AB13: 1.3311119e-07 | AC13: 3.577432e-24 | AD13: 0 | AE13: 7.53799e-08 | AF13: -7.9505397e-08 | AG13: 2.5189016e-07 | AH13: 9.3777795e-09 | AI13: 3.7897138e-08 | AJ13: 6.5339893e-08 | AK13: 1.7323402e-07 | AL13: 9.5428646e-08 | AM13: 1 | AN13: -1.0772049e-18 | AO13: 0.00016493361 | AQ13: -0.00034235774 | AS13: =SQRT(ROUND(AG13,10))*$AR$3 -> 0.00046380175
B14: 266348 | C14: -1176370.3 | D14: 0 | E14: 0 | F14: -118960.75 | G14: -23325.638 | H14: 153229.99 | I14: -1351047.3 | J14: -668089.35 | K14: -1893001.6 | L14: 183839.17 | M14: 7842926.8 | N14: -227611.34 | O14: -2619099 | P14: 411244.28 | Q14: -780082.94 | R14: 0 | S14: 0 | T14: 0 | W14: -1.3557894e-07 | X14: 2.2813556e-07 | Y14: -4.2844472e-08 | Z14: 4.0461408e-08 | AA14: -1.4390688e-08 | AB14: 2.1377321e-08 | AC14: 2.7540752e-24 | AD14: 0 | AE14: 7.2457265e-08 | AF14: 2.1745467e-07 | AG14: 9.3777795e-09 | AH14: 3.448261e-07 | AI14: 1.6764025e-07 | AJ14: 2.8903491e-07 | AK14: -7.068108e-08 | AL14: 1.5205443e-07 | AM14: -8.3929667e-17 | AN14: 1 | AO14: -0.00018064158 | AQ14: 0.000629695 | AS14: =SQRT(ROUND(AH14,10))*$AR$3 -> 0.00054262766
B15: -551395.99 | C15: 497031.57 | D15: 0 | E15: 0 | F15: 0 | G15: 0 | H15: 0 | I15: 0 | J15: 333331.82 | K15: 156700.7 | L15: -641554.04 | M15: -227611.34 | N15: 1603418.2 | O15: -541984.55 | P15: -743800 | Q15: 115863.62 | R15: 0 | S15: 0 | T15: 1905.4767 | W15: -1.2827387e-07 | X15: 1.378884e-07 | Y15: -3.8342344e-08 | Z15: 2.2906047e-08 | AA15: 4.5111618e-09 | AB15: 2.0357266e-08 | AC15: -3.9483791e-24 | AD15: 0 | AE15: 2.311642e-08 | AF15: 1.1628424e-07 | AG15: 3.7897138e-08 | AH15: 1.6764025e-07 | AI15: 1.6554606e-07 | AJ15: 2.8542424e-07 | AK15: -3.3501923e-08 | AL15: 1.1510355e-07 | AM15: 1 | AN15: 1.4595713e-16 | AO15: 0.00039269908 | AQ15: -0.00018942142 | AS15: =SQRT(ROUND(AI15,10))*$AR$3 -> 0.00037593893
B16: 1785040.8 | C16: -1166911.2 | D16: 0 | E16: 0 | F16: 0 | G16: 0 | H16: 0 | I16: 0 | J16: 14175.265 | K16: -571436.67 | L16: -1300053.6 | M16: -2619099 | N16: -541984.55 | O16: 5683020.4 | P16: 42822.055 | Q16: -1325573.5 | R16: 0 | S16: 0 | T16: -1105.1765 | W16: -2.2116184e-07 | X16: 2.3773862e-07 | Y16: -6.610749e-08 | Z16: 3.9493185e-08 | AA16: 7.7778652e-09 | AB16: 3.5098734e-08 | AC16: -1.9069057e-24 | AD16: 0 | AE16: 3.9855897e-08 | AF16: 2.0049007e-07 | AG16: 6.5339893e-08 | AH16: 2.8903491e-07 | AI16: 2.8542424e-07 | AJ16: 4.9211076e-07 | AK16: -5.7761937e-08 | AL16: 1.984544e-07 | AM16: 4.973061e-17 | AN16: 1 | AO16: -0.00022776547 | AQ16: -0.00032658866 | AS16: =SQRT(ROUND(AJ16,10))*$AR$3 -> 0.00064825367
B17: -2190966.5 | C17: 700573.58 | D17: -744343.67 | E17: -39464.619 | F17: -1509651.6 | G17: -1029589.2 | H17: -1082062.5 | I17: -521342.94 | J17: 191783.62 | K17: 659043.25 | L17: -2622586.1 | M17: 411244.28 | N17: -743800 | O17: 42822.055 | P17: 8701626.8 | Q17: -223286.45 | R17: 0 | S17: 0 | T17: 0 | W17: 4.9816519e-07 | X17: 8.2062481e-08 | Y17: 4.0236917e-07 | Z17: 3.0154083e-07 | AA17: 1.1949721e-07 | AB17: 2.5856024e-07 | AC17: 4.8556681e-25 | AD17: 0 | AE17: -1.1109107e-08 | AF17: -1.4671616e-07 | AG17: 1.7323402e-07 | AH17: -7.068108e-08 | AI17: -3.3501923e-08 | AJ17: -5.7761937e-08 | AK17: 3.8838352e-07 | AL17: 1.2458864e-07 | AM17: 1 | AN17: -3.586757e-16 | AO17: 0.0003424336 | AQ17: -5.8500553e-05 | AS17: =SQRT(ROUND(AK17,10))*$AR$3 -> 0.00057591437
B18: 974149.92 | C18: -1200086.3 | D18: -404891.06 | E18: -3167112.6 | F18: -326937.09 | G18: -581242.71 | H18: -75983.3 | I18: -349439.44 | J18: 439956.42 | K18: -177985.49 | L18: -498872.06 | M18: -780082.94 | N18: 115863.62 | O18: -1325573.5 | P18: -223286.45 | Q18: 7581523 | R18: 0 | S18: 0 | T18: 0 | W18: 2.3757557e-07 | X18: 2.8615567e-07 | Y18: 2.3924857e-07 | Z18: 4.4320726e-07 | AA18: -2.4740349e-08 | AB18: 2.7577385e-07 | AC18: -3.4180089e-24 | AD18: 0 | AE18: -4.2524288e-08 | AF18: 7.056791e-08 | AG18: 9.5428646e-08 | AH18: 1.5205443e-07 | AI18: 1.1510355e-07 | AJ18: 1.984544e-07 | AK18: 1.2458864e-07 | AL18: 4.2732527e-07 | AM18: 7.7571281e-16 | AN18: 1 | AO18: 2.8274334e-05 | AQ18: 0.0010518508 | AS18: =SQRT(ROUND(AL18,10))*$AR$3 -> 0.0006040665
A19: S | B19: =IF(B$22=$B$49,IF(B$23="dx",1,0),0) -> 0 | C19: =IF(C$22=$B$49,IF(C$23="dx",1,0),0) -> 0 | D19: =IF(D$22=$B$49,IF(D$23="dx",1,0),0) -> 0 | E19: =IF(E$22=$B$49,IF(E$23="dx",1,0),0) -> 0 | F19: =IF(F$22=$B$49,IF(F$23="dx",1,0),0) -> 0 | G19: =IF(G$22=$B$49,IF(G$23="dx",1,0),0) -> 0 | H19: =IF(H$22=$B$49,IF(H$23="dx",1,0),0) -> 1 | I19: =IF(I$22=$B$49,IF(I$23="dx",1,0),0) -> 0 | ... Q19: =IF(Q$22=$B$49,IF(Q$23="dx",1,0),0) -> 0 | R19: 0 | S19: 0 | T19: 0 | V19: S(-1) | W19: 1 | X19: 1.4210855e-16 | Y19: 1 | Z19: 8.5265128e-16 | AA19: 1 | AB19: 6.3948846e-16 | AC19: 1 | AD19: 0 | AE19: 1 | AF19: -2.8421709e-16 | AG19: 1 | AH19: 7.1054274e-17 | AI19: 1 | AJ19: 2.1316282e-16 | AK19: 1 | AL19: 4.9737992e-16 | AM19: 1.3969839e-09 | AN19: 8.3673513e-10 | AO19: 3.9025626e-13
B20: =IF(B$22=$B$49,IF(B$23="dy",1,0),0) -> 0 | C20: =IF(C$22=$B$49,IF(C$23="dy",1,0),0) -> 0 | D20: =IF(D$22=$B$49,IF(D$23="dy",1,0),0) -> 0 | E20: =IF(E$22=$B$49,IF(E$23="dy",1,0),0) -> 0 | F20: =IF(F$22=$B$49,IF(F$23="dy",1,0),0) -> 0 | G20: =IF(G$22=$B$49,IF(G$23="dy",1,0),0) -> 0 | H20: =IF(H$22=$B$49,IF(H$23="dy",1,0),0) -> 0 | I20: =IF(I$22=$B$49,IF(I$23="dy",1,0),0) -> 1 | ... Q20: =IF(Q$22=$B$49,IF(Q$23="dy",1,0),0) -> 0 | R20: 0 | S20: 0 | T20: 0 | W20: 4.0112083e-16 | X20: 1 | Y20: 4.2316636e-16 | Z20: 1 | AA20: 1.4018348e-16 | AB20: 1 | AC20: -8.7366628e-33 | AD20: 1 | AE20: 2.0871177e-17 | AF20: 1 | AG20: 9.8292641e-17 | AH20: 1 | AI20: 3.1477145e-16 | AJ20: 1 | AK20: 1.9507306e-16 | AL20: 1 | AM20: 1.1641532e-09 | AN20: 1.7462298e-09 | AO20: -3.035555e-14
