Workbook

Sheet Dane
B2: ID = 3
B4: Układ obserwacji w pomiarze wyjściowym i aktualnym | I4: Współrzędne przybliżone
B6: p | C6: k | D6: Pomiar wyjściowy | F6: Pomiar aktualny | I6: Nr | J6: Xo | K6: Yo
D7: k [g] | E7: σk [cc] | F7: k' [g] | G7: σk' [cc] | J7: w metrach
B8: St.1 | C8: P1 | D8: 108.01134 | E8: 2 | F8: 108.01716 | G8: 1.5 | I8: P1 | J8: 231.25 | K8: 199.36
B9: St.1 | C9: P2 | D9: 119.7973 | F9: 119.8021 | I9: P2 | J9: 230.99 | K9: 220.77
B10: St.1 | C10: P3 | D10: 130.18516 | F10: 130.17578 | I10: P3 | J10: 231.13 | K10: 253.22
B11: St.2 | C11: K-2,1 | D11: 351.41482 | E11: 2.5 | F11: 168.45464 | G11: 2 | I11: St.1 | J11: 184.51 | K11: 152.15
B12: St.2 | C12: K-2,2 | D12: 327.89606 | F12: 144.93566 | I12: St.2 | J12: 161.07 | K12: 208.17
B13: St.2 | C13: K-2,3 | D13: 287.98024 | F13: 105.02732 | I13: K-2,1 | J13: 71.35 | K13: 106.09
B14: St.2 | C14: K-2,4 | D14: 243.66184 | F14: 60.70744 | I14: K-2,2 | J14: 46.047 | K14: 148.238
B15: St.2 | C15: K-2,5 | D15: 215.42282 | F15: 32.47062 | I15: K-2,3 | J15: 0.408 | K15: 231.906
B16: St.2 | C16: K-2,6 | D16: 169.7481 | F16: 386.79758 | I16: K-2,4 | J16: 57.469 | K16: 324.409
B17: St.2 | C17: P1 | D17: 89.36604 | F17: 306.4245 | I17: K-2,5 | J17: 116.992 | K17: 358.958
B18: St.2 | C18: P2 | D18: 108.67044 | F18: 325.73602 | I18: K-2,6 | J18: 240.304 | K18: 379.551
B19: St.2 | C19: P3 | D19: 133.6999 | F19: 350.75402 | I19: St.3 | J19: 170.41 | K19: 276.097
B20: St.3 | C20: P1 | D20: 131.67682 | E20: 2 | F20: 131.67898 | G20: 2
B21: St.3 | C21: P2 | D21: 141.88194 | F21: 141.88786
B22: St.3 | C22: P3 | D22: 166.06158 | F22: 166.0774
B24: Dane dot. Stanowisk pomiarowych 1 i 3:
B26: Stan. | C26: zs [cc] | D26: ΔX [mm] | E26: ΔY [mm]
B27: 1 | C27: 8.75 | D27: -5.52 | E27: 3.45
B28: 3 | C28: -12.89 | D28: -4.91 | E28: -3.37

Sheet Wyr. wst. i met. analit.-graf.
C2: K | D2: K' | F2: L | H2: σl
B3: K-2,1 | C3: =Dane!D11-Dane!$D$11 -> 0 | D3: =Dane!F11-Dane!$F$11 -> 0 | F3: =D3-C3 -> 0 | H3: =SQRT((Dane!E11/10000)^2+(Dane!G11/10000)^2) -> 0.00032015621
B4: K-2,2 | C4: =Dane!D12-Dane!$D$11+400 -> 376.48124 | D4: =Dane!F12-Dane!$F$11+400 -> 376.48102 | F4: =D4-C4 -> -0.00022
B5: K-2,3 | C5: =Dane!D13-Dane!$D$11+400 -> 336.56542 | D5: =Dane!F13-Dane!$F$11+400 -> 336.57268 | F5: =D5-C5 -> 0.00726
B6: K-2,4 | C6: =Dane!D14-Dane!$D$11+400 -> 292.24702 | D6: =Dane!F14-Dane!$F$11+400 -> 292.2528 | F6: =D6-C6 -> 0.00578
B7: K-2,5 | C7: =Dane!D15-Dane!$D$11+400 -> 264.008 | D7: =Dane!F15-Dane!$F$11+400 -> 264.01598 | F7: =D7-C7 -> 0.00798
B8: K-2,6 | C8: =Dane!D16-Dane!$D$11+400 -> 218.33328 | D8: =Dane!F16-Dane!$F$11 -> 218.34294 | F8: =D8-C8 -> 0.00966
B9: P1 | C9: =Dane!D17-Dane!$D$11+400 -> 137.95122 | D9: =Dane!F17-Dane!$F$11 -> 137.96986 | F9: =D9-C9 -> 0.01864
B10: P2 | C10: =Dane!D18-Dane!$D$11+400 -> 157.25562 | D10: =Dane!F18-Dane!$F$11 -> 157.28138 | F10: =D10-C10 -> 0.02576
B11: P3 | C11: =Dane!D19-Dane!$D$11+400 -> 182.28508 | D11: =Dane!F19-Dane!$F$11 -> 182.29938 | F11: =D11-C11 -> 0.0143
C13: st2-K2,1 | D13: st2-K2,2 | E13: st2-K2,3 | F13: st2-K2,4 | G13: st2-K2,5 | H13: st2-K2,6
B14: ΔX | C14: =Dane!J13-Dane!$J$12 -> -89.72 | D14: =Dane!J14-Dane!$J$12 -> -115.023 | E14: =Dane!J15-Dane!$J$12 -> -160.662 | F14: =Dane!J16-Dane!$J$12 -> -103.601 | G14: =Dane!J17-Dane!$J$12 -> -44.078 | H14: =Dane!J18-Dane!$J$12 -> 79.234
B15: ΔY | C15: =Dane!$K13-Dane!$K$12 -> -102.08 | D15: =Dane!$K14-Dane!$K$12 -> -59.932 | E15: =Dane!$K15-Dane!$K$12 -> 23.736 | F15: =Dane!$K16-Dane!$K$12 -> 116.239 | G15: =Dane!$K17-Dane!$K$12 -> 150.788 | H15: =Dane!$K18-Dane!$K$12 -> 171.381
B16: Dsc | C16: =SQRT(C15^2+C14^2) -> 135.9044 | D16: =SQRT(D15^2+D14^2) -> 129.70017 | E16: =SQRT(E15^2+E14^2) -> 162.4059 | F16: =SQRT(F15^2+F14^2) -> 155.70701 | G16: =SQRT(G15^2+G14^2) -> 157.09835 | H16: =SQRT(H15^2+H14^2) -> 188.81068
B17: a | C17: =C15/C16^2*200/PI() -> -0.35184694 | D17: =D15/D16^2*200/PI() -> -0.22680769 | E17: =E15/E16^2*200/PI() -> 0.057290691 | F17: =F15/F16^2*200/PI() -> 0.30522188 | G17: =G15/G16^2*200/PI() -> 0.38895886 | H17: =H15/H16^2*200/PI() -> 0.30604809
B18: b | C18: =-C14/C16^2*200/PI() -> 0.30924478 | D18: =-D14/D16^2*200/PI() -> 0.43529502 | E18: =-E14/E16^2*200/PI() -> 0.38778383 | F18: =-F14/F16^2*200/PI() -> 0.27203686 | G18: =-G14/G16^2*200/PI() -> 0.11369956 | H18: =-H14/H16^2*200/PI() -> -0.14149418
B19: c | C19: =-C15/C16^2*200/PI() -> 0.35184694 | D19: =-D15/D16^2*200/PI() -> 0.22680769 | E19: =-E15/E16^2*200/PI() -> -0.057290691 | F19: =-F15/F16^2*200/PI() -> -0.30522188 | G19: =-G15/G16^2*200/PI() -> -0.38895886 | H19: =-H15/H16^2*200/PI() -> -0.30604809
B20: d | C20: =C14/C16^2*200/PI() -> -0.30924478 | D20: =D14/D16^2*200/PI() -> -0.43529502 | E20: =E14/E16^2*200/PI() -> -0.38778383 | F20: =F14/F16^2*200/PI() -> -0.27203686 | G20: =G14/G16^2*200/PI() -> -0.11369956 | H20: =H14/H16^2*200/PI() -> 0.14149418
B22: A | F22: AT
B23: Zs | C23: ΔXs | D23: ΔYs | F23: {=TRANSPOSE(B24:D29)} -> -1 | G23: -1 | H23: -1 | I23: -1 | J23: -1 | K23: -1
A24: K-2,1 | B24: -1 | C24: =C17 -> -0.35184694 | D24: =C18 -> 0.30924478 | F24: -0.35184694 | G24: -0.22680769 | H24: 0.057290691 | I24: 0.30522188 | J24: 0.38895886 | K24: 0.30604809
A25: K-2,2 | B25: -1 | C25: =D17 -> -0.22680769 | D25: =D18 -> 0.43529502 | F25: 0.30924478 | G25: 0.43529502 | H25: 0.38778383 | I25: 0.27203686 | J25: 0.11369956 | K25: -0.14149418
A26: K-2,3 | B26: -1 | C26: =E17 -> 0.057290691 | D26: =E18 -> 0.38778383
A27: K-2,4 | B27: -1 | C27: =F17 -> 0.30522188 | D27: =F18 -> 0.27203686 | F27: ATL | H27: X | J27: V
A28: K-2,5 | B28: -1 | C28: =G17 -> 0.38895886 | D28: =G18 -> 0.11369956 | F28: {=MMULT(_xlfn.ANCHORARRAY(F23),F3:F8)} -> -0.03046 | H28: {=MMULT(_xlfn.ANCHORARRAY(B37),_xlfn.ANCHORARRAY(F28))} -> -0.0052283695 | J28: {=MMULT(B24:D29,_xlfn.ANCHORARRAY(H28))-F3:F8} -> 0.0002626277
A29: K-2,6 | B29: -1 | C29: =H17 -> 0.30604809 | D29: =H18 -> -0.14149418 | F29: 0.0082903268 | H29: 0.010363554 | J29: 0.0012406999
F30: 0.0038324074 | H30: -0.0042663844 | J30: -0.0030923302
B31: ATA | J31: 0.0014509391
B32: {=MMULT(_xlfn.ANCHORARRAY(F23),B24:D29)} -> 6 | C32: -0.47886489 | D32: -1.3765659 | F32: VTV | H32: VTL | J32: 0.00079427956
B33: -0.47886489 | C33: 0.51663504 | D33: -0.10136666 | F33: {=MMULT(TRANSPOSE(_xlfn.ANCHORARRAY(J28)),_xlfn.ANCHORARRAY(J28))} -> 1.433754e-05 | H33: {=MMULT(TRANSPOSE(_xlfn.ANCHORARRAY(J28)),F3:F8)} -> -1.433754e-05 | J33: -0.00065621609
B34: -1.3765659 | C34: -0.10136666 | D34: 0.54244263
F35: σ'l | G35: σo | H35: σ'o kryt | I35: kryterium
B36: ATA^-1 | F36: =SQRT(F33/(6-3)) -> 0.0021861335 | G36: =SQRT(F36^2/H3^2) -> 6.828334 | H36: =SQRT(CHIINV(0.05,3)/(6-3)) -> 1.6139731 | I36: =IF(G36^2<=H36^2,TRUE,FALSE) -> FALSE
B37: {=MINVERSE(_xlfn.ANCHORARRAY(B32))} -> 0.70524811 | C37: 1.0430867 | D37: 1.9846425
B38: 1.0430867 | C38: 3.5520342 | D38: 3.31083
B39: 1.9846425 | C39: 3.31083 | D39: 7.498671
B42: p | C42: k | D42: alfa [g] | E42: alfa' [g] | F42: Δ alfa [g] | G42: a [m] | H42: b [m] | I42: c [m] | J42: p [m] | K42: w skali 1:1000
B43: St.2 | C43: K-2,1 | D43: =Dane!D11-Dane!D12 -> 23.51876 | E43: =Dane!F11-Dane!F12 -> 23.51898 | F43: =E43-D43 -> 0.00022 | G43: =C16 -> 135.9044 | H43: =G45 -> 129.70017 | I43: =SQRT((Dane!J14-Dane!J13)^2+(Dane!K14-Dane!K13)^2) -> 49.159899 | J43: =F43*PI()/200*G43*H43/I43 -> 0.0012390979 | K43: =J43*1000 -> 1.2390979
C44: K-2,2
C45: K-2,2 | D45: =Dane!D12-Dane!D13 -> 39.91582 | E45: =Dane!F12-Dane!F13 -> 39.90834 | F45: =E45-D45 -> -0.00748 | G45: =D16 -> 129.70017 | H45: =G47 -> 162.4059 | I45: =SQRT((Dane!J15-Dane!J14)^2+(Dane!K15-Dane!K14)^2) -> 95.306099 | J45: =F45*PI()/200*G45*H45/I45 -> -0.025968277 | K45: =J45*1000 -> -25.968277
...

Sheet Metoda analityczna
A2: Stałe | B2: wartość | C2: jedn. | E2: Wniosek z grafiki | F2: K-2,3 podejrzany | I2: Dane St.2 i współczynniki A
A3: σk | B3: 2.5 | C3: cc | E3: k | F3: 2.5 | I3: Pkt | J3: X | K3: Y | L3: k [g] | M3: k' [g] | N3: l [cc] | O3: a | P3: b | Q3: status | R3: uwagi
A4: σk' | B4: 2 | C4: cc | E4: σl | F4: 3.201562 | G4: cc
I5: K-2,1 | J5: 71.35 | K5: 106.09 | L5: 351.41482 | M5: 168.45464 | N5: 0 | O5: -0.351847 | P5: 0.309245 | Q5: stały/kontrolny
I6: K-2,2 | J6: 46.047 | K6: 148.238 | L6: 327.89606 | M6: 144.93566 | N6: -2.2 | O6: -0.226808 | P6: 0.435295 | Q6: stały/kontrolny
I7: K-2,3 | J7: 0.408 | K7: 231.906 | L7: 287.98024 | M7: 105.02732 | N7: 72.6 | O7: 0.057291 | P7: 0.387784 | Q7: podejrzany | R7: z grafiki
I8: K-2,4 | J8: 57.469 | K8: 324.409 | L8: 243.66184 | M8: 60.70744 | N8: 57.8 | O8: 0.305222 | P8: 0.272037 | Q8: stały/kontrolny
I9: K-2,5 | J9: 116.992 | K9: 358.958 | L9: 215.42282 | M9: 32.47062 | N9: 79.8 | O9: 0.388959 | P9: 0.1137 | Q9: stały/kontrolny
I10: K-2,6 | J10: 240.304 | K10: 379.551 | L10: 169.7481 | M10: 386.79758 | N10: 96.6 | O10: 0.306048 | P10: -0.141494 | Q10: stały/kontrolny
A11: Identyfikacja
A12: Nr | B12: Punkt | C12: A: -1 | D12: A: a | E12: A: b | G12: Aᵀ r1 | H12: Aᵀ r2 | I12: Aᵀ r3 | K12: AᵀA 1 | L12: AᵀA 2 | M12: AᵀA 3 | O12: det(AᵀA) | P12: ocena
A13: 1 | B13: K-2,1 | C13: -1 | D13: -0.351847 | E13: 0.309245 | G13: -1 | H13: -1 | I13: -1 | K13: 3 | L13: 0.521364 | M13: -1.132324
B14: K-2,2 | C14: -1 | D14: -0.226808 | E14: 0.435295 | G14: -0.351847 | H14: -0.226808 | I14: 0.057291 | K14: 0.521364 | L14: 0.17852 | M14: -0.185319 | O14: 0.001743 | P14: zawiera K-2,3
B15: K-2,3 | C15: -1 | D15: 0.057291 | E15: 0.387784 | G15: 0.309245 | H15: 0.435295 | I15: 0.387784 | K15: -1.132324 | L15: -0.185319 | M15: 0.435491
A16: 2 | B16: K-2,1 | C16: -1 | D16: -0.351847 | E16: 0.309245 | G16: -1 | H16: -1 | I16: -1 | K16: 3 | L16: 0.273433 | M16: -1.016577
B17: K-2,2 | C17: -1 | D17: -0.226808 | E17: 0.435295 | G17: -0.351847 | H17: -0.226808 | I17: 0.305222 | K17: 0.273433 | L17: 0.268399 | M17: -0.124504 | O17: 0.007652 | P17: bez K-2,3
B18: K-2,4 | C18: -1 | D18: 0.305222 | E18: 0.272037 | G18: 0.309245 | H18: 0.435295 | I18: 0.272037 | K18: -1.016577 | L18: -0.124504 | M18: 0.359118
A19: 3 | B19: K-2,1 | C19: -1 | D19: -0.351847 | E19: 0.309245 | G19: -1 | H19: -1 | I19: -1 | K19: 3 | L19: 0.189696 | M19: -0.85824
B20: K-2,2 | C20: -1 | D20: -0.226808 | E20: 0.435295 | G20: -0.351847 | H20: -0.226808 | I20: 0.388959 | K20: 0.189696 | L20: 0.326527 | M20: -0.163311 | O20: 0.013884 | P20: bez K-2,3
B21: K-2,5 | C21: -1 | D21: 0.388959 | E21: 0.1137 | G21: 0.309245 | H21: 0.435295 | I21: 0.1137 | K21: -0.85824 | L21: -0.163311 | M21: 0.298042
A22: 4 | B22: K-2,1 | C22: -1 | D22: -0.351847 | E22: 0.309245 | G22: -1 | H22: -1 | I22: -1 | K22: 3 | L22: 0.272607 | M22: -0.603046
B23: K-2,2 | C23: -1 | D23: -0.226808 | E23: 0.435295 | G23: -0.351847 | H23: -0.226808 | I23: 0.306048 | K23: 0.272607 | L23: 0.268904 | M23: -0.250839 | O23: 0.019401 | P23: bez K-2,3
B24: K-2,6 | C24: -1 | D24: 0.306048 | E24: -0.141494 | G24: 0.309245 | H24: 0.435295 | I24: -0.141494 | K24: -0.603046 | L24: -0.250839 | M24: 0.305135
A25: 5 | B25: K-2,1 | C25: -1 | D25: -0.351847 | E25: 0.309245 | G25: -1 | H25: -1 | I25: -1 | K25: 3 | L25: -0.010666 | M25: -0.969066
B26: K-2,3 | C26: -1 | D26: 0.057291 | E26: 0.387784 | G26: -0.351847 | H26: 0.057291 | I26: 0.305222 | K26: -0.010666 | L26: 0.220239 | M26: -0.003559 | O26: 0.004466 | P26: zawiera K-2,3
B27: K-2,4 | C27: -1 | D27: 0.305222 | E27: 0.272037 | G27: 0.309245 | H27: 0.387784 | I27: 0.272037 | K27: -0.969066 | L27: -0.003559 | M27: 0.320013
A28: 6 | B28: K-2,1 | C28: -1 | D28: -0.351847 | E28: 0.309245 | G28: -1 | H28: -1 | I28: -1 | K28: 3 | L28: -0.094403 | M28: -0.810728
B29: K-2,3 | C29: -1 | D29: 0.057291 | E29: 0.387784 | G29: -0.351847 | H29: 0.057291 | I29: 0.388959 | K29: -0.094403 | L29: 0.278368 | M29: -0.042366 | O29: 0.019096 | P29: zawiera K-2,3
B30: K-2,5 | C30: -1 | D30: 0.388959 | E30: 0.1137 | G30: 0.309245 | H30: 0.387784 | I30: 0.1137 | K30: -0.810728 | L30: -0.042366 | M30: 0.258936
A31: 7 | B31: K-2,1 | C31: -1 | D31: -0.351847 | E31: 0.309245 | G31: -1 | H31: -1 | I31: -1 | K31: 3 | L31: -0.011492 | M31: -0.555535
B32: K-2,3 | C32: -1 | D32: 0.057291 | E32: 0.387784 | G32: -0.351847 | H32: 0.057291 | I32: 0.306048 | K32: -0.011492 | L32: 0.220744 | M32: -0.129895 | O32: 0.055736 | P32: zawiera K-2,3
B33: K-2,6 | C33: -1 | D33: 0.306048 | E33: -0.141494 | G33: 0.309245 | H33: 0.387784 | I33: -0.141494 | K33: -0.555535 | L33: -0.129895 | M33: 0.266029
A34: 8 | B34: K-2,1 | C34: -1 | D34: -0.351847 | E34: 0.309245 | G34: -1 | H34: -1 | I34: -1 | K34: 3 | L34: -0.342334 | M34: -0.694981
B35: K-2,4 | C35: -1 | D35: 0.305222 | E35: 0.272037 | G35: -0.351847 | H35: 0.305222 | I35: 0.388959 | K35: -0.342334 | L35: 0.368246 | M35: 0.018449 | O35: 0.010185 | P35: bez K-2,3
B36: K-2,5 | C36: -1 | D36: 0.388959 | E36: 0.1137 | G36: 0.309245 | H36: 0.272037 | I36: 0.1137 | K36: -0.694981 | L36: 0.018449 | M36: 0.182564
A37: 9 | B37: K-2,1 | C37: -1 | D37: -0.351847 | E37: 0.309245 | G37: -1 | H37: -1 | I37: -1 | K37: 3 | L37: -0.259423 | M37: -0.439788
B38: K-2,4 | C38: -1 | D38: 0.305222 | E38: 0.272037 | G38: -0.351847 | H38: 0.305222 | I38: 0.306048 | K38: -0.259423 | L38: 0.310622 | M38: -0.069079 | O38: 0.073814 | P38: bez K-2,3
B39: K-2,6 | C39: -1 | D39: 0.306048 | E39: -0.141494 | G39: 0.309245 | H39: 0.272037 | I39: -0.141494 | K39: -0.439788 | L39: -0.069079 | M39: 0.189657
A40: 10 | B40: K-2,1 | C40: -1 | D40: -0.351847 | E40: 0.309245 | G40: -1 | H40: -1 | I40: -1 | K40: 3 | L40: -0.34316 | M40: -0.28145
B41: K-2,5 | C41: -1 | D41: 0.388959 | E41: 0.1137 | G41: -0.351847 | H41: 0.388959 | I41: 0.306048 | K41: -0.34316 | L41: 0.368751 | M41: -0.107886 | O41: 0.042132 | P41: bez K-2,3
...

Sheet Wartości przemieszczeń
B1: WARTOŚCI PRZEMIESZCZEŃ – NASZE DANE / FORMUŁY
C2: Współrzędne przybliżone | E2: Stała orientacyjna przemieszczenia | H2: Różnice kierunków l | K2: Błąd średni
B3: St | C3: Xs [m] | D3: Ys [m] | E3: Zs [g] | F3: ∆Xs [m] | G3: ∆Ys [m] | H3: l1 | I3: l2 | J3: l3 | K3: σlq [g]
B4: 1 | C4: =Dane!J11 -> 184.51 | D4: =Dane!K11 -> 152.15 | E4: =Dane!C27/10000 -> 0.000875 | F4: =Dane!D27/1000 -> -0.00552 | G4: =Dane!E27/1000 -> 0.00345 | H4: =Dane!F8-Dane!D8 -> 0.00582 | I4: =Dane!F9-Dane!D9 -> 0.0048 | J4: =Dane!F10-Dane!D10 -> -0.00938 | K4: =SQRT(Dane!E8^2+Dane!G8^2)/10000 -> 0.00025
B5: 2 | C5: =Dane!J12 -> 161.07 | D5: =Dane!K12 -> 208.17 | E5: ='Metoda analityczna'!A93 -> 0 | F5: ='Metoda analityczna'!B93 -> 0 | G5: ='Metoda analityczna'!C93 -> 0 | H5: ='Wyr. wst. i met. analit.-graf.'!F9 -> 0.01864 | I5: ='Wyr. wst. i met. analit.-graf.'!F10 -> 0.02576 | J5: ='Wyr. wst. i met. analit.-graf.'!F11 -> 0.0143 | K5: =SQRT(Dane!E11^2+Dane!G11^2)/10000 -> 0.00032015621 | L5: S2: Metoda analityczna - nasze, wiersz 98 (K-2,3 pominięty)
B6: 3 | C6: =Dane!J19 -> 170.41 | D6: =Dane!K19 -> 276.097 | E6: =Dane!C28/10000 -> -0.001289 | F6: =Dane!D28/1000 -> -0.00491 | G6: =Dane!E28/1000 -> -0.00337 | H6: =Dane!F20-Dane!D20 -> 0.00216 | I6: =Dane!F21-Dane!D21 -> 0.00592 | J6: =Dane!F22-Dane!D22 -> 0.01582 | K6: =SQRT(Dane!E20^2+Dane!G20^2)/10000 -> 0.00028284271
C8: Współrzędne przybliżone | F8: Współczynnik c | K8: Współczynnik d
C9: X | D9: Y | F9: St\Pkt | G9: P1 | H9: P2 | I9: P3 | K9: St\Pkt | L9: P1 | M9: P2 | N9: P3
B10: P1 | C10: =Dane!J8 -> 231.25 | D10: =Dane!K8 -> 199.36 | F10: 1 | G10: =-((D$10-D4)/((C$10-C4)^2+(D$10-D4)^2))*200/PI() -> -0.68098835 | H10: =-((D$11-D4)/((C$11-C4)^2+(D$11-D4)^2))*200/PI() -> -0.63596223 | I10: =-((D$12-D4)/((C$12-C4)^2+(D$12-D4)^2))*200/PI() -> -0.51937523 | K10: 1 | L10: =((C$10-C4)/((C$10-C4)^2+(D$10-D4)^2))*200/PI() -> 0.67420876 | M10: =((C$11-C4)/((C$11-C4)^2+(D$11-D4)^2))*200/PI() -> 0.43077127 | N10: =((C$12-C4)/((C$12-C4)^2+(D$12-D4)^2))*200/PI() -> 0.23956934
B11: P2 | C11: =Dane!J9 -> 230.99 | D11: =Dane!K9 -> 220.77 | F11: 2 | G11: =-((D$10-D5)/((C$10-C5)^2+(D$10-D5)^2))*200/PI() -> 0.11210854 | H11: =-((D$11-D5)/((C$11-C5)^2+(D$11-D5)^2))*200/PI() -> -0.15891637 | I11: =-((D$12-D5)/((C$12-C5)^2+(D$12-D5)^2))*200/PI() -> -0.41337718 | K11: 2 | L11: =((C$10-C5)/((C$10-C5)^2+(D$10-D5)^2))*200/PI() -> 0.89305074 | M11: =((C$11-C5)/((C$11-C5)^2+(D$11-D5)^2))*200/PI() -> 0.88185971 | N11: =((C$12-C5)/((C$12-C5)^2+(D$12-D5)^2))*200/PI() -> 0.64286804
B12: P3 | C12: =Dane!J10 -> 231.13 | D12: =Dane!K10 -> 253.22 | F12: 3 | G12: =-((D$10-D6)/((C$10-C6)^2+(D$10-D6)^2))*200/PI() -> 0.5094048 | H12: =-((D$11-D6)/((C$11-C6)^2+(D$11-D6)^2))*200/PI() -> 0.5232832 | I12: =-((D$12-D6)/((C$12-C6)^2+(D$12-D6)^2))*200/PI() -> 0.34591443 | K12: 3 | L12: =((C$10-C6)/((C$10-C6)^2+(D$10-D6)^2))*200/PI() -> 0.40387542 | M12: =((C$11-C6)/((C$11-C6)^2+(D$11-D6)^2))*200/PI() -> 0.57296612 | N12: =((C$12-C6)/((C$12-C6)^2+(D$12-D6)^2))*200/PI() -> 0.91812406
D20: Macierz a
D21: ΔXP1 | E21: ΔYP1 | F21: ΔXP2 | G21: ΔYP2 | H21: ΔXP3 | I21: ΔYP3 | J21: -Zs+ε [g] | K21: K'- K [g] | L21: K'-K-Zs+ε [g] | M21: σlq [g] | N21: p
B22: P1 | C22: St 1 | D22: =G10 -> -0.68098835 | E22: =L10 -> 0.67420876 | F22: 0 | G22: 0 | H22: 0 | I22: 0 | J22: =-E4-G10*F4-L10*G4 -> -0.0069600759 | K22: =H4 -> 0.00582 | L22: =K22-J22 -> 0.012780076 | M22: =K4 -> 0.00025 | N22: =SQRT(1/M22^2) -> 4000
C23: St 2 | D23: =G11 -> 0.11210854 | E23: =L11 -> 0.89305074 | F23: 0 | G23: 0 | H23: 0 | I23: 0 | J23: =-E5-G11*F5-L11*G5 -> 0 | K23: =H5 -> 0.01864 | L23: =K23-J23 -> 0.01864 | M23: =K5 -> 0.00032015621 | N23: =SQRT(1/M23^2) -> 3123.4752
C24: St 3 | D24: =G12 -> 0.5094048 | E24: =L12 -> 0.40387542 | F24: 0 | G24: 0 | H24: 0 | I24: 0 | J24: =-E6-G12*F6-L12*G6 -> 0.0051512378 | K24: =H6 -> 0.00216 | L24: =K24-J24 -> -0.0029912378 | M24: =K6 -> 0.00028284271 | N24: =SQRT(1/M24^2) -> 3535.5339
B25: P2 | C25: St 1 | D25: 0 | E25: 0 | F25: =H10 -> -0.63596223 | G25: =M10 -> 0.43077127 | H25: 0 | I25: 0 | J25: =-E4-H10*F4-M10*G4 -> -0.0058716724 | K25: =I4 -> 0.0048 | L25: =K25-J25 -> 0.010671672 | M25: =K4 -> 0.00025 | N25: =SQRT(1/M25^2) -> 4000
C26: St 2 | D26: 0 | E26: 0 | F26: =H11 -> -0.15891637 | G26: =M11 -> 0.88185971 | H26: 0 | I26: 0 | J26: =-E5-H11*F5-M11*G5 -> 0 | K26: =I5 -> 0.02576 | L26: =K26-J26 -> 0.02576 | M26: =K5 -> 0.00032015621 | N26: =SQRT(1/M26^2) -> 3123.4752
C27: St 3 | D27: 0 | E27: 0 | F27: =H12 -> 0.5232832 | G27: =M12 -> 0.57296612 | H27: 0 | I27: 0 | J27: =-E6-H12*F6-M12*G6 -> 0.0057892163 | K27: =I6 -> 0.00592 | L27: =K27-J27 -> 0.00013078365 | M27: =K6 -> 0.00028284271 | N27: =SQRT(1/M27^2) -> 3535.5339
B28: P3 | C28: St 1 | D28: 0 | E28: 0 | F28: 0 | G28: 0 | H28: =I10 -> -0.51937523 | I28: =N10 -> 0.23956934 | J28: =-E4-I10*F4-N10*G4 -> -0.0045684655 | K28: =J4 -> -0.00938 | L28: =K28-J28 -> -0.0048115345 | M28: =K4 -> 0.00025 | N28: =SQRT(1/M28^2) -> 4000
C29: St 2 | D29: 0 | E29: 0 | F29: 0 | G29: 0 | H29: =I11 -> -0.41337718 | I29: =N11 -> 0.64286804 | J29: =-E5-I11*F5-N11*G5 -> 0 | K29: =J5 -> 0.0143 | L29: =K29-J29 -> 0.0143 | M29: =K5 -> 0.00032015621 | N29: =SQRT(1/M29^2) -> 3123.4752
C30: St 3 | D30: 0 | E30: 0 | F30: 0 | G30: 0 | H30: =I12 -> 0.34591443 | I30: =N12 -> 0.91812406 | J30: =-E6-I12*F6-N12*G6 -> 0.0060815179 | K30: =J6 -> 0.01582 | L30: =K30-J30 -> 0.0097384821 | M30: =K6 -> 0.00028284271 | N30: =SQRT(1/M30^2) -> 3535.5339
B32: A | I32: L | K32: AT
B33: ΔXP1 | C33: ΔYP1 | D33: ΔXP2 | E33: ΔYP2 | F33: ΔXP3 | G33: ΔYP3 | K33: =INDEX($B$34:$G$42,1,1) -> -2723.9534 | L33: =INDEX($B$34:$G$42,2,1) -> 350.16824 | M33: =INDEX($B$34:$G$42,3,1) -> 1801.018 | N33: =INDEX($B$34:$G$42,4,1) -> 0 | O33: =INDEX($B$34:$G$42,5,1) -> 0 | P33: =INDEX($B$34:$G$42,6,1) -> 0 | Q33: =INDEX($B$34:$G$42,7,1) -> 0 | R33: =INDEX($B$34:$G$42,8,1) -> 0 | S33: =INDEX($B$34:$G$42,9,1) -> 0
B34: =D22*N22 -> -2723.9534 | C34: =E22*N22 -> 2696.835 | D34: 0 | E34: 0 | F34: 0 | G34: 0 | I34: =L22*N22 -> 51.120304 | K34: =INDEX($B$34:$G$42,1,2) -> 2696.835 | L34: =INDEX($B$34:$G$42,2,2) -> 2789.4219 | M34: =INDEX($B$34:$G$42,3,2) -> 1427.9153 | N34: =INDEX($B$34:$G$42,4,2) -> 0 | O34: =INDEX($B$34:$G$42,5,2) -> 0 | P34: =INDEX($B$34:$G$42,6,2) -> 0 | Q34: =INDEX($B$34:$G$42,7,2) -> 0 | R34: =INDEX($B$34:$G$42,8,2) -> 0 | S34: =INDEX($B$34:$G$42,9,2) -> 0
B35: =D23*N23 -> 350.16824 | C35: =E23*N23 -> 2789.4219 | D35: 0 | E35: 0 | F35: 0 | G35: 0 | I35: =L23*N23 -> 58.221578 | K35: =INDEX($B$34:$G$42,1,3) -> 0 | L35: =INDEX($B$34:$G$42,2,3) -> 0 | M35: =INDEX($B$34:$G$42,3,3) -> 0 | N35: =INDEX($B$34:$G$42,4,3) -> -2543.8489 | O35: =INDEX($B$34:$G$42,5,3) -> -496.37134 | P35: =INDEX($B$34:$G$42,6,3) -> 1850.0855 | Q35: =INDEX($B$34:$G$42,7,3) -> 0 | R35: =INDEX($B$34:$G$42,8,3) -> 0 | S35: =INDEX($B$34:$G$42,9,3) -> 0
B36: =D24*N24 -> 1801.018 | C36: =E24*N24 -> 1427.9153 | D36: 0 | E36: 0 | F36: 0 | G36: 0 | I36: =L24*N24 -> -10.575623 | K36: =INDEX($B$34:$G$42,1,4) -> 0 | L36: =INDEX($B$34:$G$42,2,4) -> 0 | M36: =INDEX($B$34:$G$42,3,4) -> 0 | N36: =INDEX($B$34:$G$42,4,4) -> 1723.0851 | O36: =INDEX($B$34:$G$42,5,4) -> 2754.467 | P36: =INDEX($B$34:$G$42,6,4) -> 2025.7411 | Q36: =INDEX($B$34:$G$42,7,4) -> 0 | R36: =INDEX($B$34:$G$42,8,4) -> 0 | S36: =INDEX($B$34:$G$42,9,4) -> 0
B37: 0 | C37: 0 | D37: =F25*N25 -> -2543.8489 | E37: =G25*N25 -> 1723.0851 | F37: 0 | G37: 0 | I37: =L25*N25 -> 42.68669 | K37: =INDEX($B$34:$G$42,1,5) -> 0 | L37: =INDEX($B$34:$G$42,2,5) -> 0 | M37: =INDEX($B$34:$G$42,3,5) -> 0 | N37: =INDEX($B$34:$G$42,4,5) -> 0 | O37: =INDEX($B$34:$G$42,5,5) -> 0 | P37: =INDEX($B$34:$G$42,6,5) -> 0 | Q37: =INDEX($B$34:$G$42,7,5) -> -2077.5009 | R37: =INDEX($B$34:$G$42,8,5) -> -1291.1734 | S37: =INDEX($B$34:$G$42,9,5) -> 1222.9922
B38: 0 | C38: 0 | D38: =F26*N26 -> -496.37134 | E38: =G26*N26 -> 2754.467 | F38: 0 | G38: 0 | I38: =L26*N26 -> 80.460722 | K38: =INDEX($B$34:$G$42,1,6) -> 0 | L38: =INDEX($B$34:$G$42,2,6) -> 0 | M38: =INDEX($B$34:$G$42,3,6) -> 0 | N38: =INDEX($B$34:$G$42,4,6) -> 0 | O38: =INDEX($B$34:$G$42,5,6) -> 0 | P38: =INDEX($B$34:$G$42,6,6) -> 0 | Q38: =INDEX($B$34:$G$42,7,6) -> 958.27736 | R38: =INDEX($B$34:$G$42,8,6) -> 2007.9824 | S38: =INDEX($B$34:$G$42,9,6) -> 3246.0587
B39: 0 | C39: 0 | D39: =F27*N27 -> 1850.0855 | E39: =G27*N27 -> 2025.7411 | F39: 0 | G39: 0 | I39: =L27*N27 -> 0.46239004
B40: 0 | C40: 0 | D40: 0 | E40: 0 | F40: =H28*N28 -> -2077.5009 | G40: =I28*N28 -> 958.27736 | I40: =L28*N28 -> -19.246138
B41: 0 | C41: 0 | D41: 0 | E41: 0 | F41: =H29*N29 -> -1291.1734 | G41: =I29*N29 -> 2007.9824 | I41: =L29*N29 -> 44.665696
B42: 0 | C42: 0 | D42: 0 | E42: 0 | F42: =H30*N30 -> 1222.9922 | G42: =I30*N30 -> 3246.0587 | I42: =L30*N30 -> 34.430734 | K42: ATA | R42: ATL
K43: =K33*B34+L33*B35+M33*B36+N33*B37+O33*B38+P33*B39+Q33*B40+R33*B41+S33*B42 -> 10786206 | L43: =K33*C34+L33*C35+M33*C36+N33*C37+O33*C38+P33*C39+Q33*C40+R33*C41+S33*C42 -> -3797585 | M43: =K33*D34+L33*D35+M33*D36+N33*D37+O33*D38+P33*D39+Q33*D40+R33*D41+S33*D42 -> 0 | N43: =K33*E34+L33*E35+M33*E36+N33*E37+O33*E38+P33*E39+Q33*E40+R33*E41+S33*E42 -> 0 | O43: =K33*F34+L33*F35+M33*F36+N33*F37+O33*F38+P33*F39+Q33*F40+R33*F41+S33*F42 -> 0 | P43: =K33*G34+L33*G35+M33*G36+N33*G37+O33*G38+P33*G39+Q33*G40+R33*G41+S33*G42 -> 0 | R43: =K33*I34+L33*I35+M33*I36+N33*I37+O33*I38+P33*I39+Q33*I40+R33*I41+S33*I42 -> -137908.86
K44: =K34*B34+L34*B35+M34*B36+N34*B37+O34*B38+P34*B39+Q34*B40+R34*B41+S34*B42 -> -3797585 | L44: =K34*C34+L34*C35+M34*C36+N34*C37+O34*C38+P34*C39+Q34*C40+R34*C41+S34*C42 -> 17092736 | M44: =K34*D34+L34*D35+M34*D36+N34*D37+O34*D38+P34*D39+Q34*D40+R34*D41+S34*D42 -> 0 | N44: =K34*E34+L34*E35+M34*E36+N34*E37+O34*E38+P34*E39+Q34*E40+R34*E41+S34*E42 -> 0 | O44: =K34*F34+L34*F35+M34*F36+N34*F37+O34*F38+P34*F39+Q34*F40+R34*F41+S34*F42 -> 0 | P44: =K34*G34+L34*G35+M34*G36+N34*G37+O34*G38+P34*G39+Q34*G40+R34*G41+S34*G42 -> 0 | R44: =K34*I34+L34*I35+M34*I36+N34*I37+O34*I38+P34*I39+Q34*I40+R34*I41+S34*I42 -> 285166.48
K45: =K35*B34+L35*B35+M35*B36+N35*B37+O35*B38+P35*B39+Q35*B40+R35*B41+S35*B42 -> 0 | L45: =K35*C34+L35*C35+M35*C36+N35*C37+O35*C38+P35*C39+Q35*C40+R35*C41+S35*C42 -> 0 | M45: =K35*D34+L35*D35+M35*D36+N35*D37+O35*D38+P35*D39+Q35*D40+R35*D41+S35*D42 -> 10140368 | N45: =K35*E34+L35*E35+M35*E36+N35*E37+O35*E38+P35*E39+Q35*E40+R35*E41+S35*E42 -> -2002712.3 | O45: =K35*F34+L35*F35+M35*F36+N35*F37+O35*F38+P35*F39+Q35*F40+R35*F41+S35*F42 -> 0 | P45: =K35*G34+L35*G35+M35*G36+N35*G37+O35*G38+P35*G39+Q35*G40+R35*G41+S35*G42 -> 0 | R45: =K35*I34+L35*I35+M35*I36+N35*I37+O35*I38+P35*I39+Q35*I40+R35*I41+S35*I42 -> -147671.43
B46: (ATA)^-1 | K46: =K36*B34+L36*B35+M36*B36+N36*B37+O36*B38+P36*B39+Q36*B40+R36*B41+S36*B42 -> 0 | L46: =K36*C34+L36*C35+M36*C36+N36*C37+O36*C38+P36*C39+Q36*C40+R36*C41+S36*C42 -> 0 | M46: =K36*D34+L36*D35+M36*D36+N36*D37+O36*D38+P36*D39+Q36*D40+R36*D41+S36*D42 -> -2002712.3 | N46: =K36*E34+L36*E35+M36*E36+N36*E37+O36*E38+P36*E39+Q36*E40+R36*E41+S36*E42 -> 14659738 | O46: =K36*F34+L36*F35+M36*F36+N36*F37+O36*F38+P36*F39+Q36*F40+R36*F41+S36*F42 -> 0 | P46: =K36*G34+L36*G35+M36*G36+N36*G37+O36*G38+P36*G39+Q36*G40+R36*G41+S36*G42 -> 0 | R46: =K36*I34+L36*I35+M36*I36+N36*I37+O36*I38+P36*I39+Q36*I40+R36*I41+S36*I42 -> 296115.88
B47: =INDEX(MINVERSE($K$43:$P$48),1,1) -> 1.0057857e-07 | C47: =INDEX(MINVERSE($K$43:$P$48),1,2) -> 2.2346082e-08 | D47: =INDEX(MINVERSE($K$43:$P$48),1,3) -> 0 | E47: =INDEX(MINVERSE($K$43:$P$48),1,4) -> 0 | F47: =INDEX(MINVERSE($K$43:$P$48),1,5) -> 0 | G47: =INDEX(MINVERSE($K$43:$P$48),1,6) -> 0 | K47: =K37*B34+L37*B35+M37*B36+N37*B37+O37*B38+P37*B39+Q37*B40+R37*B41+S37*B42 -> 0 | L47: =K37*C34+L37*C35+M37*C36+N37*C37+O37*C38+P37*C39+Q37*C40+R37*C41+S37*C42 -> 0 | M47: =K37*D34+L37*D35+M37*D36+N37*D37+O37*D38+P37*D39+Q37*D40+R37*D41+S37*D42 -> 0 | N47: =K37*E34+L37*E35+M37*E36+N37*E37+O37*E38+P37*E39+Q37*E40+R37*E41+S37*E42 -> 0 | O47: =K37*F34+L37*F35+M37*F36+N37*F37+O37*F38+P37*F39+Q37*F40+R37*F41+S37*F42 -> 7478848.7 | P47: =K37*G34+L37*G35+M37*G36+N37*G37+O37*G38+P37*G39+Q37*G40+R37*G41+S37*G42 -> -613571.09 | R47: =K37*I34+L37*I35+M37*I36+N37*I37+O37*I38+P37*I39+Q37*I40+R37*I41+S37*I42 -> 24421.23
B48: =INDEX(MINVERSE($K$43:$P$48),2,1) -> 2.2346082e-08 | C48: =INDEX(MINVERSE($K$43:$P$48),2,2) -> 6.3469135e-08 | D48: =INDEX(MINVERSE($K$43:$P$48),2,3) -> 0 | E48: =INDEX(MINVERSE($K$43:$P$48),2,4) -> 0 | F48: =INDEX(MINVERSE($K$43:$P$48),2,5) -> 0 | G48: =INDEX(MINVERSE($K$43:$P$48),2,6) -> 0 | K48: =K38*B34+L38*B35+M38*B36+N38*B37+O38*B38+P38*B39+Q38*B40+R38*B41+S38*B42 -> 0 | L48: =K38*C34+L38*C35+M38*C36+N38*C37+O38*C38+P38*C39+Q38*C40+R38*C41+S38*C42 -> 0 | M48: =K38*D34+L38*D35+M38*D36+N38*D37+O38*D38+P38*D39+Q38*D40+R38*D41+S38*D42 -> 0 | N48: =K38*E34+L38*E35+M38*E36+N38*E37+O38*E38+P38*E39+Q38*E40+R38*E41+S38*E42 -> 0 | O48: =K38*F34+L38*F35+M38*F36+N38*F37+O38*F38+P38*F39+Q38*F40+R38*F41+S38*F42 -> -613571.09 | P48: =K38*G34+L38*G35+M38*G36+N38*G37+O38*G38+P38*G39+Q38*G40+R38*G41+S38*G42 -> 15487186 | R48: =K38*I34+L38*I35+M38*I36+N38*I37+O38*I38+P38*I39+Q38*I40+R38*I41+S38*I42 -> 183008.98
B49: =INDEX(MINVERSE($K$43:$P$48),3,1) -> 0 | C49: =INDEX(MINVERSE($K$43:$P$48),3,2) -> 0 | D49: =INDEX(MINVERSE($K$43:$P$48),3,3) -> 1.0135027e-07 | E49: =INDEX(MINVERSE($K$43:$P$48),3,4) -> 1.3845776e-08 | F49: =INDEX(MINVERSE($K$43:$P$48),3,5) -> 0 | G49: =INDEX(MINVERSE($K$43:$P$48),3,6) -> 0
...
