Workbook

Sheet Dane
A4: Wyniki pomiaru wyjściowego | F4: Wyniki pomiaru aktualnego | J4: Numer ID | K4: 3
A5: c | B5: l | C5: p | D5: Lobs. | E5: c | F5: l | G5: p | H5: Lobs. | J5: σβ | K5: 3 | L5: cc
A6: 7 | B6: 1 | C6: 0 | D6: 271.7062 | E6: 7 | F6: 1 | G6: 0 | H6: 271.702 | J6: σd | K6: 0,001+10-6d | L6: [m]
A7: 7 | B7: 5 | C7: 0 | D7: 155.7243 | E7: 7 | F7: 5 | G7: 0 | H7: 155.7279
A8: 7 | B8: 6 | C8: 0 | D8: 178.4659 | E8: 7 | F8: 6 | G8: 0 | H8: 178.4685 | J8: ρcc | K8: 636619.77
A9: 7 | B9: 8 | C9: 0 | D9: 148.0717 | E9: 7 | F9: 8 | G9: 0 | H9: 148.0689
A10: 7 | B10: 9 | C10: 0 | D10: 174.5226 | E10: 7 | F10: 9 | G10: 0 | H10: 174.522 | J10: n (obserwacje) | K10: 32
A11: 8 | B11: 1 | C11: 0 | D11: 149.9983 | E11: 8 | F11: 1 | G11: 0 | H11: 150.0006 | J11: u (niewiadome) | K11: 16
A12: 8 | B12: 9 | C12: 0 | D12: 166.1118 | E12: 8 | F12: 9 | G12: 0 | H12: 166.1145 | J12: d (defekt) | K12: 3
A13: 8 | B13: 7 | C13: 0 | D13: 148.0732 | E13: 8 | F13: 7 | G13: 0 | H13: 148.0712
A14: 8 | B14: 6 | C14: 0 | D14: 320.0413 | E14: 8 | F14: 6 | G14: 0 | H14: 320.0445
A15: 1 | B15: 3 | C15: 0 | D15: 266.1756 | E15: 1 | F15: 2 | G15: 0 | H15: 147.1241
A16: 1 | B16: 9 | C16: 0 | D16: 168.6215 | E16: 1 | F16: 9 | G16: 0 | H16: 168.6108 | J16: Współrzędne przybliżone
A17: 1 | B17: 7 | C17: 0 | D17: 271.7081 | E17: 1 | F17: 7 | G17: 0 | H17: 271.7008 | J17: Nr | K17: X0 | L17: Y0
A18: 3 | B18: 5 | C18: 0 | D18: 304.0138 | E18: 2 | F18: 8 | G18: 0 | H18: 253.4723 | J18: 1 | K18: 240 | L18: 120
A19: 3 | B19: 9 | C19: 0 | D19: 164.2349 | E19: 2 | F19: 9 | G19: 0 | H19: 145.9865 | J19: 2 | K19: 385 | L19: 145
A20: 3 | B20: 4 | C20: 0 | D20: 194.1629 | E20: 2 | F20: 4 | G20: 0 | H20: 294.2725 | J20: 3 | K20: 475 | L20: 245
A21: 4 | B21: 5 | C21: 0 | D21: 150.4167 | E21: 4 | F21: 5 | G21: 0 | H21: 150.4243 | J21: 4 | K21: 435 | L21: 435
A22: 4 | B22: 7 | C22: 0 | D22: 259.8561 | E22: 4 | F22: 7 | G22: 0 | H22: 259.868 | J22: 5 | K22: 295 | L22: 490
A23: 4 | B23: 9 | C23: 0 | D23: 203.6004 | E23: 4 | F23: 9 | G23: 0 | H23: 203.6019 | J23: 6 | K23: 145 | L23: 560
A24: 6 | B24: 9 | C24: 0 | D24: 333.4194 | E24: 6 | F24: 9 | G24: 0 | H24: 333.4174 | J24: 7 | K24: 180 | L24: 385
A25: 6 | B25: 5 | C25: 0 | D25: 165.528 | E25: 6 | F25: 5 | G25: 0 | H25: 165.5303 | J25: 8 | K25: 150 | L25: 240
A26: 9 | B26: 1 | C26: 3 | D26: 117.9893 | E26: 9 | F26: 1 | G26: 2 | H26: 61.3342 | J26: 9 | K26: 313 | L26: 272
A27: 9 | B27: 3 | C27: 4 | D27: 69.6093 | E27: 9 | F27: 2 | G27: 4 | H27: 126.2606
A28: 9 | B28: 4 | C28: 5 | D28: 46.1487 | E28: 9 | F28: 4 | G28: 5 | H28: 46.1513
A29: 9 | B29: 5 | C29: 7 | D29: 49.92 | E29: 9 | F29: 5 | G29: 7 | H29: 49.9219
A30: 9 | B30: 7 | C30: 8 | D30: 57.1766 | E30: 9 | F30: 7 | G30: 8 | H30: 57.1764
A31: 9 | B31: 8 | C31: 1 | D31: 59.1555 | E31: 9 | F31: 8 | G31: 1 | H31: 59.1567
A32: 6 | B32: 8 | C32: 7 | D32: 11.5719 | E32: 6 | F32: 8 | G32: 7 | H32: 11.5714
A33: 6 | B33: 7 | C33: 9 | D33: 21.0515 | E33: 6 | F33: 7 | G33: 9 | H33: 21.0531
A34: 6 | B34: 9 | C34: 5 | D34: 38.5847 | E34: 6 | F34: 9 | G34: 5 | H34: 38.5857
A35: 5 | B35: 6 | C35: 7 | D35: 74.9047 | E35: 5 | F35: 6 | G35: 7 | H35: 74.9054
A36: 5 | B36: 7 | C36: 9 | D36: 58.1366 | E36: 5 | F36: 7 | G36: 9 | H36: 58.1359
A37: 5 | B37: 9 | C37: 4 | D37: 70.9251 | E37: 5 | F37: 9 | G37: 4 | H37: 70.9246

Sheet Wstepnewyjsciowy
B2: Wyniki pomiaru wyjściowego | P2: Współrzędne przybliżone | S2: Współrzędne wyrównane
B3: c | C3: l | D3: p | E3: L obs [m] | F3: ∆x | G3: ∆y | H3: L przyb [m] | I3: Az [g] | J3: Sin Az | K3: Cos Az | L3: Błąd [m] | M3: l [m] | N3: li [m] | P3: Współrzedne przybliżone | Q3: X0 | R3: Y0 | S3: X | T3: Y | U3: mx | V3: my
B4: ='_calc_Dane'!B5 | C4: ='_calc_Dane'!C5 | D4: ='_calc_Dane'!D5 | E4: ='_calc_Dane'!E5 | F4: ='_calc_Dane'!M5-'_calc_Dane'!M11 | G4: ='_calc_Dane'!N5-'_calc_Dane'!N11 | H4: =SQRT(F4^2+G4^2) | I4: =IF(ATAN2(F4,G4)*200/PI()<0,ATAN2(F4,G4)*200/PI()+400) | J4: =SIN(I4*PI()/200) | K4: =COS(I4*PI()/200) | L4: =0.001+0.000001*E4 | M4: =H4-E4 | N4: =H4-E4 | P4: NR | Q4: Xo | R4: Yo | S4: =Q4+U140 | T4: =R4+U141 | U4: =V140 | V4: =V141
B5: ='_calc_Dane'!B6 | C5: ='_calc_Dane'!C6 | D5: ='_calc_Dane'!D6 | E5: ='_calc_Dane'!E6 | F5: ='_calc_Dane'!M9-'_calc_Dane'!M11 | G5: ='_calc_Dane'!N9-'_calc_Dane'!N11 | H5: =SQRT(F5^2+G5^2) | I5: =IF(ATAN2(F5,G5)*200/PI()<0,ATAN2(F5,G5)*200/PI()+400,ATAN2(F5,G5)*200/PI()) | J5: =SIN(I5*PI()/200) | K5: =COS(I5*PI()/200) | L5: =0.001+0.000001*E5 | M5: =H5-E5 | N5: =H5-E5 | P5: 1 | Q5: 240 | R5: 120 | S5: =Q5 | T5: =R5 | U5: 0 | V5: 0
B6: ='_calc_Dane'!B7 | C6: ='_calc_Dane'!C7 | D6: ='_calc_Dane'!D7 | E6: ='_calc_Dane'!E7 | F6: ='_calc_Dane'!M10-'_calc_Dane'!M11 | G6: ='_calc_Dane'!N10-'_calc_Dane'!N11 | H6: =SQRT(F6^2+G6^2) | I6: =IF(ATAN2(F6,G6)*200/PI()<0,ATAN2(F6,G6)*200/PI()+400,ATAN2(F6,G6)*200/PI()) | J6: =SIN(I6*PI()/200) | K6: =COS(I6*PI()/200) | L6: =0.001+0.000001*E6 | M6: =H6-E6 | N6: =H6-E6 | P6: 2 | Q6: 385 | R6: 145 | S6: =Q6+U142 | T6: =R6+U143 | U6: =V142 | V6: =V143
B7: ='_calc_Dane'!B8 | C7: ='_calc_Dane'!C8 | D7: ='_calc_Dane'!D8 | E7: ='_calc_Dane'!E8 | F7: ='_calc_Dane'!M12-'_calc_Dane'!M11 | G7: ='_calc_Dane'!N12-'_calc_Dane'!N11 | H7: =SQRT(F7^2+G7^2) | I7: =IF(ATAN2(F7,G7)*200/PI()<0,ATAN2(F7,G7)*200/PI()+400) | J7: =SIN(I7*PI()/200) | K7: =COS(I7*PI()/200) | L7: =0.001+0.000001*E7 | M7: =H7-E7 | N7: =H7-E7 | P7: 3 | Q7: 475 | R7: 245 | S7: =Q7+U144 | T7: =R7+U145 | U7: =V144 | V7: =V145
B8: ='_calc_Dane'!B9 | C8: ='_calc_Dane'!C9 | D8: ='_calc_Dane'!D9 | E8: ='_calc_Dane'!E9 | F8: ='_calc_Dane'!M13-'_calc_Dane'!M11 | G8: ='_calc_Dane'!N13-'_calc_Dane'!N11 | H8: =SQRT(F8^2+G8^2) | I8: =IF(ATAN2(F8,G8)*200/PI()<0,ATAN2(F8,G8)*200/PI()+400) | J8: =SIN(I8*PI()/200) | K8: =COS(I8*PI()/200) | L8: =0.001+0.000001*E8 | M8: =H8-E8 | N8: =H8-E8 | P8: 4 | Q8: 435 | R8: 435 | S8: =Q8+U146 | T8: =R8+U147 | U8: =V146 | V8: =V147
B9: ='_calc_Dane'!B10 | C9: ='_calc_Dane'!C10 | D9: ='_calc_Dane'!D10 | E9: ='_calc_Dane'!E10 | F9: ='_calc_Dane'!M5-'_calc_Dane'!M12 | G9: ='_calc_Dane'!N5-'_calc_Dane'!N12 | H9: =SQRT(F9^2+G9^2) | I9: =IF(ATAN2(F9,G9)*200/PI()<0,ATAN2(F9,G9)*200/PI()+400) | J9: =SIN(I9*PI()/200) | K9: =COS(I9*PI()/200) | L9: =0.001+0.000001*E9 | M9: =H9-E9 | N9: =H9-E9 | P9: 5 | Q9: 295 | R9: 490 | S9: =Q9+U148 | T9: =R9+U149 | U9: =V148 | V9: =V149
B10: ='_calc_Dane'!B11 | C10: ='_calc_Dane'!C11 | D10: ='_calc_Dane'!D11 | E10: ='_calc_Dane'!E11 | F10: ='_calc_Dane'!M13-'_calc_Dane'!M12 | G10: ='_calc_Dane'!N13-'_calc_Dane'!N12 | H10: =SQRT(F10^2+G10^2) | I10: =IF(ATAN2(F10,G10)*200/PI()<0,ATAN2(F10,G10)*200/PI()+400,ATAN2(F10,G10)*200/PI()) | J10: =SIN(I10*PI()/200) | K10: =COS(I10*PI()/200) | L10: =0.001+0.000001*E10 | M10: =H10-E10 | N10: =H10-E10 | P10: 6 | Q10: 145 | R10: 560 | S10: =Q10+U150 | T10: =R10+U151 | U10: =V150 | V10: =V151
B11: ='_calc_Dane'!B12 | C11: ='_calc_Dane'!C12 | D11: ='_calc_Dane'!D12 | E11: ='_calc_Dane'!E12 | F11: ='_calc_Dane'!M11-'_calc_Dane'!M12 | G11: ='_calc_Dane'!N11-'_calc_Dane'!N12 | H11: =SQRT(F11^2+G11^2) | I11: =IF(ATAN2(F11,G11)*200/PI()<0,ATAN2(F11,G11)*200/PI()+400,ATAN2(F11,G11)*200/PI()) | J11: =SIN(I11*PI()/200) | K11: =COS(I11*PI()/200) | L11: =0.001+0.000001*E11 | M11: =H11-E11 | N11: =H11-E11 | P11: 7 | Q11: 180 | R11: 385 | S11: =Q11+U152 | T11: =R11+U153 | U11: =V152 | V11: =V153
B12: ='_calc_Dane'!B13 | C12: ='_calc_Dane'!C13 | D12: ='_calc_Dane'!D13 | E12: ='_calc_Dane'!E13 | F12: ='_calc_Dane'!M10-'_calc_Dane'!M12 | G12: ='_calc_Dane'!N10-'_calc_Dane'!N12 | H12: =SQRT(F12^2+G12^2) | I12: =IF(ATAN2(F12,G12)*200/PI()<0,ATAN2(F12,G12)*200/PI()+400,ATAN2(F12,G12)*200/PI()) | J12: =SIN(I12*PI()/200) | K12: =COS(I12*PI()/200) | L12: =0.001+0.000001*E12 | M12: =H12-E12 | N12: =H12-E12 | P12: 8 | Q12: 150 | R12: 240 | S12: =Q12+U154 | T12: =R12+U155 | U12: =V154 | V12: =V155
B13: ='_calc_Dane'!B14 | C13: ='_calc_Dane'!C14 | D13: ='_calc_Dane'!D14 | E13: ='_calc_Dane'!E14 | F13: ='_calc_Dane'!M7-'_calc_Dane'!M5 | G13: ='_calc_Dane'!N7-'_calc_Dane'!N5 | H13: =SQRT(F13^2+G13^2) | I13: =IF(ATAN2(F13,G13)*200/PI()<0,ATAN2(F13,G13)*200/PI()+400,ATAN2(F13,G13)*200/PI()) | J13: =SIN(I13*PI()/200) | K13: =COS(I13*PI()/200) | L13: =0.001+0.000001*E13 | M13: =H13-E13 | N13: =H13-E13 | P13: 9 | Q13: 314 | R13: 271
B14: ='_calc_Dane'!B15 | C14: ='_calc_Dane'!C15 | D14: ='_calc_Dane'!D15 | E14: ='_calc_Dane'!E15 | F14: ='_calc_Dane'!M13-'_calc_Dane'!M5 | G14: ='_calc_Dane'!N13-'_calc_Dane'!N5 | H14: =SQRT(F14^2+G14^2) | I14: =IF(ATAN2(F14,G14)*200/PI()<0,ATAN2(F14,G14)*200/PI()+400,ATAN2(F14,G14)*200/PI()) | J14: =SIN(I14*PI()/200) | K14: =COS(I14*PI()/200) | L14: =0.001+0.000001*E14 | M14: =H14-E14 | N14: =H14-E14 | P14: Numer ID | Q14: =Dane!K4 | T14: n (obserwacje) | U14: =Dane!K10 | V14: m0 | W14: =SQRT(W15/(U14-U15+U16))
B15: ='_calc_Dane'!B16 | C15: ='_calc_Dane'!C16 | D15: ='_calc_Dane'!D16 | E15: ='_calc_Dane'!E16 | F15: ='_calc_Dane'!M11-'_calc_Dane'!M5 | G15: ='_calc_Dane'!N11-'_calc_Dane'!N5 | H15: =SQRT(F15^2+G15^2) | I15: =IF(ATAN2(F15,G15)*200/PI()<0,ATAN2(F15,G15)*200/PI()+400,ATAN2(F15,G15)*200/PI()) | J15: =SIN(I15*PI()/200) | K15: =COS(I15*PI()/200) | L15: =0.001+0.000001*E15 | M15: =H15-E15 | N15: =H15-E15 | P15: σβ | Q15: =Dane!K5 | R15: =Dane!L5 | T15: u (niewiadome) | U15: =Dane!K11 | V15: VTV | W15: {=(MMULT(TRANSPOSE(T80:T111),T80:T111))}
B16: ='_calc_Dane'!B17 | C16: ='_calc_Dane'!C17 | D16: ='_calc_Dane'!D17 | E16: ='_calc_Dane'!E17 | F16: ='_calc_Dane'!M9-'_calc_Dane'!M7 | G16: ='_calc_Dane'!N9-'_calc_Dane'!N7 | H16: =SQRT(F16^2+G16^2) | I16: =IF(ATAN2(F16,G16)*200/PI()<0,ATAN2(F16,G16)*200/PI()+400,ATAN2(F16,G16)*200/PI()) | J16: =SIN(I16*PI()/200) | K16: =COS(I16*PI()/200) | L16: =0.001+0.000001*E16 | M16: =H16-E16 | N16: =H16-E16 | P16: σd | Q16: =Dane!K6 | R16: =Dane!L6 | T16: d (defekt) | U16: =Dane!K12
B17: ='_calc_Dane'!B18 | C17: ='_calc_Dane'!C18 | D17: ='_calc_Dane'!D18 | E17: ='_calc_Dane'!E18 | F17: ='_calc_Dane'!M13-'_calc_Dane'!M7 | G17: ='_calc_Dane'!N13-'_calc_Dane'!N7 | H17: =SQRT(F17^2+G17^2) | I17: =IF(ATAN2(F17,G17)*200/PI()<0,ATAN2(F17,G17)*200/PI()+400,ATAN2(F17,G17)*200/PI()) | J17: =SIN(I17*PI()/200) | K17: =COS(I17*PI()/200) | L17: =0.001+0.000001*E17 | M17: =H17-E17 | N17: =H17-E17
B18: ='_calc_Dane'!B19 | C18: ='_calc_Dane'!C19 | D18: ='_calc_Dane'!D19 | E18: ='_calc_Dane'!E19 | F18: ='_calc_Dane'!M8-'_calc_Dane'!M7 | G18: ='_calc_Dane'!N8-'_calc_Dane'!N7 | H18: =SQRT(F18^2+G18^2) | I18: =IF(ATAN2(F18,G18)*200/PI()<0,ATAN2(F18,G18)*200/PI()+400,ATAN2(F18,G18)*200/PI()) | J18: =SIN(I18*PI()/200) | K18: =COS(I18*PI()/200) | L18: =0.001+0.000001*E18 | M18: =H18-E18 | N18: =H18-E18 | P18: ρcc | Q18: =200/PI()*10000
B19: ='_calc_Dane'!B20 | C19: ='_calc_Dane'!C20 | D19: ='_calc_Dane'!D20 | E19: ='_calc_Dane'!E20 | F19: ='_calc_Dane'!M9-'_calc_Dane'!M8 | G19: ='_calc_Dane'!N9-'_calc_Dane'!N8 | H19: =SQRT(F19^2+G19^2) | I19: =IF(ATAN2(F19,G19)*200/PI()<0,ATAN2(F19,G19)*200/PI()+400,ATAN2(F19,G19)*200/PI()) | J19: =SIN(I19*PI()/200) | K19: =COS(I19*PI()/200) | L19: =0.001+0.000001*E19 | M19: =H19-E19 | N19: =H19-E19
B20: ='_calc_Dane'!B21 | C20: ='_calc_Dane'!C21 | D20: ='_calc_Dane'!D21 | E20: ='_calc_Dane'!E21 | F20: ='_calc_Dane'!M11-'_calc_Dane'!M8 | G20: ='_calc_Dane'!N11-'_calc_Dane'!N8 | H20: =SQRT(F20^2+G20^2) | I20: =IF(ATAN2(F20,G20)*200/PI()<0,ATAN2(F20,G20)*200/PI()+400) | J20: =SIN(I20*PI()/200) | K20: =COS(I20*PI()/200) | L20: =0.001+0.000001*E20 | M20: =H20-E20 | N20: =H20-E20
B21: ='_calc_Dane'!B22 | C21: ='_calc_Dane'!C22 | D21: ='_calc_Dane'!D22 | E21: ='_calc_Dane'!E22 | F21: ='_calc_Dane'!M13-'_calc_Dane'!M8 | G21: ='_calc_Dane'!N13-'_calc_Dane'!N8 | H21: =SQRT(F21^2+G21^2) | I21: =IF(ATAN2(F21,G21)*200/PI()<0,ATAN2(F21,G21)*200/PI()+400) | J21: =SIN(I21*PI()/200) | K21: =COS(I21*PI()/200) | L21: =0.001+0.000001*E21 | M21: =H21-E21 | N21: =H21-E21
B22: ='_calc_Dane'!B23 | C22: ='_calc_Dane'!C23 | D22: ='_calc_Dane'!D23 | E22: ='_calc_Dane'!E23 | F22: ='_calc_Dane'!M13-'_calc_Dane'!M10 | G22: ='_calc_Dane'!N13-'_calc_Dane'!N10 | H22: =SQRT(F22^2+G22^2) | I22: =IF(ATAN2(F22,G22)*200/PI()<0,ATAN2(F22,G22)*200/PI()+400) | J22: =SIN(I22*PI()/200) | K22: =COS(I22*PI()/200) | L22: =0.001+0.000001*E22 | M22: =H22-E22 | N22: =H22-E22
B23: ='_calc_Dane'!B24 | C23: ='_calc_Dane'!C24 | D23: ='_calc_Dane'!D24 | E23: ='_calc_Dane'!E24 | F23: ='_calc_Dane'!M9-'_calc_Dane'!M10 | G23: ='_calc_Dane'!N9-'_calc_Dane'!N10 | H23: =SQRT(F23^2+G23^2) | I23: =IF(ATAN2(F23,G23)*200/PI()<0,ATAN2(F23,G23)*200/PI()+400) | J23: =SIN(I23*PI()/200) | K23: =COS(I23*PI()/200) | L23: =0.001+0.000001*E23 | M23: =H23-E23 | N23: =H23-E23
B24: c | C24: l | D24: p | E24: βobs [g] | F24: Dxcl | G24: Dycl | H24: Dxcp | I24: Dycp | J24: d2cl | K24: d2cp | L24: Acl [rad] | M24: Acp [rad] | N24: βprzyb [g] | O24: błąd [cc] | P24: li [cc] | Q24: Acl | R24: Bcl | S24: Acp | T24: Bcp | U24: Dxcl | V24: Dycl | W24: Dxcp | X24: Dycp | Y24: Acl [rad] | Z24: Acp [rad] | AA24: βprzyb [g]
B25: c | C25: l | D25: p | E25: b obs [g] | F25: ∆xcl | G25: ∆ycl | H25: ∆xcp | I25: ∆ycp | J25: d²cl | K25: d²cp | L25: Az cl [g] | M25: Az cp [g] | N25: b przyb [g] | O25: Błąd [cc] | P25: l [g] | Q25: Al. | R25: Bl | S25: Ap | T25: Bp | U25: =VLOOKUP(C25,$P$4:$V$12,4,FALSE)-VLOOKUP(B25,$P$4:$V$12,4,FALSE) | V25: =VLOOKUP(C25,$P$4:$V$12,5,FALSE)-VLOOKUP(B25,$P$4:$V$12,5,FALSE) | W25: =VLOOKUP(D25,$P$4:$V$12,4,FALSE)-VLOOKUP(B25,$P$4:$V$12,4,FALSE) | X25: =VLOOKUP(D25,$P$4:$V$12,5,FALSE)-VLOOKUP(B25,$P$4:$V$12,5,FALSE) | Y25: =IF(U25>0,IF(V25>0,ATAN(V25/U25),ATAN(V25/U25)+2*PI()),ATAN(V25/U25)+PI()) | Z25: =IF(W25>0,IF(X25>0,ATAN(X25/W25),ATAN(X25/W25)+2*PI()),ATAN(X25/W25)+PI()) | AA25: =IF((Z25-Y25)*200/PI()>0,(Z25-Y25)*200/PI(),(Z25-Y25)*200/PI()+400)
B26: ='_calc_Dane'!B25 | C26: ='_calc_Dane'!C25 | D26: ='_calc_Dane'!D25 | E26: ='_calc_Dane'!E25 | F26: ='_calc_Dane'!M5-'_calc_Dane'!M13 | G26: ='_calc_Dane'!N5-'_calc_Dane'!N13 | H26: ='_calc_Dane'!M7-'_calc_Dane'!M13 | I26: ='_calc_Dane'!N7-'_calc_Dane'!N13 | J26: =F26^2+G26^2 | K26: =H26^2+I26^2 | L26: =IF(ATAN2(F26,G26)*200/PI()<0,ATAN2(F26,G26)*200/PI()+400,ATAN2(F26,G26)*200/PI()) | M26: =IF(ATAN2(H26,I26)*200/PI()<0,ATAN2(H26,I26)*200/PI()+400,ATAN2(H26,I26)*200/PI()) | N26: =IF(M26-L26<0,M26-L26+400,M26-L26) | O26: ='_calc_Dane'!$M$15 | P26: =N26-E26 | Q26: =F26/J26*2000000/PI() | R26: =G26/J26*2000000/PI() | S26: =H26/K26*2000000/PI() | T26: =I26/K26*2000000/PI() | U26: =VLOOKUP(C26,$P$4:$V$12,4,FALSE)-VLOOKUP(B26,$P$4:$V$12,4,FALSE) | V26: =VLOOKUP(C26,$P$4:$V$12,5,FALSE)-VLOOKUP(B26,$P$4:$V$12,5,FALSE) | W26: =VLOOKUP(D26,$P$4:$V$12,4,FALSE)-VLOOKUP(B26,$P$4:$V$12,4,FALSE) | X26: =VLOOKUP(D26,$P$4:$V$12,5,FALSE)-VLOOKUP(B26,$P$4:$V$12,5,FALSE) | Y26: =IF(U26>0,IF(V26>0,ATAN(V26/U26),ATAN(V26/U26)+2*PI()),ATAN(V26/U26)+PI()) | Z26: =IF(W26>0,IF(X26>0,ATAN(X26/W26),ATAN(X26/W26)+2*PI()),ATAN(X26/W26)+PI()) | AA26: =IF((Z26-Y26)*200/PI()>0,(Z26-Y26)*200/PI(),(Z26-Y26)*200/PI()+400)
B27: ='_calc_Dane'!B26 | C27: ='_calc_Dane'!C26 | D27: ='_calc_Dane'!D26 | E27: ='_calc_Dane'!E26 | F27: ='_calc_Dane'!M7-'_calc_Dane'!M13 | G27: ='_calc_Dane'!N7-'_calc_Dane'!N13 | H27: ='_calc_Dane'!M8-'_calc_Dane'!M13 | I27: ='_calc_Dane'!N8-'_calc_Dane'!N13 | J27: =F27^2+G27^2 | K27: =H27^2+I27^2 | L27: =IF(ATAN2(F27,G27)*200/PI()<0,ATAN2(F27,G27)*200/PI()+400,ATAN2(F27,G27)*200/PI()) | M27: =IF(ATAN2(H27,I27)*200/PI()<0,ATAN2(H27,I27)*200/PI()+400,ATAN2(H27,I27)*200/PI()) | N27: =IF(M27-L27<0,M27-L27+400,M27-L27) | O27: ='_calc_Dane'!$M$15 | P27: =N27-E27 | Q27: =F27/J27*2000000/PI() | R27: =G27/J27*2000000/PI() | S27: =H27/K27*2000000/PI() | T27: =I27/K27*2000000/PI() | U27: =VLOOKUP(C27,$P$4:$V$12,4,FALSE)-VLOOKUP(B27,$P$4:$V$12,4,FALSE) | V27: =VLOOKUP(C27,$P$4:$V$12,5,FALSE)-VLOOKUP(B27,$P$4:$V$12,5,FALSE) | W27: =VLOOKUP(D27,$P$4:$V$12,4,FALSE)-VLOOKUP(B27,$P$4:$V$12,4,FALSE) | X27: =VLOOKUP(D27,$P$4:$V$12,5,FALSE)-VLOOKUP(B27,$P$4:$V$12,5,FALSE) | Y27: =IF(U27>0,IF(V27>0,ATAN(V27/U27),ATAN(V27/U27)+2*PI()),ATAN(V27/U27)+PI()) | Z27: =IF(W27>0,IF(X27>0,ATAN(X27/W27),ATAN(X27/W27)+2*PI()),ATAN(X27/W27)+PI()) | AA27: =IF((Z27-Y27)*200/PI()>0,(Z27-Y27)*200/PI(),(Z27-Y27)*200/PI()+400)
B28: ='_calc_Dane'!B27 | C28: ='_calc_Dane'!C27 | D28: ='_calc_Dane'!D27 | E28: ='_calc_Dane'!E27 | F28: ='_calc_Dane'!M8-'_calc_Dane'!M13 | G28: ='_calc_Dane'!N8-'_calc_Dane'!N13 | H28: ='_calc_Dane'!M9-'_calc_Dane'!M13 | I28: ='_calc_Dane'!N9-'_calc_Dane'!N13 | J28: =F28^2+G28^2 | K28: =H28^2+I28^2 | L28: =IF(ATAN2(F28,G28)*200/PI()<0,ATAN2(F28,G28)*200/PI()+400,ATAN2(F28,G28)*200/PI()) | M28: =IF(ATAN2(H28,I28)*200/PI()<0,ATAN2(H28,I28)*200/PI()+400,ATAN2(H28,I28)*200/PI()) | N28: =IF(M28-L28<0,M28-L28+400,M28-L28) | O28: ='_calc_Dane'!$M$15 | P28: =N28-E28 | Q28: =F28/J28*2000000/PI() | R28: =G28/J28*2000000/PI() | S28: =H28/K28*2000000/PI() | T28: =I28/K28*2000000/PI() | U28: =VLOOKUP(C28,$P$4:$V$12,4,FALSE)-VLOOKUP(B28,$P$4:$V$12,4,FALSE) | V28: =VLOOKUP(C28,$P$4:$V$12,5,FALSE)-VLOOKUP(B28,$P$4:$V$12,5,FALSE) | W28: =VLOOKUP(D28,$P$4:$V$12,4,FALSE)-VLOOKUP(B28,$P$4:$V$12,4,FALSE) | X28: =VLOOKUP(D28,$P$4:$V$12,5,FALSE)-VLOOKUP(B28,$P$4:$V$12,5,FALSE) | Y28: =IF(U28>0,IF(V28>0,ATAN(V28/U28),ATAN(V28/U28)+2*PI()),ATAN(V28/U28)+PI()) | Z28: =IF(W28>0,IF(X28>0,ATAN(X28/W28),ATAN(X28/W28)+2*PI()),ATAN(X28/W28)+PI()) | AA28: =IF((Z28-Y28)*200/PI()>0,(Z28-Y28)*200/PI(),(Z28-Y28)*200/PI()+400)
B29: ='_calc_Dane'!B28 | C29: ='_calc_Dane'!C28 | D29: ='_calc_Dane'!D28 | E29: ='_calc_Dane'!E28 | F29: ='_calc_Dane'!M9-'_calc_Dane'!M13 | G29: ='_calc_Dane'!N9-'_calc_Dane'!N13 | H29: ='_calc_Dane'!M11-'_calc_Dane'!M13 | I29: ='_calc_Dane'!N11-'_calc_Dane'!N13 | J29: =F29^2+G29^2 | K29: =H29^2+I29^2 | L29: =IF(ATAN2(F29,G29)*200/PI()<0,ATAN2(F29,G29)*200/PI()+400,ATAN2(F29,G29)*200/PI()) | M29: =IF(ATAN2(H29,I29)*200/PI()<0,ATAN2(H29,I29)*200/PI()+400,ATAN2(H29,I29)*200/PI()) | N29: =IF(M29-L29<0,M29-L29+400,M29-L29) | O29: ='_calc_Dane'!$M$15 | P29: =N29-E29 | Q29: =F29/J29*2000000/PI() | R29: =G29/J29*2000000/PI() | S29: =H29/K29*2000000/PI() | T29: =I29/K29*2000000/PI() | U29: =VLOOKUP(C29,$P$4:$V$12,4,FALSE)-VLOOKUP(B29,$P$4:$V$12,4,FALSE) | V29: =VLOOKUP(C29,$P$4:$V$12,5,FALSE)-VLOOKUP(B29,$P$4:$V$12,5,FALSE) | W29: =VLOOKUP(D29,$P$4:$V$12,4,FALSE)-VLOOKUP(B29,$P$4:$V$12,4,FALSE) | X29: =VLOOKUP(D29,$P$4:$V$12,5,FALSE)-VLOOKUP(B29,$P$4:$V$12,5,FALSE) | Y29: =IF(U29>0,IF(V29>0,ATAN(V29/U29),ATAN(V29/U29)+2*PI()),ATAN(V29/U29)+PI()) | Z29: =IF(W29>0,IF(X29>0,ATAN(X29/W29),ATAN(X29/W29)+2*PI()),ATAN(X29/W29)+PI()) | AA29: =IF((Z29-Y29)*200/PI()>0,(Z29-Y29)*200/PI(),(Z29-Y29)*200/PI()+400)
B30: ='_calc_Dane'!B29 | C30: ='_calc_Dane'!C29 | D30: ='_calc_Dane'!D29 | E30: ='_calc_Dane'!E29 | F30: ='_calc_Dane'!M11-'_calc_Dane'!M13 | G30: ='_calc_Dane'!N11-'_calc_Dane'!N13 | H30: ='_calc_Dane'!M12-'_calc_Dane'!M13 | I30: ='_calc_Dane'!N12-'_calc_Dane'!N13 | J30: =F30^2+G30^2 | K30: =H30^2+I30^2 | L30: =IF(ATAN2(F30,G30)*200/PI()<0,ATAN2(F30,G30)*200/PI()+400,ATAN2(F30,G30)*200/PI()) | M30: =IF(ATAN2(H30,I30)*200/PI()<0,ATAN2(H30,I30)*200/PI()+400,ATAN2(H30,I30)*200/PI()) | N30: =IF(M30-L30<0,M30-L30+400,M30-L30) | O30: ='_calc_Dane'!$M$15 | P30: =N30-E30 | Q30: =F30/J30*2000000/PI() | R30: =G30/J30*2000000/PI() | S30: =H30/K30*2000000/PI() | T30: =I30/K30*2000000/PI() | U30: =VLOOKUP(C30,$P$4:$V$12,4,FALSE)-VLOOKUP(B30,$P$4:$V$12,4,FALSE) | V30: =VLOOKUP(C30,$P$4:$V$12,5,FALSE)-VLOOKUP(B30,$P$4:$V$12,5,FALSE) | W30: =VLOOKUP(D30,$P$4:$V$12,4,FALSE)-VLOOKUP(B30,$P$4:$V$12,4,FALSE) | X30: =VLOOKUP(D30,$P$4:$V$12,5,FALSE)-VLOOKUP(B30,$P$4:$V$12,5,FALSE) | Y30: =IF(U30>0,IF(V30>0,ATAN(V30/U30),ATAN(V30/U30)+2*PI()),ATAN(V30/U30)+PI()) | Z30: =IF(W30>0,IF(X30>0,ATAN(X30/W30),ATAN(X30/W30)+2*PI()),ATAN(X30/W30)+PI()) | AA30: =IF((Z30-Y30)*200/PI()>0,(Z30-Y30)*200/PI(),(Z30-Y30)*200/PI()+400)
B31: ='_calc_Dane'!B30 | C31: ='_calc_Dane'!C30 | D31: ='_calc_Dane'!D30 | E31: ='_calc_Dane'!E30 | F31: ='_calc_Dane'!M12-'_calc_Dane'!M13 | G31: ='_calc_Dane'!N12-'_calc_Dane'!N13 | H31: ='_calc_Dane'!M5-'_calc_Dane'!M13 | I31: ='_calc_Dane'!N5-'_calc_Dane'!N13 | J31: =F31^2+G31^2 | K31: =H31^2+I31^2 | L31: =IF(ATAN2(F31,G31)*200/PI()<0,ATAN2(F31,G31)*200/PI()+400,ATAN2(F31,G31)*200/PI()) | M31: =IF(ATAN2(H31,I31)*200/PI()<0,ATAN2(H31,I31)*200/PI()+400,ATAN2(H31,I31)*200/PI()) | N31: =IF(M31-L31<0,M31-L31+400,M31-L31) | O31: ='_calc_Dane'!$M$15 | P31: =N31-E31 | Q31: =F31/J31*2000000/PI() | R31: =G31/J31*2000000/PI() | S31: =H31/K31*2000000/PI() | T31: =I31/K31*2000000/PI() | U31: =VLOOKUP(C31,$P$4:$V$12,4,FALSE)-VLOOKUP(B31,$P$4:$V$12,4,FALSE) | V31: =VLOOKUP(C31,$P$4:$V$12,5,FALSE)-VLOOKUP(B31,$P$4:$V$12,5,FALSE) | W31: =VLOOKUP(D31,$P$4:$V$12,4,FALSE)-VLOOKUP(B31,$P$4:$V$12,4,FALSE) | X31: =VLOOKUP(D31,$P$4:$V$12,5,FALSE)-VLOOKUP(B31,$P$4:$V$12,5,FALSE) | Y31: =IF(U31>0,IF(V31>0,ATAN(V31/U31),ATAN(V31/U31)+2*PI()),ATAN(V31/U31)+PI()) | Z31: =IF(W31>0,IF(X31>0,ATAN(X31/W31),ATAN(X31/W31)+2*PI()),ATAN(X31/W31)+PI()) | AA31: =IF((Z31-Y31)*200/PI()>0,(Z31-Y31)*200/PI(),(Z31-Y31)*200/PI()+400)
B32: ='_calc_Dane'!B31 | C32: ='_calc_Dane'!C31 | D32: ='_calc_Dane'!D31 | E32: ='_calc_Dane'!E31 | F32: ='_calc_Dane'!M12-'_calc_Dane'!M10 | G32: ='_calc_Dane'!N12-'_calc_Dane'!N10 | H32: ='_calc_Dane'!M11-'_calc_Dane'!M10 | I32: ='_calc_Dane'!N11-'_calc_Dane'!N10 | J32: =F32^2+G32^2 | K32: =H32^2+I32^2 | L32: =IF(ATAN2(F32,G32)*200/PI()<0,ATAN2(F32,G32)*200/PI()+400,ATAN2(F32,G32)*200/PI()) | M32: =IF(ATAN2(H32,I32)*200/PI()<0,ATAN2(H32,I32)*200/PI()+400,ATAN2(H32,I32)*200/PI()) | N32: =IF(M32-L32<0,M32-L32+400,M32-L32) | O32: ='_calc_Dane'!$M$15 | P32: =N32-E32 | Q32: =F32/J32*2000000/PI() | R32: =G32/J32*2000000/PI() | S32: =H32/K32*2000000/PI() | T32: =I32/K32*2000000/PI() | U32: =VLOOKUP(C32,$P$4:$V$12,4,FALSE)-VLOOKUP(B32,$P$4:$V$12,4,FALSE) | V32: =VLOOKUP(C32,$P$4:$V$12,5,FALSE)-VLOOKUP(B32,$P$4:$V$12,5,FALSE) | W32: =VLOOKUP(D32,$P$4:$V$12,4,FALSE)-VLOOKUP(B32,$P$4:$V$12,4,FALSE) | X32: =VLOOKUP(D32,$P$4:$V$12,5,FALSE)-VLOOKUP(B32,$P$4:$V$12,5,FALSE) | Y32: =IF(U32>0,IF(V32>0,ATAN(V32/U32),ATAN(V32/U32)+2*PI()),ATAN(V32/U32)+PI()) | Z32: =IF(W32>0,IF(X32>0,ATAN(X32/W32),ATAN(X32/W32)+2*PI()),ATAN(X32/W32)+PI()) | AA32: =IF((Z32-Y32)*200/PI()>0,(Z32-Y32)*200/PI(),(Z32-Y32)*200/PI()+400)
B33: ='_calc_Dane'!B32 | C33: ='_calc_Dane'!C32 | D33: ='_calc_Dane'!D32 | E33: ='_calc_Dane'!E32 | F33: ='_calc_Dane'!M11-'_calc_Dane'!M10 | G33: ='_calc_Dane'!N11-'_calc_Dane'!N10 | H33: ='_calc_Dane'!M13-'_calc_Dane'!M10 | I33: ='_calc_Dane'!N13-'_calc_Dane'!N10 | J33: =F33^2+G33^2 | K33: =H33^2+I33^2 | L33: =IF(ATAN2(F33,G33)*200/PI()<0,ATAN2(F33,G33)*200/PI()+400,ATAN2(F33,G33)*200/PI()) | M33: =IF(ATAN2(H33,I33)*200/PI()<0,ATAN2(H33,I33)*200/PI()+400,ATAN2(H33,I33)*200/PI()) | N33: =IF(M33-L33<0,M33-L33+400,M33-L33) | O33: ='_calc_Dane'!$M$15 | P33: =N33-E33 | Q33: =F33/J33*2000000/PI() | R33: =G33/J33*2000000/PI() | S33: =H33/K33*2000000/PI() | T33: =I33/K33*2000000/PI() | U33: =VLOOKUP(C33,$P$4:$V$12,4,FALSE)-VLOOKUP(B33,$P$4:$V$12,4,FALSE) | V33: =VLOOKUP(C33,$P$4:$V$12,5,FALSE)-VLOOKUP(B33,$P$4:$V$12,5,FALSE) | W33: =VLOOKUP(D33,$P$4:$V$12,4,FALSE)-VLOOKUP(B33,$P$4:$V$12,4,FALSE) | X33: =VLOOKUP(D33,$P$4:$V$12,5,FALSE)-VLOOKUP(B33,$P$4:$V$12,5,FALSE) | Y33: =IF(U33>0,IF(V33>0,ATAN(V33/U33),ATAN(V33/U33)+2*PI()),ATAN(V33/U33)+PI()) | Z33: =IF(W33>0,IF(X33>0,ATAN(X33/W33),ATAN(X33/W33)+2*PI()),ATAN(X33/W33)+PI()) | AA33: =IF((Z33-Y33)*200/PI()>0,(Z33-Y33)*200/PI(),(Z33-Y33)*200/PI()+400)
B34: ='_calc_Dane'!B33 | C34: ='_calc_Dane'!C33 | D34: ='_calc_Dane'!D33 | E34: ='_calc_Dane'!E33 | F34: ='_calc_Dane'!M13-'_calc_Dane'!M10 | G34: ='_calc_Dane'!N13-'_calc_Dane'!N10 | H34: ='_calc_Dane'!M9-'_calc_Dane'!M10 | I34: ='_calc_Dane'!N9-'_calc_Dane'!N10 | J34: =F34^2+G34^2 | K34: =H34^2+I34^2 | L34: =IF(ATAN2(F34,G34)*200/PI()<0,ATAN2(F34,G34)*200/PI()+400,ATAN2(F34,G34)*200/PI()) | M34: =IF(ATAN2(H34,I34)*200/PI()<0,ATAN2(H34,I34)*200/PI()+400,ATAN2(H34,I34)*200/PI()) | N34: =IF(M34-L34<0,M34-L34+400,M34-L34) | O34: ='_calc_Dane'!$M$15 | P34: =N34-E34 | Q34: =F34/J34*2000000/PI() | R34: =G34/J34*2000000/PI() | S34: =H34/K34*2000000/PI() | T34: =I34/K34*2000000/PI() | U34: =VLOOKUP(C34,$P$4:$V$12,4,FALSE)-VLOOKUP(B34,$P$4:$V$12,4,FALSE) | V34: =VLOOKUP(C34,$P$4:$V$12,5,FALSE)-VLOOKUP(B34,$P$4:$V$12,5,FALSE) | W34: =VLOOKUP(D34,$P$4:$V$12,4,FALSE)-VLOOKUP(B34,$P$4:$V$12,4,FALSE) | X34: =VLOOKUP(D34,$P$4:$V$12,5,FALSE)-VLOOKUP(B34,$P$4:$V$12,5,FALSE) | Y34: =IF(U34>0,IF(V34>0,ATAN(V34/U34),ATAN(V34/U34)+2*PI()),ATAN(V34/U34)+PI()) | Z34: =IF(W34>0,IF(X34>0,ATAN(X34/W34),ATAN(X34/W34)+2*PI()),ATAN(X34/W34)+PI()) | AA34: =IF((Z34-Y34)*200/PI()>0,(Z34-Y34)*200/PI(),(Z34-Y34)*200/PI()+400)
B35: ='_calc_Dane'!B34 | C35: ='_calc_Dane'!C34 | D35: ='_calc_Dane'!D34 | E35: ='_calc_Dane'!E34 | F35: ='_calc_Dane'!M10-'_calc_Dane'!M9 | G35: ='_calc_Dane'!N10-'_calc_Dane'!N9 | H35: ='_calc_Dane'!M11-'_calc_Dane'!M9 | I35: ='_calc_Dane'!N11-'_calc_Dane'!N9 | J35: =F35^2+G35^2 | K35: =H35^2+I35^2 | L35: =IF(ATAN2(F35,G35)*200/PI()<0,ATAN2(F35,G35)*200/PI()+400,ATAN2(F35,G35)*200/PI()) | M35: =IF(ATAN2(H35,I35)*200/PI()<0,ATAN2(H35,I35)*200/PI()+400,ATAN2(H35,I35)*200/PI()) | N35: =IF(M35-L35<0,M35-L35+400,M35-L35) | O35: ='_calc_Dane'!$M$15 | P35: =N35-E35 | Q35: =F35/J35*2000000/PI() | R35: =G35/J35*2000000/PI() | S35: =H35/K35*2000000/PI() | T35: =I35/K35*2000000/PI() | U35: =VLOOKUP(C35,$P$4:$V$12,4,FALSE)-VLOOKUP(B35,$P$4:$V$12,4,FALSE) | V35: =VLOOKUP(C35,$P$4:$V$12,5,FALSE)-VLOOKUP(B35,$P$4:$V$12,5,FALSE) | W35: =VLOOKUP(D35,$P$4:$V$12,4,FALSE)-VLOOKUP(B35,$P$4:$V$12,4,FALSE) | X35: =VLOOKUP(D35,$P$4:$V$12,5,FALSE)-VLOOKUP(B35,$P$4:$V$12,5,FALSE) | Y35: =IF(U35>0,IF(V35>0,ATAN(V35/U35),ATAN(V35/U35)+2*PI()),ATAN(V35/U35)+PI()) | Z35: =IF(W35>0,IF(X35>0,ATAN(X35/W35),ATAN(X35/W35)+2*PI()),ATAN(X35/W35)+PI()) | AA35: =IF((Z35-Y35)*200/PI()>0,(Z35-Y35)*200/PI(),(Z35-Y35)*200/PI()+400)
B36: ='_calc_Dane'!B35 | C36: ='_calc_Dane'!C35 | D36: ='_calc_Dane'!D35 | E36: ='_calc_Dane'!E35 | F36: ='_calc_Dane'!M11-'_calc_Dane'!M9 | G36: ='_calc_Dane'!N11-'_calc_Dane'!N9 | H36: ='_calc_Dane'!M13-'_calc_Dane'!M9 | I36: ='_calc_Dane'!N13-'_calc_Dane'!N9 | J36: =F36^2+G36^2 | K36: =H36^2+I36^2 | L36: =IF(ATAN2(F36,G36)*200/PI()<0,ATAN2(F36,G36)*200/PI()+400,ATAN2(F36,G36)*200/PI()) | M36: =IF(ATAN2(H36,I36)*200/PI()<0,ATAN2(H36,I36)*200/PI()+400,ATAN2(H36,I36)*200/PI()) | N36: =IF(M36-L36<0,M36-L36+400,M36-L36) | O36: ='_calc_Dane'!$M$15 | P36: =N36-E36 | Q36: =F36/J36*2000000/PI() | R36: =G36/J36*2000000/PI() | S36: =H36/K36*2000000/PI() | T36: =I36/K36*2000000/PI() | U36: =VLOOKUP(C36,$P$4:$V$12,4,FALSE)-VLOOKUP(B36,$P$4:$V$12,4,FALSE) | V36: =VLOOKUP(C36,$P$4:$V$12,5,FALSE)-VLOOKUP(B36,$P$4:$V$12,5,FALSE) | W36: =VLOOKUP(D36,$P$4:$V$12,4,FALSE)-VLOOKUP(B36,$P$4:$V$12,4,FALSE) | X36: =VLOOKUP(D36,$P$4:$V$12,5,FALSE)-VLOOKUP(B36,$P$4:$V$12,5,FALSE) | Y36: =IF(U36>0,IF(V36>0,ATAN(V36/U36),ATAN(V36/U36)+2*PI()),ATAN(V36/U36)+PI()) | Z36: =IF(W36>0,IF(X36>0,ATAN(X36/W36),ATAN(X36/W36)+2*PI()),ATAN(X36/W36)+PI()) | AA36: =IF((Z36-Y36)*200/PI()>0,(Z36-Y36)*200/PI(),(Z36-Y36)*200/PI()+400)
B37: ='_calc_Dane'!B36 | C37: ='_calc_Dane'!C36 | D37: ='_calc_Dane'!D36 | E37: ='_calc_Dane'!E36 | F37: ='_calc_Dane'!M13-'_calc_Dane'!M9 | G37: ='_calc_Dane'!N13-'_calc_Dane'!N9 | H37: ='_calc_Dane'!M8-'_calc_Dane'!M9 | I37: ='_calc_Dane'!N8-'_calc_Dane'!N9 | J37: =F37^2+G37^2 | K37: =H37^2+I37^2 | L37: =IF(ATAN2(F37,G37)*200/PI()<0,ATAN2(F37,G37)*200/PI()+400,ATAN2(F37,G37)*200/PI()) | M37: =IF(ATAN2(H37,I37)*200/PI()<0,ATAN2(H37,I37)*200/PI()+400,ATAN2(H37,I37)*200/PI()) | N37: =IF(M37-L37<0,M37-L37+400,M37-L37) | O37: ='_calc_Dane'!$M$15 | P37: =N37-E37 | Q37: =F37/J37*2000000/PI() | R37: =G37/J37*2000000/PI() | S37: =H37/K37*2000000/PI() | T37: =I37/K37*2000000/PI()
B39: a | S39: l [m/cc]
B40: dx
B41: 1 | C41: 1 | D41: 3 | E41: 3 | F41: 4 | G41: 4 | H41: 5 | I41: 5 | J41: 6 | K41: 6 | L41: 7 | M41: 7 | N41: 8 | O41: 8 | P41: 9 | Q41: 9 | R41: l | T41: v
B42: =IF(B$41=$B4,IF(B$40="dx",-$K4,-$J4),IF(B$41=$C4,IF(B$40="dx",$K4,$J4),0)) | C42: =IF(C$41=$B4,IF(C$40="dx",-$K4,-$J4),IF(C$41=$C4,IF(C$40="dx",$K4,$J4),0)) | D42: =IF(D$41=$B4,IF(D$40="dx",-$K4,-$J4),IF(D$41=$C4,IF(D$40="dx",$K4,$J4),0)) | E42: =IF(E$41=$B4,IF(E$40="dx",-$K4,-$J4),IF(E$41=$C4,IF(E$40="dx",$K4,$J4),0)) | F42: =IF(F$41=$B4,IF(F$40="dx",-$K4,-$J4),IF(F$41=$C4,IF(F$40="dx",$K4,$J4),0)) | G42: =IF(G$41=$B4,IF(G$40="dx",-$K4,-$J4),IF(G$41=$C4,IF(G$40="dx",$K4,$J4),0)) | H42: =IF(H$41=$B4,IF(H$40="dx",-$K4,-$J4),IF(H$41=$C4,IF(H$40="dx",$K4,$J4),0)) | I42: =IF(I$41=$B4,IF(I$40="dx",-$K4,-$J4),IF(I$41=$C4,IF(I$40="dx",$K4,$J4),0)) | ... Q42: =IF(Q$41=$B4,IF(Q$40="dx",-$K4,-$J4),IF(Q$41=$C4,IF(Q$40="dx",$K4,$J4),0)) | S42: =M4
...

Sheet Wstepneaktualny
B2: Wyniki pomiaru aktualnego | P2: Współrzędne przybliżone | S2: Współrzędne wyrównane
B3: c | C3: l | D3: p | E3: L obs [m] | F3: ∆x | G3: ∆y | H3: L przyb [m] | I3: Az [g] | J3: Sin Az | K3: Cos Az | L3: Błąd [m] | M3: l [m] | N3: li [m] | P3: Współrzedne przybliżone | Q3: X0 | R3: Y0 | S3: X | T3: Y | U3: mx | V3: my
B4: ='_calc_Dane'!F5 | C4: ='_calc_Dane'!G5 | D4: ='_calc_Dane'!H5 | E4: ='_calc_Dane'!I5 | F4: ='_calc_Dane'!M5-'_calc_Dane'!M11 | G4: ='_calc_Dane'!N5-'_calc_Dane'!N11 | H4: =SQRT(F4^2+G4^2) | I4: =IF(ATAN2(F4,G4)*200/PI()<0,ATAN2(F4,G4)*200/PI()+400) | J4: =SIN(I4*PI()/200) | K4: =COS(I4*PI()/200) | L4: =0.001+0.000001*E4 | M4: =H4-E4 | N4: =H4-E4 | P4: NR | Q4: Xo | R4: Yo | S4: =Q4+U140 | T4: =R4+U141 | U4: =V140 | V4: =V141
B5: ='_calc_Dane'!F6 | C5: ='_calc_Dane'!G6 | D5: ='_calc_Dane'!H6 | E5: ='_calc_Dane'!I6 | F5: ='_calc_Dane'!M9-'_calc_Dane'!M11 | G5: ='_calc_Dane'!N9-'_calc_Dane'!N11 | H5: =SQRT(F5^2+G5^2) | I5: =IF(ATAN2(F5,G5)*200/PI()<0,ATAN2(F5,G5)*200/PI()+400,ATAN2(F5,G5)*200/PI()) | J5: =SIN(I5*PI()/200) | K5: =COS(I5*PI()/200) | L5: =0.001+0.000001*E5 | M5: =H5-E5 | N5: =H5-E5 | P5: 1 | Q5: 240 | R5: 120 | S5: =Q5+U142 | T5: =R5+U143 | U5: =V142 | V5: =V143
B6: ='_calc_Dane'!F7 | C6: ='_calc_Dane'!G7 | D6: ='_calc_Dane'!H7 | E6: ='_calc_Dane'!I7 | F6: ='_calc_Dane'!M10-'_calc_Dane'!M11 | G6: ='_calc_Dane'!N10-'_calc_Dane'!N11 | H6: =SQRT(F6^2+G6^2) | I6: =IF(ATAN2(F6,G6)*200/PI()<0,ATAN2(F6,G6)*200/PI()+400,ATAN2(F6,G6)*200/PI()) | J6: =SIN(I6*PI()/200) | K6: =COS(I6*PI()/200) | L6: =0.001+0.000001*E6 | M6: =H6-E6 | N6: =H6-E6 | P6: 2 | Q6: 385 | R6: 145 | S6: =Q6 | T6: =R6 | U6: 0 | V6: 0
B7: ='_calc_Dane'!F8 | C7: ='_calc_Dane'!G8 | D7: ='_calc_Dane'!H8 | E7: ='_calc_Dane'!I8 | F7: ='_calc_Dane'!M12-'_calc_Dane'!M11 | G7: ='_calc_Dane'!N12-'_calc_Dane'!N11 | H7: =SQRT(F7^2+G7^2) | I7: =IF(ATAN2(F7,G7)*200/PI()<0,ATAN2(F7,G7)*200/PI()+400) | J7: =SIN(I7*PI()/200) | K7: =COS(I7*PI()/200) | L7: =0.001+0.000001*E7 | M7: =H7-E7 | N7: =H7-E7 | P7: 3 | Q7: 475 | R7: 245 | S7: =Q7+U144 | T7: =R7+U145 | U7: =V144 | V7: =V145
B8: ='_calc_Dane'!F9 | C8: ='_calc_Dane'!G9 | D8: ='_calc_Dane'!H9 | E8: ='_calc_Dane'!I9 | F8: ='_calc_Dane'!M13-'_calc_Dane'!M11 | G8: ='_calc_Dane'!N13-'_calc_Dane'!N11 | H8: =SQRT(F8^2+G8^2) | I8: =IF(ATAN2(F8,G8)*200/PI()<0,ATAN2(F8,G8)*200/PI()+400) | J8: =SIN(I8*PI()/200) | K8: =COS(I8*PI()/200) | L8: =0.001+0.000001*E8 | M8: =H8-E8 | N8: =H8-E8 | P8: 4 | Q8: 435 | R8: 435 | S8: =Q8+U146 | T8: =R8+U147 | U8: =V146 | V8: =V147
B9: ='_calc_Dane'!F10 | C9: ='_calc_Dane'!G10 | D9: ='_calc_Dane'!H10 | E9: ='_calc_Dane'!I10 | F9: ='_calc_Dane'!M5-'_calc_Dane'!M12 | G9: ='_calc_Dane'!N5-'_calc_Dane'!N12 | H9: =SQRT(F9^2+G9^2) | I9: =IF(ATAN2(F9,G9)*200/PI()<0,ATAN2(F9,G9)*200/PI()+400) | J9: =SIN(I9*PI()/200) | K9: =COS(I9*PI()/200) | L9: =0.001+0.000001*E9 | M9: =H9-E9 | N9: =H9-E9 | P9: 5 | Q9: 295 | R9: 490 | S9: =Q9+U148 | T9: =R9+U149 | U9: =V148 | V9: =V149
B10: ='_calc_Dane'!F11 | C10: ='_calc_Dane'!G11 | D10: ='_calc_Dane'!H11 | E10: ='_calc_Dane'!I11 | F10: ='_calc_Dane'!M13-'_calc_Dane'!M12 | G10: ='_calc_Dane'!N13-'_calc_Dane'!N12 | H10: =SQRT(F10^2+G10^2) | I10: =IF(ATAN2(F10,G10)*200/PI()<0,ATAN2(F10,G10)*200/PI()+400,ATAN2(F10,G10)*200/PI()) | J10: =SIN(I10*PI()/200) | K10: =COS(I10*PI()/200) | L10: =0.001+0.000001*E10 | M10: =H10-E10 | N10: =H10-E10 | P10: 6 | Q10: 145 | R10: 560 | S10: =Q10+U150 | T10: =R10+U151 | U10: =V150 | V10: =V151
B11: ='_calc_Dane'!F12 | C11: ='_calc_Dane'!G12 | D11: ='_calc_Dane'!H12 | E11: ='_calc_Dane'!I12 | F11: ='_calc_Dane'!M11-'_calc_Dane'!M12 | G11: ='_calc_Dane'!N11-'_calc_Dane'!N12 | H11: =SQRT(F11^2+G11^2) | I11: =IF(ATAN2(F11,G11)*200/PI()<0,ATAN2(F11,G11)*200/PI()+400,ATAN2(F11,G11)*200/PI()) | J11: =SIN(I11*PI()/200) | K11: =COS(I11*PI()/200) | L11: =0.001+0.000001*E11 | M11: =H11-E11 | N11: =H11-E11 | P11: 7 | Q11: 180 | R11: 385 | S11: =Q11+U152 | T11: =R11+U153 | U11: =V152 | V11: =V153
B12: ='_calc_Dane'!F13 | C12: ='_calc_Dane'!G13 | D12: ='_calc_Dane'!H13 | E12: ='_calc_Dane'!I13 | F12: ='_calc_Dane'!M10-'_calc_Dane'!M12 | G12: ='_calc_Dane'!N10-'_calc_Dane'!N12 | H12: =SQRT(F12^2+G12^2) | I12: =IF(ATAN2(F12,G12)*200/PI()<0,ATAN2(F12,G12)*200/PI()+400,ATAN2(F12,G12)*200/PI()) | J12: =SIN(I12*PI()/200) | K12: =COS(I12*PI()/200) | L12: =0.001+0.000001*E12 | M12: =H12-E12 | N12: =H12-E12 | P12: 8 | Q12: 150 | R12: 240 | S12: =Q12+U154 | T12: =R12+U155 | U12: =V154 | V12: =V155
B13: ='_calc_Dane'!F14 | C13: ='_calc_Dane'!G14 | D13: ='_calc_Dane'!H14 | E13: ='_calc_Dane'!I14 | F13: ='_calc_Dane'!M6-'_calc_Dane'!M5 | G13: ='_calc_Dane'!N6-'_calc_Dane'!N5 | H13: =SQRT(F13^2+G13^2) | I13: =IF(ATAN2(F13,G13)*200/PI()<0,ATAN2(F13,G13)*200/PI()+400,ATAN2(F13,G13)*200/PI()) | J13: =SIN(I13*PI()/200) | K13: =COS(I13*PI()/200) | L13: =0.001+0.000001*E13 | M13: =H13-E13 | N13: =H13-E13 | P13: 9 | Q13: 314 | R13: 271
B14: ='_calc_Dane'!F15 | C14: ='_calc_Dane'!G15 | D14: ='_calc_Dane'!H15 | E14: ='_calc_Dane'!I15 | F14: ='_calc_Dane'!M13-'_calc_Dane'!M5 | G14: ='_calc_Dane'!N13-'_calc_Dane'!N5 | H14: =SQRT(F14^2+G14^2) | I14: =IF(ATAN2(F14,G14)*200/PI()<0,ATAN2(F14,G14)*200/PI()+400,ATAN2(F14,G14)*200/PI()) | J14: =SIN(I14*PI()/200) | K14: =COS(I14*PI()/200) | L14: =0.001+0.000001*E14 | M14: =H14-E14 | N14: =H14-E14 | P14: Numer ID | Q14: =Dane!K4 | T14: n (obserwacje) | U14: =Dane!K10 | V14: m0 | W14: =SQRT(W15/(U14-U15+U16))
B15: ='_calc_Dane'!F16 | C15: ='_calc_Dane'!G16 | D15: ='_calc_Dane'!H16 | E15: ='_calc_Dane'!I16 | F15: ='_calc_Dane'!M11-'_calc_Dane'!M5 | G15: ='_calc_Dane'!N11-'_calc_Dane'!N5 | H15: =SQRT(F15^2+G15^2) | I15: =IF(ATAN2(F15,G15)*200/PI()<0,ATAN2(F15,G15)*200/PI()+400,ATAN2(F15,G15)*200/PI()) | J15: =SIN(I15*PI()/200) | K15: =COS(I15*PI()/200) | L15: =0.001+0.000001*E15 | M15: =H15-E15 | N15: =H15-E15 | P15: σβ | Q15: =Dane!K5 | R15: =Dane!L5 | T15: u (niewiadome) | U15: =Dane!K11 | V15: VTV | W15: {=(MMULT(TRANSPOSE(T80:T111),T80:T111))}
B16: ='_calc_Dane'!F17 | C16: ='_calc_Dane'!G17 | D16: ='_calc_Dane'!H17 | E16: ='_calc_Dane'!I17 | F16: ='_calc_Dane'!M12-'_calc_Dane'!M6 | G16: ='_calc_Dane'!N12-'_calc_Dane'!N6 | H16: =SQRT(F16^2+G16^2) | I16: =IF(ATAN2(F16,G16)*200/PI()<0,ATAN2(F16,G16)*200/PI()+400,ATAN2(F16,G16)*200/PI()) | J16: =SIN(I16*PI()/200) | K16: =COS(I16*PI()/200) | L16: =0.001+0.000001*E16 | M16: =H16-E16 | N16: =H16-E16 | P16: σd | Q16: =Dane!K6 | R16: =Dane!L6 | T16: d (defekt) | U16: =Dane!K12
B17: ='_calc_Dane'!F18 | C17: ='_calc_Dane'!G18 | D17: ='_calc_Dane'!H18 | E17: ='_calc_Dane'!I18 | F17: ='_calc_Dane'!M13-'_calc_Dane'!M6 | G17: ='_calc_Dane'!N13-'_calc_Dane'!N6 | H17: =SQRT(F17^2+G17^2) | I17: =IF(ATAN2(F17,G17)*200/PI()<0,ATAN2(F17,G17)*200/PI()+400,ATAN2(F17,G17)*200/PI()) | J17: =SIN(I17*PI()/200) | K17: =COS(I17*PI()/200) | L17: =0.001+0.000001*E17 | M17: =H17-E17 | N17: =H17-E17
B18: ='_calc_Dane'!F19 | C18: ='_calc_Dane'!G19 | D18: ='_calc_Dane'!H19 | E18: ='_calc_Dane'!I19 | F18: ='_calc_Dane'!M8-'_calc_Dane'!M6 | G18: ='_calc_Dane'!N8-'_calc_Dane'!N6 | H18: =SQRT(F18^2+G18^2) | I18: =IF(ATAN2(F18,G18)*200/PI()<0,ATAN2(F18,G18)*200/PI()+400,ATAN2(F18,G18)*200/PI()) | J18: =SIN(I18*PI()/200) | K18: =COS(I18*PI()/200) | L18: =0.001+0.000001*E18 | M18: =H18-E18 | N18: =H18-E18 | P18: ρcc | Q18: =200/PI()*10000
B19: ='_calc_Dane'!F20 | C19: ='_calc_Dane'!G20 | D19: ='_calc_Dane'!H20 | E19: ='_calc_Dane'!I20 | F19: ='_calc_Dane'!M9-'_calc_Dane'!M8 | G19: ='_calc_Dane'!N9-'_calc_Dane'!N8 | H19: =SQRT(F19^2+G19^2) | I19: =IF(ATAN2(F19,G19)*200/PI()<0,ATAN2(F19,G19)*200/PI()+400,ATAN2(F19,G19)*200/PI()) | J19: =SIN(I19*PI()/200) | K19: =COS(I19*PI()/200) | L19: =0.001+0.000001*E19 | M19: =H19-E19 | N19: =H19-E19
B20: ='_calc_Dane'!F21 | C20: ='_calc_Dane'!G21 | D20: ='_calc_Dane'!H21 | E20: ='_calc_Dane'!I21 | F20: ='_calc_Dane'!M11-'_calc_Dane'!M8 | G20: ='_calc_Dane'!N11-'_calc_Dane'!N8 | H20: =SQRT(F20^2+G20^2) | I20: =IF(ATAN2(F20,G20)*200/PI()<0,ATAN2(F20,G20)*200/PI()+400) | J20: =SIN(I20*PI()/200) | K20: =COS(I20*PI()/200) | L20: =0.001+0.000001*E20 | M20: =H20-E20 | N20: =H20-E20
B21: ='_calc_Dane'!F22 | C21: ='_calc_Dane'!G22 | D21: ='_calc_Dane'!H22 | E21: ='_calc_Dane'!I22 | F21: ='_calc_Dane'!M13-'_calc_Dane'!M8 | G21: ='_calc_Dane'!N13-'_calc_Dane'!N8 | H21: =SQRT(F21^2+G21^2) | I21: =IF(ATAN2(F21,G21)*200/PI()<0,ATAN2(F21,G21)*200/PI()+400) | J21: =SIN(I21*PI()/200) | K21: =COS(I21*PI()/200) | L21: =0.001+0.000001*E21 | M21: =H21-E21 | N21: =H21-E21
B22: ='_calc_Dane'!F23 | C22: ='_calc_Dane'!G23 | D22: ='_calc_Dane'!H23 | E22: ='_calc_Dane'!I23 | F22: ='_calc_Dane'!M13-'_calc_Dane'!M10 | G22: ='_calc_Dane'!N13-'_calc_Dane'!N10 | H22: =SQRT(F22^2+G22^2) | I22: =IF(ATAN2(F22,G22)*200/PI()<0,ATAN2(F22,G22)*200/PI()+400) | J22: =SIN(I22*PI()/200) | K22: =COS(I22*PI()/200) | L22: =0.001+0.000001*E22 | M22: =H22-E22 | N22: =H22-E22
B23: ='_calc_Dane'!F24 | C23: ='_calc_Dane'!G24 | D23: ='_calc_Dane'!H24 | E23: ='_calc_Dane'!I24 | F23: ='_calc_Dane'!M9-'_calc_Dane'!M10 | G23: ='_calc_Dane'!N9-'_calc_Dane'!N10 | H23: =SQRT(F23^2+G23^2) | I23: =IF(ATAN2(F23,G23)*200/PI()<0,ATAN2(F23,G23)*200/PI()+400) | J23: =SIN(I23*PI()/200) | K23: =COS(I23*PI()/200) | L23: =0.001+0.000001*E23 | M23: =H23-E23 | N23: =H23-E23
B24: c | C24: l | D24: p | E24: βobs [g] | F24: Dxcl | G24: Dycl | H24: Dxcp | I24: Dycp | J24: d2cl | K24: d2cp | L24: Acl [rad] | M24: Acp [rad] | N24: βprzyb [g] | O24: błąd [cc] | P24: li [cc] | Q24: Acl | R24: Bcl | S24: Acp | T24: Bcp | U24: Dxcl | V24: Dycl | W24: Dxcp | X24: Dycp | Y24: Acl [rad] | Z24: Acp [rad] | AA24: βprzyb [g]
B25: c | C25: l | D25: p | E25: b obs [g] | F25: ∆xcl | G25: ∆ycl | H25: ∆xcp | I25: ∆ycp | J25: d²cl | K25: d²cp | L25: Az cl [g] | M25: Az cp [g] | N25: b przyb [g] | O25: Błąd [cc] | P25: l [g] | Q25: Acl. | R25: Bcl | S25: Acp | T25: Bcp | U25: =VLOOKUP(C25,$P$4:$V$12,4,FALSE)-VLOOKUP(B25,$P$4:$V$12,4,FALSE) | V25: =VLOOKUP(C25,$P$4:$V$12,5,FALSE)-VLOOKUP(B25,$P$4:$V$12,5,FALSE) | W25: =VLOOKUP(D25,$P$4:$V$12,4,FALSE)-VLOOKUP(B25,$P$4:$V$12,4,FALSE) | X25: =VLOOKUP(D25,$P$4:$V$12,5,FALSE)-VLOOKUP(B25,$P$4:$V$12,5,FALSE) | Y25: =IF(U25>0,IF(V25>0,ATAN(V25/U25),ATAN(V25/U25)+2*PI()),ATAN(V25/U25)+PI()) | Z25: =IF(W25>0,IF(X25>0,ATAN(X25/W25),ATAN(X25/W25)+2*PI()),ATAN(X25/W25)+PI()) | AA25: =IF((Z25-Y25)*200/PI()>0,(Z25-Y25)*200/PI(),(Z25-Y25)*200/PI()+400)
B26: ='_calc_Dane'!F25 | C26: ='_calc_Dane'!G25 | D26: ='_calc_Dane'!H25 | E26: ='_calc_Dane'!I25 | F26: ='_calc_Dane'!M5-'_calc_Dane'!M13 | G26: ='_calc_Dane'!N5-'_calc_Dane'!N13 | H26: ='_calc_Dane'!M6-'_calc_Dane'!M13 | I26: ='_calc_Dane'!N6-'_calc_Dane'!N13 | J26: =F26^2+G26^2 | K26: =H26^2+I26^2 | L26: =IF(ATAN2(F26,G26)*200/PI()<0,ATAN2(F26,G26)*200/PI()+400,ATAN2(F26,G26)*200/PI()) | M26: =IF(ATAN2(H26,I26)*200/PI()<0,ATAN2(H26,I26)*200/PI()+400,ATAN2(H26,I26)*200/PI()) | N26: =IF(M26-L26<0,M26-L26+400,M26-L26) | O26: ='_calc_Dane'!$M$15 | P26: =N26-E26 | Q26: =F26/J26*(2000000/PI()) | R26: =G26/J26*2000000/PI() | S26: =H26/K26*2000000/PI() | T26: =I26/K26*2000000/PI() | U26: =VLOOKUP(C26,$P$4:$V$12,4,FALSE)-VLOOKUP(B26,$P$4:$V$12,4,FALSE) | V26: =VLOOKUP(C26,$P$4:$V$12,5,FALSE)-VLOOKUP(B26,$P$4:$V$12,5,FALSE) | W26: =VLOOKUP(D26,$P$4:$V$12,4,FALSE)-VLOOKUP(B26,$P$4:$V$12,4,FALSE) | X26: =VLOOKUP(D26,$P$4:$V$12,5,FALSE)-VLOOKUP(B26,$P$4:$V$12,5,FALSE) | Y26: =IF(U26>0,IF(V26>0,ATAN(V26/U26),ATAN(V26/U26)+2*PI()),ATAN(V26/U26)+PI()) | Z26: =IF(W26>0,IF(X26>0,ATAN(X26/W26),ATAN(X26/W26)+2*PI()),ATAN(X26/W26)+PI()) | AA26: =IF((Z26-Y26)*200/PI()>0,(Z26-Y26)*200/PI(),(Z26-Y26)*200/PI()+400)
B27: ='_calc_Dane'!F26 | C27: ='_calc_Dane'!G26 | D27: ='_calc_Dane'!H26 | E27: ='_calc_Dane'!I26 | F27: ='_calc_Dane'!M6-'_calc_Dane'!M13 | G27: ='_calc_Dane'!N6-'_calc_Dane'!N13 | H27: ='_calc_Dane'!M8-'_calc_Dane'!M13 | I27: ='_calc_Dane'!N8-'_calc_Dane'!N13 | J27: =F27^2+G27^2 | K27: =H27^2+I27^2 | L27: =IF(ATAN2(F27,G27)*200/PI()<0,ATAN2(F27,G27)*200/PI()+400,ATAN2(F27,G27)*200/PI()) | M27: =IF(ATAN2(H27,I27)*200/PI()<0,ATAN2(H27,I27)*200/PI()+400,ATAN2(H27,I27)*200/PI()) | N27: =IF(M27-L27<0,M27-L27+400,M27-L27) | O27: ='_calc_Dane'!$M$15 | P27: =N27-E27 | Q27: =F27/J27*(2000000/PI()) | R27: =G27/J27*2000000/PI() | S27: =H27/K27*2000000/PI() | T27: =I27/K27*2000000/PI() | U27: =VLOOKUP(C27,$P$4:$V$12,4,FALSE)-VLOOKUP(B27,$P$4:$V$12,4,FALSE) | V27: =VLOOKUP(C27,$P$4:$V$12,5,FALSE)-VLOOKUP(B27,$P$4:$V$12,5,FALSE) | W27: =VLOOKUP(D27,$P$4:$V$12,4,FALSE)-VLOOKUP(B27,$P$4:$V$12,4,FALSE) | X27: =VLOOKUP(D27,$P$4:$V$12,5,FALSE)-VLOOKUP(B27,$P$4:$V$12,5,FALSE) | Y27: =IF(U27>0,IF(V27>0,ATAN(V27/U27),ATAN(V27/U27)+2*PI()),ATAN(V27/U27)+PI()) | Z27: =IF(W27>0,IF(X27>0,ATAN(X27/W27),ATAN(X27/W27)+2*PI()),ATAN(X27/W27)+PI()) | AA27: =IF((Z27-Y27)*200/PI()>0,(Z27-Y27)*200/PI(),(Z27-Y27)*200/PI()+400)
B28: ='_calc_Dane'!F27 | C28: ='_calc_Dane'!G27 | D28: ='_calc_Dane'!H27 | E28: ='_calc_Dane'!I27 | F28: ='_calc_Dane'!M8-'_calc_Dane'!M13 | G28: ='_calc_Dane'!N8-'_calc_Dane'!N13 | H28: ='_calc_Dane'!M9-'_calc_Dane'!M13 | I28: ='_calc_Dane'!N9-'_calc_Dane'!N13 | J28: =F28^2+G28^2 | K28: =H28^2+I28^2 | L28: =IF(ATAN2(F28,G28)*200/PI()<0,ATAN2(F28,G28)*200/PI()+400,ATAN2(F28,G28)*200/PI()) | M28: =IF(ATAN2(H28,I28)*200/PI()<0,ATAN2(H28,I28)*200/PI()+400,ATAN2(H28,I28)*200/PI()) | N28: =IF(M28-L28<0,M28-L28+400,M28-L28) | O28: ='_calc_Dane'!$M$15 | P28: =N28-E28 | Q28: =F28/J28*(2000000/PI()) | R28: =G28/J28*2000000/PI() | S28: =H28/K28*2000000/PI() | T28: =I28/K28*2000000/PI() | U28: =VLOOKUP(C28,$P$4:$V$12,4,FALSE)-VLOOKUP(B28,$P$4:$V$12,4,FALSE) | V28: =VLOOKUP(C28,$P$4:$V$12,5,FALSE)-VLOOKUP(B28,$P$4:$V$12,5,FALSE) | W28: =VLOOKUP(D28,$P$4:$V$12,4,FALSE)-VLOOKUP(B28,$P$4:$V$12,4,FALSE) | X28: =VLOOKUP(D28,$P$4:$V$12,5,FALSE)-VLOOKUP(B28,$P$4:$V$12,5,FALSE) | Y28: =IF(U28>0,IF(V28>0,ATAN(V28/U28),ATAN(V28/U28)+2*PI()),ATAN(V28/U28)+PI()) | Z28: =IF(W28>0,IF(X28>0,ATAN(X28/W28),ATAN(X28/W28)+2*PI()),ATAN(X28/W28)+PI()) | AA28: =IF((Z28-Y28)*200/PI()>0,(Z28-Y28)*200/PI(),(Z28-Y28)*200/PI()+400)
B29: ='_calc_Dane'!F28 | C29: ='_calc_Dane'!G28 | D29: ='_calc_Dane'!H28 | E29: ='_calc_Dane'!I28 | F29: ='_calc_Dane'!M9-'_calc_Dane'!M13 | G29: ='_calc_Dane'!N9-'_calc_Dane'!N13 | H29: ='_calc_Dane'!M11-'_calc_Dane'!M13 | I29: ='_calc_Dane'!N11-'_calc_Dane'!N13 | J29: =F29^2+G29^2 | K29: =H29^2+I29^2 | L29: =IF(ATAN2(F29,G29)*200/PI()<0,ATAN2(F29,G29)*200/PI()+400,ATAN2(F29,G29)*200/PI()) | M29: =IF(ATAN2(H29,I29)*200/PI()<0,ATAN2(H29,I29)*200/PI()+400,ATAN2(H29,I29)*200/PI()) | N29: =IF(M29-L29<0,M29-L29+400,M29-L29) | O29: ='_calc_Dane'!$M$15 | P29: =N29-E29 | Q29: =F29/J29*(2000000/PI()) | R29: =G29/J29*2000000/PI() | S29: =H29/K29*2000000/PI() | T29: =I29/K29*2000000/PI() | U29: =VLOOKUP(C29,$P$4:$V$12,4,FALSE)-VLOOKUP(B29,$P$4:$V$12,4,FALSE) | V29: =VLOOKUP(C29,$P$4:$V$12,5,FALSE)-VLOOKUP(B29,$P$4:$V$12,5,FALSE) | W29: =VLOOKUP(D29,$P$4:$V$12,4,FALSE)-VLOOKUP(B29,$P$4:$V$12,4,FALSE) | X29: =VLOOKUP(D29,$P$4:$V$12,5,FALSE)-VLOOKUP(B29,$P$4:$V$12,5,FALSE) | Y29: =IF(U29>0,IF(V29>0,ATAN(V29/U29),ATAN(V29/U29)+2*PI()),ATAN(V29/U29)+PI()) | Z29: =IF(W29>0,IF(X29>0,ATAN(X29/W29),ATAN(X29/W29)+2*PI()),ATAN(X29/W29)+PI()) | AA29: =IF((Z29-Y29)*200/PI()>0,(Z29-Y29)*200/PI(),(Z29-Y29)*200/PI()+400)
B30: ='_calc_Dane'!F29 | C30: ='_calc_Dane'!G29 | D30: ='_calc_Dane'!H29 | E30: ='_calc_Dane'!I29 | F30: ='_calc_Dane'!M11-'_calc_Dane'!M13 | G30: ='_calc_Dane'!N11-'_calc_Dane'!N13 | H30: ='_calc_Dane'!M12-'_calc_Dane'!M13 | I30: ='_calc_Dane'!N12-'_calc_Dane'!N13 | J30: =F30^2+G30^2 | K30: =H30^2+I30^2 | L30: =IF(ATAN2(F30,G30)*200/PI()<0,ATAN2(F30,G30)*200/PI()+400,ATAN2(F30,G30)*200/PI()) | M30: =IF(ATAN2(H30,I30)*200/PI()<0,ATAN2(H30,I30)*200/PI()+400,ATAN2(H30,I30)*200/PI()) | N30: =IF(M30-L30<0,M30-L30+400,M30-L30) | O30: ='_calc_Dane'!$M$15 | P30: =N30-E30 | Q30: =F30/J30*(2000000/PI()) | R30: =G30/J30*2000000/PI() | S30: =H30/K30*2000000/PI() | T30: =I30/K30*2000000/PI() | U30: =VLOOKUP(C30,$P$4:$V$12,4,FALSE)-VLOOKUP(B30,$P$4:$V$12,4,FALSE) | V30: =VLOOKUP(C30,$P$4:$V$12,5,FALSE)-VLOOKUP(B30,$P$4:$V$12,5,FALSE) | W30: =VLOOKUP(D30,$P$4:$V$12,4,FALSE)-VLOOKUP(B30,$P$4:$V$12,4,FALSE) | X30: =VLOOKUP(D30,$P$4:$V$12,5,FALSE)-VLOOKUP(B30,$P$4:$V$12,5,FALSE) | Y30: =IF(U30>0,IF(V30>0,ATAN(V30/U30),ATAN(V30/U30)+2*PI()),ATAN(V30/U30)+PI()) | Z30: =IF(W30>0,IF(X30>0,ATAN(X30/W30),ATAN(X30/W30)+2*PI()),ATAN(X30/W30)+PI()) | AA30: =IF((Z30-Y30)*200/PI()>0,(Z30-Y30)*200/PI(),(Z30-Y30)*200/PI()+400)
B31: ='_calc_Dane'!F30 | C31: ='_calc_Dane'!G30 | D31: ='_calc_Dane'!H30 | E31: ='_calc_Dane'!I30 | F31: ='_calc_Dane'!M12-'_calc_Dane'!M13 | G31: ='_calc_Dane'!N12-'_calc_Dane'!N13 | H31: ='_calc_Dane'!M5-'_calc_Dane'!M13 | I31: ='_calc_Dane'!N5-'_calc_Dane'!N13 | J31: =F31^2+G31^2 | K31: =H31^2+I31^2 | L31: =IF(ATAN2(F31,G31)*200/PI()<0,ATAN2(F31,G31)*200/PI()+400,ATAN2(F31,G31)*200/PI()) | M31: =IF(ATAN2(H31,I31)*200/PI()<0,ATAN2(H31,I31)*200/PI()+400,ATAN2(H31,I31)*200/PI()) | N31: =IF(M31-L31<0,M31-L31+400,M31-L31) | O31: ='_calc_Dane'!$M$15 | P31: =N31-E31 | Q31: =F31/J31*(2000000/PI()) | R31: =G31/J31*2000000/PI() | S31: =H31/K31*2000000/PI() | T31: =I31/K31*2000000/PI() | U31: =VLOOKUP(C31,$P$4:$V$12,4,FALSE)-VLOOKUP(B31,$P$4:$V$12,4,FALSE) | V31: =VLOOKUP(C31,$P$4:$V$12,5,FALSE)-VLOOKUP(B31,$P$4:$V$12,5,FALSE) | W31: =VLOOKUP(D31,$P$4:$V$12,4,FALSE)-VLOOKUP(B31,$P$4:$V$12,4,FALSE) | X31: =VLOOKUP(D31,$P$4:$V$12,5,FALSE)-VLOOKUP(B31,$P$4:$V$12,5,FALSE) | Y31: =IF(U31>0,IF(V31>0,ATAN(V31/U31),ATAN(V31/U31)+2*PI()),ATAN(V31/U31)+PI()) | Z31: =IF(W31>0,IF(X31>0,ATAN(X31/W31),ATAN(X31/W31)+2*PI()),ATAN(X31/W31)+PI()) | AA31: =IF((Z31-Y31)*200/PI()>0,(Z31-Y31)*200/PI(),(Z31-Y31)*200/PI()+400)
B32: ='_calc_Dane'!F31 | C32: ='_calc_Dane'!G31 | D32: ='_calc_Dane'!H31 | E32: ='_calc_Dane'!I31 | F32: ='_calc_Dane'!M12-'_calc_Dane'!M10 | G32: ='_calc_Dane'!N12-'_calc_Dane'!N10 | H32: ='_calc_Dane'!M11-'_calc_Dane'!M10 | I32: ='_calc_Dane'!N11-'_calc_Dane'!N10 | J32: =F32^2+G32^2 | K32: =H32^2+I32^2 | L32: =IF(ATAN2(F32,G32)*200/PI()<0,ATAN2(F32,G32)*200/PI()+400,ATAN2(F32,G32)*200/PI()) | M32: =IF(ATAN2(H32,I32)*200/PI()<0,ATAN2(H32,I32)*200/PI()+400,ATAN2(H32,I32)*200/PI()) | N32: =IF(M32-L32<0,M32-L32+400,M32-L32) | O32: ='_calc_Dane'!$M$15 | P32: =N32-E32 | Q32: =F32/J32*(2000000/PI()) | R32: =G32/J32*2000000/PI() | S32: =H32/K32*2000000/PI() | T32: =I32/K32*2000000/PI() | U32: =VLOOKUP(C32,$P$4:$V$12,4,FALSE)-VLOOKUP(B32,$P$4:$V$12,4,FALSE) | V32: =VLOOKUP(C32,$P$4:$V$12,5,FALSE)-VLOOKUP(B32,$P$4:$V$12,5,FALSE) | W32: =VLOOKUP(D32,$P$4:$V$12,4,FALSE)-VLOOKUP(B32,$P$4:$V$12,4,FALSE) | X32: =VLOOKUP(D32,$P$4:$V$12,5,FALSE)-VLOOKUP(B32,$P$4:$V$12,5,FALSE) | Y32: =IF(U32>0,IF(V32>0,ATAN(V32/U32),ATAN(V32/U32)+2*PI()),ATAN(V32/U32)+PI()) | Z32: =IF(W32>0,IF(X32>0,ATAN(X32/W32),ATAN(X32/W32)+2*PI()),ATAN(X32/W32)+PI()) | AA32: =IF((Z32-Y32)*200/PI()>0,(Z32-Y32)*200/PI(),(Z32-Y32)*200/PI()+400)
B33: ='_calc_Dane'!F32 | C33: ='_calc_Dane'!G32 | D33: ='_calc_Dane'!H32 | E33: ='_calc_Dane'!I32 | F33: ='_calc_Dane'!M11-'_calc_Dane'!M10 | G33: ='_calc_Dane'!N11-'_calc_Dane'!N10 | H33: ='_calc_Dane'!M13-'_calc_Dane'!M10 | I33: ='_calc_Dane'!N13-'_calc_Dane'!N10 | J33: =F33^2+G33^2 | K33: =H33^2+I33^2 | L33: =IF(ATAN2(F33,G33)*200/PI()<0,ATAN2(F33,G33)*200/PI()+400,ATAN2(F33,G33)*200/PI()) | M33: =IF(ATAN2(H33,I33)*200/PI()<0,ATAN2(H33,I33)*200/PI()+400,ATAN2(H33,I33)*200/PI()) | N33: =IF(M33-L33<0,M33-L33+400,M33-L33) | O33: ='_calc_Dane'!$M$15 | P33: =N33-E33 | Q33: =F33/J33*(2000000/PI()) | R33: =G33/J33*2000000/PI() | S33: =H33/K33*2000000/PI() | T33: =I33/K33*2000000/PI() | U33: =VLOOKUP(C33,$P$4:$V$12,4,FALSE)-VLOOKUP(B33,$P$4:$V$12,4,FALSE) | V33: =VLOOKUP(C33,$P$4:$V$12,5,FALSE)-VLOOKUP(B33,$P$4:$V$12,5,FALSE) | W33: =VLOOKUP(D33,$P$4:$V$12,4,FALSE)-VLOOKUP(B33,$P$4:$V$12,4,FALSE) | X33: =VLOOKUP(D33,$P$4:$V$12,5,FALSE)-VLOOKUP(B33,$P$4:$V$12,5,FALSE) | Y33: =IF(U33>0,IF(V33>0,ATAN(V33/U33),ATAN(V33/U33)+2*PI()),ATAN(V33/U33)+PI()) | Z33: =IF(W33>0,IF(X33>0,ATAN(X33/W33),ATAN(X33/W33)+2*PI()),ATAN(X33/W33)+PI()) | AA33: =IF((Z33-Y33)*200/PI()>0,(Z33-Y33)*200/PI(),(Z33-Y33)*200/PI()+400)
B34: ='_calc_Dane'!F33 | C34: ='_calc_Dane'!G33 | D34: ='_calc_Dane'!H33 | E34: ='_calc_Dane'!I33 | F34: ='_calc_Dane'!M13-'_calc_Dane'!M10 | G34: ='_calc_Dane'!N13-'_calc_Dane'!N10 | H34: ='_calc_Dane'!M9-'_calc_Dane'!M10 | I34: ='_calc_Dane'!N9-'_calc_Dane'!N10 | J34: =F34^2+G34^2 | K34: =H34^2+I34^2 | L34: =IF(ATAN2(F34,G34)*200/PI()<0,ATAN2(F34,G34)*200/PI()+400,ATAN2(F34,G34)*200/PI()) | M34: =IF(ATAN2(H34,I34)*200/PI()<0,ATAN2(H34,I34)*200/PI()+400,ATAN2(H34,I34)*200/PI()) | N34: =IF(M34-L34<0,M34-L34+400,M34-L34) | O34: ='_calc_Dane'!$M$15 | P34: =N34-E34 | Q34: =F34/J34*(2000000/PI()) | R34: =G34/J34*2000000/PI() | S34: =H34/K34*2000000/PI() | T34: =I34/K34*2000000/PI() | U34: =VLOOKUP(C34,$P$4:$V$12,4,FALSE)-VLOOKUP(B34,$P$4:$V$12,4,FALSE) | V34: =VLOOKUP(C34,$P$4:$V$12,5,FALSE)-VLOOKUP(B34,$P$4:$V$12,5,FALSE) | W34: =VLOOKUP(D34,$P$4:$V$12,4,FALSE)-VLOOKUP(B34,$P$4:$V$12,4,FALSE) | X34: =VLOOKUP(D34,$P$4:$V$12,5,FALSE)-VLOOKUP(B34,$P$4:$V$12,5,FALSE) | Y34: =IF(U34>0,IF(V34>0,ATAN(V34/U34),ATAN(V34/U34)+2*PI()),ATAN(V34/U34)+PI()) | Z34: =IF(W34>0,IF(X34>0,ATAN(X34/W34),ATAN(X34/W34)+2*PI()),ATAN(X34/W34)+PI()) | AA34: =IF((Z34-Y34)*200/PI()>0,(Z34-Y34)*200/PI(),(Z34-Y34)*200/PI()+400)
B35: ='_calc_Dane'!F34 | C35: ='_calc_Dane'!G34 | D35: ='_calc_Dane'!H34 | E35: ='_calc_Dane'!I34 | F35: ='_calc_Dane'!M10-'_calc_Dane'!M9 | G35: ='_calc_Dane'!N10-'_calc_Dane'!N9 | H35: ='_calc_Dane'!M11-'_calc_Dane'!M9 | I35: ='_calc_Dane'!N11-'_calc_Dane'!N9 | J35: =F35^2+G35^2 | K35: =H35^2+I35^2 | L35: =IF(ATAN2(F35,G35)*200/PI()<0,ATAN2(F35,G35)*200/PI()+400,ATAN2(F35,G35)*200/PI()) | M35: =IF(ATAN2(H35,I35)*200/PI()<0,ATAN2(H35,I35)*200/PI()+400,ATAN2(H35,I35)*200/PI()) | N35: =IF(M35-L35<0,M35-L35+400,M35-L35) | O35: ='_calc_Dane'!$M$15 | P35: =N35-E35 | Q35: =F35/J35*(2000000/PI()) | R35: =G35/J35*2000000/PI() | S35: =H35/K35*2000000/PI() | T35: =I35/K35*2000000/PI() | U35: =VLOOKUP(C35,$P$4:$V$12,4,FALSE)-VLOOKUP(B35,$P$4:$V$12,4,FALSE) | V35: =VLOOKUP(C35,$P$4:$V$12,5,FALSE)-VLOOKUP(B35,$P$4:$V$12,5,FALSE) | W35: =VLOOKUP(D35,$P$4:$V$12,4,FALSE)-VLOOKUP(B35,$P$4:$V$12,4,FALSE) | X35: =VLOOKUP(D35,$P$4:$V$12,5,FALSE)-VLOOKUP(B35,$P$4:$V$12,5,FALSE) | Y35: =IF(U35>0,IF(V35>0,ATAN(V35/U35),ATAN(V35/U35)+2*PI()),ATAN(V35/U35)+PI()) | Z35: =IF(W35>0,IF(X35>0,ATAN(X35/W35),ATAN(X35/W35)+2*PI()),ATAN(X35/W35)+PI()) | AA35: =IF((Z35-Y35)*200/PI()>0,(Z35-Y35)*200/PI(),(Z35-Y35)*200/PI()+400)
B36: ='_calc_Dane'!F35 | C36: ='_calc_Dane'!G35 | D36: ='_calc_Dane'!H35 | E36: ='_calc_Dane'!I35 | F36: ='_calc_Dane'!M11-'_calc_Dane'!M9 | G36: ='_calc_Dane'!N11-'_calc_Dane'!N9 | H36: ='_calc_Dane'!M13-'_calc_Dane'!M9 | I36: ='_calc_Dane'!N13-'_calc_Dane'!N9 | J36: =F36^2+G36^2 | K36: =H36^2+I36^2 | L36: =IF(ATAN2(F36,G36)*200/PI()<0,ATAN2(F36,G36)*200/PI()+400,ATAN2(F36,G36)*200/PI()) | M36: =IF(ATAN2(H36,I36)*200/PI()<0,ATAN2(H36,I36)*200/PI()+400,ATAN2(H36,I36)*200/PI()) | N36: =IF(M36-L36<0,M36-L36+400,M36-L36) | O36: ='_calc_Dane'!$M$15 | P36: =N36-E36 | Q36: =F36/J36*(2000000/PI()) | R36: =G36/J36*2000000/PI() | S36: =H36/K36*2000000/PI() | T36: =I36/K36*2000000/PI() | U36: =VLOOKUP(C36,$P$4:$V$12,4,FALSE)-VLOOKUP(B36,$P$4:$V$12,4,FALSE) | V36: =VLOOKUP(C36,$P$4:$V$12,5,FALSE)-VLOOKUP(B36,$P$4:$V$12,5,FALSE) | W36: =VLOOKUP(D36,$P$4:$V$12,4,FALSE)-VLOOKUP(B36,$P$4:$V$12,4,FALSE) | X36: =VLOOKUP(D36,$P$4:$V$12,5,FALSE)-VLOOKUP(B36,$P$4:$V$12,5,FALSE) | Y36: =IF(U36>0,IF(V36>0,ATAN(V36/U36),ATAN(V36/U36)+2*PI()),ATAN(V36/U36)+PI()) | Z36: =IF(W36>0,IF(X36>0,ATAN(X36/W36),ATAN(X36/W36)+2*PI()),ATAN(X36/W36)+PI()) | AA36: =IF((Z36-Y36)*200/PI()>0,(Z36-Y36)*200/PI(),(Z36-Y36)*200/PI()+400)
B37: ='_calc_Dane'!F36 | C37: ='_calc_Dane'!G36 | D37: ='_calc_Dane'!H36 | E37: ='_calc_Dane'!I36 | F37: ='_calc_Dane'!M13-'_calc_Dane'!M9 | G37: ='_calc_Dane'!N13-'_calc_Dane'!N9 | H37: ='_calc_Dane'!M8-'_calc_Dane'!M9 | I37: ='_calc_Dane'!N8-'_calc_Dane'!N9 | J37: =F37^2+G37^2 | K37: =H37^2+I37^2 | L37: =IF(ATAN2(F37,G37)*200/PI()<0,ATAN2(F37,G37)*200/PI()+400,ATAN2(F37,G37)*200/PI()) | M37: =IF(ATAN2(H37,I37)*200/PI()<0,ATAN2(H37,I37)*200/PI()+400,ATAN2(H37,I37)*200/PI()) | N37: =IF(M37-L37<0,M37-L37+400,M37-L37) | O37: ='_calc_Dane'!$M$15 | P37: =N37-E37 | Q37: =F37/J37*(2000000/PI()) | R37: =G37/J37*2000000/PI() | S37: =H37/K37*2000000/PI() | T37: =I37/K37*2000000/PI()
B39: a | S39: l [m/cc]
B40: dx
B41: 1 | C41: 1 | D41: 2 | E41: 2 | F41: 4 | G41: 4 | H41: 5 | I41: 5 | J41: 6 | K41: 6 | L41: 7 | M41: 7 | N41: 8 | O41: 8 | P41: 9 | Q41: 9 | R41: l | T41: v
B42: =IF(B$41=$B4,IF(B$40="dx",-$K4,-$J4),IF(B$41=$C4,IF(B$40="dx",$K4,$J4),0)) | C42: =IF(C$41=$B4,IF(C$40="dx",-$K4,-$J4),IF(C$41=$C4,IF(C$40="dx",$K4,$J4),0)) | D42: =IF(D$41=$B4,IF(D$40="dx",-$K4,-$J4),IF(D$41=$C4,IF(D$40="dx",$K4,$J4),0)) | E42: =IF(E$41=$B4,IF(E$40="dx",-$K4,-$J4),IF(E$41=$C4,IF(E$40="dx",$K4,$J4),0)) | F42: =IF(F$41=$B4,IF(F$40="dx",-$K4,-$J4),IF(F$41=$C4,IF(F$40="dx",$K4,$J4),0)) | G42: =IF(G$41=$B4,IF(G$40="dx",-$K4,-$J4),IF(G$41=$C4,IF(G$40="dx",$K4,$J4),0)) | H42: =IF(H$41=$B4,IF(H$40="dx",-$K4,-$J4),IF(H$41=$C4,IF(H$40="dx",$K4,$J4),0)) | I42: =IF(I$41=$B4,IF(I$40="dx",-$K4,-$J4),IF(I$41=$C4,IF(I$40="dx",$K4,$J4),0)) | ... Q42: =IF(Q$41=$B4,IF(Q$40="dx",-$K4,-$J4),IF(Q$41=$C4,IF(Q$40="dx",$K4,$J4),0)) | S42: =M4
...

Sheet IdentyfikacjaBazy
A2: ATA wyjściowy | R2: ST | U2: (ATA)-1 wyjściowy | AM2: ST(-1) | AO2: X | AP2: mx | AQ2: X | AR2: m0 | AS2: mx
A3: =Wstepnewyjsciowy!B115 | B3: {=_xlfn.ANCHORARRAY('Wstepnewyjsciowy'!B110)} | C3: -1321072 | D3: -727167.85 | E3: -1704466.7 | F3: 0 | G3: 0 | H3: 0 | I3: 0 | J3: 0 | K3: 0 | L3: -60305.207 | M3: 266348 | N3: -551395.99 | O3: 1785040.8 | P3: -2190966.5 | Q3: 974149.92 | R3: {=TRANSPOSE(B19:Q21)} | S3: 0 | T3: 0 | U3: dx | V3: 0 | W3: {=MINVERSE(B3:T21)} | X3: 3.0503499e-07 | Y3: 8.0476354e-07 | Z3: 7.1121386e-07 | AA3: 2.9044386e-08 | AB3: 4.5835186e-07 | AC3: 7.5628589e-25 | AD3: 0 | AE3: -5.2969972e-08 | AF3: -2.1385782e-07 | AG3: 1.8340734e-07 | AH3: -1.3557894e-07 | AI3: -1.2827387e-07 | AJ3: -2.2116184e-07 | AK3: 4.9816519e-07 | AL3: 2.3757557e-07 | AM3: 1 | AN3: -6.5960762e-16 | AO3: 0.00058119464 | AP3: 0 | AQ3: {=-MMULT(W3:AL18,_xlfn.ANCHORARRAY('Wstepnewyjsciowy'!V110))} | AR3: ='Wstepnewyjsciowy'!AB131 | AS3: =SQRT(ROUND(W3,10))*$AR$3 | AT3: 0 | AU3: Początek | AV3: Koniec | AW3: 0 | AX3: 0 | AY3: 0 | AZ3: 5 | BA3: 0 | BB3: 6 | BC3: 0 | BD3: 7 | BE3: 0 | BF3: 8 | BG3: 0 | BH3: 9 | BI3: 0 | BJ3: 0 | BK3: kierunek | BL3: 0 | BM3: Nr | BN3: 5 | BO3: 6 | BP3: 7 | BQ3: 8 | BR3: 9 | BS3: 0 | BT3: próba 1 | BU3: kierunek | BV3: 0 | BW3: Nr | BX3: 5 | BY3: 6 | BZ3: 7 | CA3: 8 | CB3: 9 | CC3: 0 | CD3: próba 4 | CE3: kierunek | CF3: 0 | CG3: Nr | CH3: 5 | CI3: 6 | CJ3: 7 | CK3: 8 | CL3: 9 | CM3: 0 | CN3: 0 | CO3: 0 | CP3: 0 | CQ3: 0 | CR3: 0 | CS3: 0 | CT3: 0 | CU3: 0 | CV3: 0 | CW3: 0 | CX3: 0 | CY3: 0 | CZ3: 0 | DA3: 0 | DB3: 0 | DC3: 0 | DD3: 0 | DE3: 0 | DF3: 0 | DG3: 0 | DH3: 0 | DI3: 0 | DJ3: 0 | DK3: 0 | DL3: 0 | DM3: 0 | DN3: 0 | DO3: 0 | DP3: 0 | DQ3: 0 | DR3: 0 | DS3: 0 | DT3: 0 | DU3: 0 | DV3: 0 | DW3: 0 | DX3: 0 | DY3: 0 | DZ3: 0 | EA3: 0 | EB3: 0 | EC3: 0 | ED3: 0 | EE3: 0 | EF3: 0 | EG3: 0 | EH3: 0 | EI3: 0 | EJ3: 0 | EK3: 0 | EL3: 0 | EM3: 0 | EN3: 0 | EO3: 0 | EP3: 0 | EQ3: 0 | ER3: 0 | ES3: 0 | ET3: 0 | EU3: 0 | EV3: 0 | EW3: 0 | EX3: 0 | EY3: 0 | EZ3: 0 | FA3: 0 | FB3: 0 | FC3: 0 | FD3: 0 | FE3: 0 | FF3: 0 | FG3: 0 | FH3: 0 | FI3: 0 | FJ3: 0 | FK3: 0 | FL3: 0 | FM3: 0 | FN3: 0 | FO3: 0 | FP3: 0 | FQ3: 0 | FR3: 0 | FS3: 0 | FT3: 0 | FU3: 0 | FV3: 0 | FW3: 0 | FX3: 0 | FY3: 0 | FZ3: 0 | GA3: 0 | GB3: 0 | GC3: 0 | GD3: 0 | GE3: 0 | GF3: 0 | GG3: 0 | GH3: 0 | GI3: 0 | GJ3: 0 | GK3: 0 | GL3: 0 | GM3: 0 | GN3: 0 | GO3: 0 | GP3: 0 | GQ3: 0 | GR3: 0 | GS3: 0 | GT3: 0 | GU3: 0 | GV3: 0 | GW3: 0 | GX3: 0 | GY3: 0 | GZ3: 0
A4: =Wstepnewyjsciowy!B116 | B4: -1321072 | C4: 2986537.5 | D4: -142881.15 | E4: 556830.31 | F4: 0 | G4: 0 | H4: 0 | I4: 0 | J4: 0 | K4: 0 | L4: 266348 | M4: -1176370.3 | N4: 497031.57 | O4: -1166911.2 | P4: 700573.58 | Q4: -1200086.3 | R4: 0 | S4: 0 | T4: 0 | U4: dy | V4: 0 | W4: 3.0503499e-07 | X4: 6.8049576e-07 | Y4: 2.767557e-07 | Z4: 2.8212662e-07 | AA4: -1.3430043e-08 | AB4: 1.7923364e-07 | AC4: -4.9659963e-25 | AD4: 0 | AE4: 6.7850241e-09 | AF4: 1.2180243e-07 | AG4: 6.1089864e-08 | AH4: 2.2813556e-07 | AI4: 1.378884e-07 | AJ4: 2.3773862e-07 | AK4: 8.2062481e-08 | AL4: 2.8615567e-07 | AM4: 4.2940048e-16 | AN4: 1 | AO4: -8.6393798e-05 | AP4: 0 | AQ4: 0.0010198994 | AR4: dy | AS4: =SQRT(ROUND(X4,10))*$AR$3 | AT4: Nr | AU4: 5 | AV4: 6 | AW4: 0 | AX4: 0 | AY4: xwyjść | AZ4: 0 | BA4: 1 | BB4: 0 | BC4: 0 | BD4: 0 | BE4: 0 | BF4: 0 | BG4: 0 | BH4: 0 | BI4: 0 | BJ4: 0 | BK4: 0 | BL4: 0 | BM4: ∆X | BN4: -9.6491071e-18 | BO4: 6.6699936e-05 | BP4: -0.0031739353 | BQ4: -0.003186979 | BR4: -0.0005373219 | BS4: 0 | BT4: 0 | BU4: 0 | BV4: 0 | BW4: ∆X | BX4: 2.8827663e-19 | BY4: 0.0036623659 | BZ4: -0.0015338263 | CA4: -0.003636419 | CB4: -0.00022742435 | CC4: 0 | CD4: 0 | CE4: 0 | CF4: 0 | CG4: ∆X | CH4: -0.001449009 | CI4: 1.798823e-17 | CJ4: 0.00033720006 | CK4: 0.002819418 | CL4: 0.0052482117 | CM4: 0 | CN4: 0 | CO4: 0 | CP4: 0 | CQ4: 0 | CR4: 0 | CS4: 0 | CT4: 0 | CU4: 0 | CV4: 0 | CW4: 0 | CX4: 0 | CY4: 0 | CZ4: 0 | DA4: 0 | DB4: 0 | DC4: 0 | DD4: 0 | DE4: 0 | DF4: 0 | DG4: 0 | DH4: 0 | DI4: 0 | DJ4: 0 | DK4: 0 | DL4: 0 | DM4: 0 | DN4: 0 | DO4: 0 | DP4: 0 | DQ4: 0 | DR4: 0 | DS4: 0 | DT4: 0 | DU4: 0 | DV4: 0 | DW4: 0 | DX4: 0 | DY4: 0 | DZ4: 0 | EA4: 0 | EB4: 0 | EC4: 0 | ED4: 0 | EE4: 0 | EF4: 0 | EG4: 0 | EH4: 0 | EI4: 0 | EJ4: 0 | EK4: 0 | EL4: 0 | EM4: 0 | EN4: 0 | EO4: 0 | EP4: 0 | EQ4: 0 | ER4: 0 | ES4: 0 | ET4: 0 | EU4: 0 | EV4: 0 | EW4: 0 | EX4: 0 | EY4: 0 | EZ4: 0 | FA4: 0 | FB4: 0 | FC4: 0 | FD4: 0 | FE4: 0 | FF4: 0 | FG4: 0 | FH4: 0 | FI4: 0 | FJ4: 0 | FK4: 0 | FL4: 0 | FM4: 0 | FN4: 0 | FO4: 0 | FP4: 0 | FQ4: 0 | FR4: 0 | FS4: 0 | FT4: 0 | FU4: 0 | FV4: 0 | FW4: 0 | FX4: 0 | FY4: 0 | FZ4: 0 | GA4: 0 | GB4: 0 | GC4: 0 | GD4: 0 | GE4: 0 | GF4: 0 | GG4: 0 | GH4: 0 | GI4: 0 | GJ4: 0 | GK4: 0 | GL4: 0 | GM4: 0 | GN4: 0 | GO4: 0 | GP4: 0 | GQ4: 0 | GR4: 0 | GS4: 0 | GT4: 0 | GU4: 0 | GV4: 0 | GW4: 0 | GX4: 0 | GY4: 0 | GZ4: 0
