Workbook

Sheet Dane
A4: Wyniki pomiaru wyjściowego | F4: Wyniki pomiaru aktualnego | J4: Numer ID | K4: 3
A5: c | B5: l | C5: p | D5: Lobs. | E5: c | F5: l | G5: p | H5: Lobs. | J5: σβ | K5: 3 | L5: cc
A6: 7 | B6: 1 | C6: 0 | D6: 271.7062 | E6: 7 | F6: 1 | G6: 0 | H6: 271.702 | J6: σd | K6: 0,001+10-6d | L6: [m]
A7: 7 | B7: 5 | C7: 0 | D7: 155.7243 | E7: 7 | F7: 5 | G7: 0 | H7: 155.7279
A8: 7 | B8: 6 | C8: 0 | D8: 178.4659 | E8: 7 | F8: 6 | G8: 0 | H8: 178.4685 | J8: ρcc | K8: 636619.77
A9: 7 | B9: 8 | C9: 0 | D9: 148.0717 | E9: 7 | F9: 8 | G9: 0 | H9: 148.0689
A10: 7 | B10: 9 | C10: 0 | D10: 174.5226 | E10: 7 | F10: 9 | G10: 0 | H10: 174.522 | J10: n (obserwacje) | K10: 32
A11: 8 | B11: 1 | C11: 0 | D11: 149.9983 | E11: 8 | F11: 1 | G11: 0 | H11: 150.0006 | J11: u (niewiadome) | K11: 16
A12: 8 | B12: 9 | C12: 0 | D12: 166.1118 | E12: 8 | F12: 9 | G12: 0 | H12: 166.1145 | J12: d (defekt) | K12: 3
A13: 8 | B13: 7 | C13: 0 | D13: 148.0732 | E13: 8 | F13: 7 | G13: 0 | H13: 148.0712
A14: 8 | B14: 6 | C14: 0 | D14: 320.0413 | E14: 8 | F14: 6 | G14: 0 | H14: 320.0445
A15: 1 | B15: 3 | C15: 0 | D15: 266.1756 | E15: 1 | F15: 2 | G15: 0 | H15: 147.1241
A16: 1 | B16: 9 | C16: 0 | D16: 168.6215 | E16: 1 | F16: 9 | G16: 0 | H16: 168.6108 | J16: Współrzędne przybliżone
A17: 1 | B17: 7 | C17: 0 | D17: 271.7081 | E17: 1 | F17: 7 | G17: 0 | H17: 271.7008 | J17: Nr | K17: X0 | L17: Y0
A18: 3 | B18: 5 | C18: 0 | D18: 304.0138 | E18: 2 | F18: 8 | G18: 0 | H18: 253.4723 | J18: 1 | K18: 240 | L18: 120
A19: 3 | B19: 9 | C19: 0 | D19: 164.2349 | E19: 2 | F19: 9 | G19: 0 | H19: 145.9865 | J19: 2 | K19: 385 | L19: 145
A20: 3 | B20: 4 | C20: 0 | D20: 194.1629 | E20: 2 | F20: 4 | G20: 0 | H20: 294.2725 | J20: 3 | K20: 475 | L20: 245
A21: 4 | B21: 5 | C21: 0 | D21: 150.4167 | E21: 4 | F21: 5 | G21: 0 | H21: 150.4243 | J21: 4 | K21: 435 | L21: 435
A22: 4 | B22: 7 | C22: 0 | D22: 259.8561 | E22: 4 | F22: 7 | G22: 0 | H22: 259.868 | J22: 5 | K22: 295 | L22: 490
A23: 4 | B23: 9 | C23: 0 | D23: 203.6004 | E23: 4 | F23: 9 | G23: 0 | H23: 203.6019 | J23: 6 | K23: 145 | L23: 560
A24: 6 | B24: 9 | C24: 0 | D24: 333.4194 | E24: 6 | F24: 9 | G24: 0 | H24: 333.4174 | J24: 7 | K24: 180 | L24: 385
A25: 6 | B25: 5 | C25: 0 | D25: 165.528 | E25: 6 | F25: 5 | G25: 0 | H25: 165.5303 | J25: 8 | K25: 150 | L25: 240
A26: 9 | B26: 1 | C26: 3 | D26: 117.9893 | E26: 9 | F26: 1 | G26: 2 | H26: 61.3342 | J26: 9 | K26: 313 | L26: 272
A27: 9 | B27: 3 | C27: 4 | D27: 69.6093 | E27: 9 | F27: 2 | G27: 4 | H27: 126.2606
A28: 9 | B28: 4 | C28: 5 | D28: 46.1487 | E28: 9 | F28: 4 | G28: 5 | H28: 46.1513
A29: 9 | B29: 5 | C29: 7 | D29: 49.92 | E29: 9 | F29: 5 | G29: 7 | H29: 49.9219
A30: 9 | B30: 7 | C30: 8 | D30: 57.1766 | E30: 9 | F30: 7 | G30: 8 | H30: 57.1764
A31: 9 | B31: 8 | C31: 1 | D31: 59.1555 | E31: 9 | F31: 8 | G31: 1 | H31: 59.1567
A32: 6 | B32: 8 | C32: 7 | D32: 11.5719 | E32: 6 | F32: 8 | G32: 7 | H32: 11.5714
A33: 6 | B33: 7 | C33: 9 | D33: 21.0515 | E33: 6 | F33: 7 | G33: 9 | H33: 21.0531
A34: 6 | B34: 9 | C34: 5 | D34: 38.5847 | E34: 6 | F34: 9 | G34: 5 | H34: 38.5857
A35: 5 | B35: 6 | C35: 7 | D35: 74.9047 | E35: 5 | F35: 6 | G35: 7 | H35: 74.9054
A36: 5 | B36: 7 | C36: 9 | D36: 58.1366 | E36: 5 | F36: 7 | G36: 9 | H36: 58.1359
A37: 5 | B37: 9 | C37: 4 | D37: 70.9251 | E37: 5 | F37: 9 | G37: 4 | H37: 70.9246

Sheet Wyrównanie wstępne - wyjściowy
B3: c | C3: l | D3: p | E3: L obs [m] | F3: ∆x | G3: ∆y | H3: L przyb [m] | I3: Az [g] | J3: Sin Az | K3: Cos Az | L3: Błąd [m] | M3: l [m] | P3: Współrzedne przybliżone
B4: ='_calc_Dane'!B5 | C4: ='_calc_Dane'!C5 | D4: ='_calc_Dane'!D5 | E4: ='_calc_Dane'!E5 | F4: ='_calc_Dane'!M5-'_calc_Dane'!M11 | G4: ='_calc_Dane'!N5-'_calc_Dane'!N11 | H4: =SQRT(F4^2+G4^2) | I4: =IF(ATAN2(F4,G4)*200/PI()<0,ATAN2(F4,G4)*200/PI()+400) | J4: =SIN(I4*PI()/200) | K4: =COS(I4*PI()/200) | L4: =0.001+0.000001*E4 | M4: =H4-E4 | P4: NR | Q4: Xo | R4: Yo
B5: ='_calc_Dane'!B6 | C5: ='_calc_Dane'!C6 | D5: ='_calc_Dane'!D6 | E5: ='_calc_Dane'!E6 | F5: ='_calc_Dane'!M9-'_calc_Dane'!M11 | G5: ='_calc_Dane'!N9-'_calc_Dane'!N11 | H5: =SQRT(F5^2+G5^2) | I5: =IF(ATAN2(F5,G5)*200/PI()<0,ATAN2(F5,G5)*200/PI()+400,ATAN2(F5,G5)*200/PI()) | J5: =SIN(I5*PI()/200) | K5: =COS(I5*PI()/200) | L5: =0.001+0.000001*E5 | M5: =H5-E5 | P5: 1 | Q5: 240 | R5: 120
B6: ='_calc_Dane'!B7 | C6: ='_calc_Dane'!C7 | D6: ='_calc_Dane'!D7 | E6: ='_calc_Dane'!E7 | F6: ='_calc_Dane'!M10-'_calc_Dane'!M11 | G6: ='_calc_Dane'!N10-'_calc_Dane'!N11 | H6: =SQRT(F6^2+G6^2) | I6: =IF(ATAN2(F6,G6)*200/PI()<0,ATAN2(F6,G6)*200/PI()+400,ATAN2(F6,G6)*200/PI()) | J6: =SIN(I6*PI()/200) | K6: =COS(I6*PI()/200) | L6: =0.001+0.000001*E6 | M6: =H6-E6 | P6: 2 | Q6: 385 | R6: 145
B7: ='_calc_Dane'!B8 | C7: ='_calc_Dane'!C8 | D7: ='_calc_Dane'!D8 | E7: ='_calc_Dane'!E8 | F7: ='_calc_Dane'!M12-'_calc_Dane'!M11 | G7: ='_calc_Dane'!N12-'_calc_Dane'!N11 | H7: =SQRT(F7^2+G7^2) | I7: =IF(ATAN2(F7,G7)*200/PI()<0,ATAN2(F7,G7)*200/PI()+400) | J7: =SIN(I7*PI()/200) | K7: =COS(I7*PI()/200) | L7: =0.001+0.000001*E7 | M7: =H7-E7 | P7: 3 | Q7: 475 | R7: 245
B8: ='_calc_Dane'!B9 | C8: ='_calc_Dane'!C9 | D8: ='_calc_Dane'!D9 | E8: ='_calc_Dane'!E9 | F8: ='_calc_Dane'!M13-'_calc_Dane'!M11 | G8: ='_calc_Dane'!N13-'_calc_Dane'!N11 | H8: =SQRT(F8^2+G8^2) | I8: =IF(ATAN2(F8,G8)*200/PI()<0,ATAN2(F8,G8)*200/PI()+400) | J8: =SIN(I8*PI()/200) | K8: =COS(I8*PI()/200) | L8: =0.001+0.000001*E8 | M8: =H8-E8 | P8: 4 | Q8: 435 | R8: 435
B9: ='_calc_Dane'!B10 | C9: ='_calc_Dane'!C10 | D9: ='_calc_Dane'!D10 | E9: ='_calc_Dane'!E10 | F9: ='_calc_Dane'!M5-'_calc_Dane'!M12 | G9: ='_calc_Dane'!N5-'_calc_Dane'!N12 | H9: =SQRT(F9^2+G9^2) | I9: =IF(ATAN2(F9,G9)*200/PI()<0,ATAN2(F9,G9)*200/PI()+400) | J9: =SIN(I9*PI()/200) | K9: =COS(I9*PI()/200) | L9: =0.001+0.000001*E9 | M9: =H9-E9 | P9: 5 | Q9: 295 | R9: 490
B10: ='_calc_Dane'!B11 | C10: ='_calc_Dane'!C11 | D10: ='_calc_Dane'!D11 | E10: ='_calc_Dane'!E11 | F10: ='_calc_Dane'!M13-'_calc_Dane'!M12 | G10: ='_calc_Dane'!N13-'_calc_Dane'!N12 | H10: =SQRT(F10^2+G10^2) | I10: =IF(ATAN2(F10,G10)*200/PI()<0,ATAN2(F10,G10)*200/PI()+400,ATAN2(F10,G10)*200/PI()) | J10: =SIN(I10*PI()/200) | K10: =COS(I10*PI()/200) | L10: =0.001+0.000001*E10 | M10: =H10-E10 | P10: 6 | Q10: 145 | R10: 560
B11: ='_calc_Dane'!B12 | C11: ='_calc_Dane'!C12 | D11: ='_calc_Dane'!D12 | E11: ='_calc_Dane'!E12 | F11: ='_calc_Dane'!M11-'_calc_Dane'!M12 | G11: ='_calc_Dane'!N11-'_calc_Dane'!N12 | H11: =SQRT(F11^2+G11^2) | I11: =IF(ATAN2(F11,G11)*200/PI()<0,ATAN2(F11,G11)*200/PI()+400,ATAN2(F11,G11)*200/PI()) | J11: =SIN(I11*PI()/200) | K11: =COS(I11*PI()/200) | L11: =0.001+0.000001*E11 | M11: =H11-E11 | P11: 7 | Q11: 180 | R11: 385
B12: ='_calc_Dane'!B13 | C12: ='_calc_Dane'!C13 | D12: ='_calc_Dane'!D13 | E12: ='_calc_Dane'!E13 | F12: ='_calc_Dane'!M10-'_calc_Dane'!M12 | G12: ='_calc_Dane'!N10-'_calc_Dane'!N12 | H12: =SQRT(F12^2+G12^2) | I12: =IF(ATAN2(F12,G12)*200/PI()<0,ATAN2(F12,G12)*200/PI()+400,ATAN2(F12,G12)*200/PI()) | J12: =SIN(I12*PI()/200) | K12: =COS(I12*PI()/200) | L12: =0.001+0.000001*E12 | M12: =H12-E12 | P12: 8 | Q12: 150 | R12: 240
B13: ='_calc_Dane'!B14 | C13: ='_calc_Dane'!C14 | D13: ='_calc_Dane'!D14 | E13: ='_calc_Dane'!E14 | F13: ='_calc_Dane'!M7-'_calc_Dane'!M5 | G13: ='_calc_Dane'!N7-'_calc_Dane'!N5 | H13: =SQRT(F13^2+G13^2) | I13: =IF(ATAN2(F13,G13)*200/PI()<0,ATAN2(F13,G13)*200/PI()+400,ATAN2(F13,G13)*200/PI()) | J13: =SIN(I13*PI()/200) | K13: =COS(I13*PI()/200) | L13: =0.001+0.000001*E13 | M13: =H13-E13 | P13: 9 | Q13: 314 | R13: 271
B14: ='_calc_Dane'!B15 | C14: ='_calc_Dane'!C15 | D14: ='_calc_Dane'!D15 | E14: ='_calc_Dane'!E15 | F14: ='_calc_Dane'!M13-'_calc_Dane'!M5 | G14: ='_calc_Dane'!N13-'_calc_Dane'!N5 | H14: =SQRT(F14^2+G14^2) | I14: =IF(ATAN2(F14,G14)*200/PI()<0,ATAN2(F14,G14)*200/PI()+400,ATAN2(F14,G14)*200/PI()) | J14: =SIN(I14*PI()/200) | K14: =COS(I14*PI()/200) | L14: =0.001+0.000001*E14 | M14: =H14-E14
B15: ='_calc_Dane'!B16 | C15: ='_calc_Dane'!C16 | D15: ='_calc_Dane'!D16 | E15: ='_calc_Dane'!E16 | F15: ='_calc_Dane'!M11-'_calc_Dane'!M5 | G15: ='_calc_Dane'!N11-'_calc_Dane'!N5 | H15: =SQRT(F15^2+G15^2) | I15: =IF(ATAN2(F15,G15)*200/PI()<0,ATAN2(F15,G15)*200/PI()+400,ATAN2(F15,G15)*200/PI()) | J15: =SIN(I15*PI()/200) | K15: =COS(I15*PI()/200) | L15: =0.001+0.000001*E15 | M15: =H15-E15
B16: ='_calc_Dane'!B17 | C16: ='_calc_Dane'!C17 | D16: ='_calc_Dane'!D17 | E16: ='_calc_Dane'!E17 | F16: ='_calc_Dane'!M9-'_calc_Dane'!M7 | G16: ='_calc_Dane'!N9-'_calc_Dane'!N7 | H16: =SQRT(F16^2+G16^2) | I16: =IF(ATAN2(F16,G16)*200/PI()<0,ATAN2(F16,G16)*200/PI()+400,ATAN2(F16,G16)*200/PI()) | J16: =SIN(I16*PI()/200) | K16: =COS(I16*PI()/200) | L16: =0.001+0.000001*E16 | M16: =H16-E16
B17: ='_calc_Dane'!B18 | C17: ='_calc_Dane'!C18 | D17: ='_calc_Dane'!D18 | E17: ='_calc_Dane'!E18 | F17: ='_calc_Dane'!M13-'_calc_Dane'!M7 | G17: ='_calc_Dane'!N13-'_calc_Dane'!N7 | H17: =SQRT(F17^2+G17^2) | I17: =IF(ATAN2(F17,G17)*200/PI()<0,ATAN2(F17,G17)*200/PI()+400,ATAN2(F17,G17)*200/PI()) | J17: =SIN(I17*PI()/200) | K17: =COS(I17*PI()/200) | L17: =0.001+0.000001*E17 | M17: =H17-E17
B18: ='_calc_Dane'!B19 | C18: ='_calc_Dane'!C19 | D18: ='_calc_Dane'!D19 | E18: ='_calc_Dane'!E19 | F18: ='_calc_Dane'!M8-'_calc_Dane'!M7 | G18: ='_calc_Dane'!N8-'_calc_Dane'!N7 | H18: =SQRT(F18^2+G18^2) | I18: =IF(ATAN2(F18,G18)*200/PI()<0,ATAN2(F18,G18)*200/PI()+400,ATAN2(F18,G18)*200/PI()) | J18: =SIN(I18*PI()/200) | K18: =COS(I18*PI()/200) | L18: =0.001+0.000001*E18 | M18: =H18-E18
B19: ='_calc_Dane'!B20 | C19: ='_calc_Dane'!C20 | D19: ='_calc_Dane'!D20 | E19: ='_calc_Dane'!E20 | F19: ='_calc_Dane'!M9-'_calc_Dane'!M8 | G19: ='_calc_Dane'!N9-'_calc_Dane'!N8 | H19: =SQRT(F19^2+G19^2) | I19: =IF(ATAN2(F19,G19)*200/PI()<0,ATAN2(F19,G19)*200/PI()+400,ATAN2(F19,G19)*200/PI()) | J19: =SIN(I19*PI()/200) | K19: =COS(I19*PI()/200) | L19: =0.001+0.000001*E19 | M19: =H19-E19
B20: ='_calc_Dane'!B21 | C20: ='_calc_Dane'!C21 | D20: ='_calc_Dane'!D21 | E20: ='_calc_Dane'!E21 | F20: ='_calc_Dane'!M11-'_calc_Dane'!M8 | G20: ='_calc_Dane'!N11-'_calc_Dane'!N8 | H20: =SQRT(F20^2+G20^2) | I20: =IF(ATAN2(F20,G20)*200/PI()<0,ATAN2(F20,G20)*200/PI()+400) | J20: =SIN(I20*PI()/200) | K20: =COS(I20*PI()/200) | L20: =0.001+0.000001*E20 | M20: =H20-E20
B21: ='_calc_Dane'!B22 | C21: ='_calc_Dane'!C22 | D21: ='_calc_Dane'!D22 | E21: ='_calc_Dane'!E22 | F21: ='_calc_Dane'!M13-'_calc_Dane'!M8 | G21: ='_calc_Dane'!N13-'_calc_Dane'!N8 | H21: =SQRT(F21^2+G21^2) | I21: =IF(ATAN2(F21,G21)*200/PI()<0,ATAN2(F21,G21)*200/PI()+400) | J21: =SIN(I21*PI()/200) | K21: =COS(I21*PI()/200) | L21: =0.001+0.000001*E21 | M21: =H21-E21
B22: ='_calc_Dane'!B23 | C22: ='_calc_Dane'!C23 | D22: ='_calc_Dane'!D23 | E22: ='_calc_Dane'!E23 | F22: ='_calc_Dane'!M13-'_calc_Dane'!M10 | G22: ='_calc_Dane'!N13-'_calc_Dane'!N10 | H22: =SQRT(F22^2+G22^2) | I22: =IF(ATAN2(F22,G22)*200/PI()<0,ATAN2(F22,G22)*200/PI()+400) | J22: =SIN(I22*PI()/200) | K22: =COS(I22*PI()/200) | L22: =0.001+0.000001*E22 | M22: =H22-E22
B23: ='_calc_Dane'!B24 | C23: ='_calc_Dane'!C24 | D23: ='_calc_Dane'!D24 | E23: ='_calc_Dane'!E24 | F23: ='_calc_Dane'!M9-'_calc_Dane'!M10 | G23: ='_calc_Dane'!N9-'_calc_Dane'!N10 | H23: =SQRT(F23^2+G23^2) | I23: =IF(ATAN2(F23,G23)*200/PI()<0,ATAN2(F23,G23)*200/PI()+400) | J23: =SIN(I23*PI()/200) | K23: =COS(I23*PI()/200) | L23: =0.001+0.000001*E23 | M23: =H23-E23
B25: c | C25: l | D25: p | E25: b obs [g] | F25: ∆xcl | G25: ∆ycl | H25: ∆xcp | I25: ∆ycp | J25: d²cl | K25: d²cp | L25: Az cl [g] | M25: Az cp [g] | N25: b przyb [g] | O25: Błąd [cc] | P25: l [g] | Q25: Al. | R25: Bl | S25: Ap | T25: Bp
B26: ='_calc_Dane'!B25 | C26: ='_calc_Dane'!C25 | D26: ='_calc_Dane'!D25 | E26: ='_calc_Dane'!E25 | F26: ='_calc_Dane'!M5-'_calc_Dane'!M13 | G26: ='_calc_Dane'!N5-'_calc_Dane'!N13 | H26: ='_calc_Dane'!M7-'_calc_Dane'!M13 | I26: ='_calc_Dane'!N7-'_calc_Dane'!N13 | J26: =F26^2+G26^2 | K26: =H26^2+I26^2 | L26: =IF(ATAN2(F26,G26)*200/PI()<0,ATAN2(F26,G26)*200/PI()+400,ATAN2(F26,G26)*200/PI()) | M26: =IF(ATAN2(H26,I26)*200/PI()<0,ATAN2(H26,I26)*200/PI()+400,ATAN2(H26,I26)*200/PI()) | N26: =IF(M26-L26<0,M26-L26+400,M26-L26) | O26: ='_calc_Dane'!$M$15 | P26: =N26-E26 | Q26: =F26/J26*2000000/PI() | R26: =G26/J26*2000000/PI() | S26: =H26/K26*2000000/PI() | T26: =I26/K26*2000000/PI()
B27: ='_calc_Dane'!B26 | C27: ='_calc_Dane'!C26 | D27: ='_calc_Dane'!D26 | E27: ='_calc_Dane'!E26 | F27: ='_calc_Dane'!M7-'_calc_Dane'!M13 | G27: ='_calc_Dane'!N7-'_calc_Dane'!N13 | H27: ='_calc_Dane'!M8-'_calc_Dane'!M13 | I27: ='_calc_Dane'!N8-'_calc_Dane'!N13 | J27: =F27^2+G27^2 | K27: =H27^2+I27^2 | L27: =IF(ATAN2(F27,G27)*200/PI()<0,ATAN2(F27,G27)*200/PI()+400,ATAN2(F27,G27)*200/PI()) | M27: =IF(ATAN2(H27,I27)*200/PI()<0,ATAN2(H27,I27)*200/PI()+400,ATAN2(H27,I27)*200/PI()) | N27: =IF(M27-L27<0,M27-L27+400,M27-L27) | O27: ='_calc_Dane'!$M$15 | P27: =N27-E27 | Q27: =F27/J27*2000000/PI() | R27: =G27/J27*2000000/PI() | S27: =H27/K27*2000000/PI() | T27: =I27/K27*2000000/PI()
B28: ='_calc_Dane'!B27 | C28: ='_calc_Dane'!C27 | D28: ='_calc_Dane'!D27 | E28: ='_calc_Dane'!E27 | F28: ='_calc_Dane'!M8-'_calc_Dane'!M13 | G28: ='_calc_Dane'!N8-'_calc_Dane'!N13 | H28: ='_calc_Dane'!M9-'_calc_Dane'!M13 | I28: ='_calc_Dane'!N9-'_calc_Dane'!N13 | J28: =F28^2+G28^2 | K28: =H28^2+I28^2 | L28: =IF(ATAN2(F28,G28)*200/PI()<0,ATAN2(F28,G28)*200/PI()+400,ATAN2(F28,G28)*200/PI()) | M28: =IF(ATAN2(H28,I28)*200/PI()<0,ATAN2(H28,I28)*200/PI()+400,ATAN2(H28,I28)*200/PI()) | N28: =IF(M28-L28<0,M28-L28+400,M28-L28) | O28: ='_calc_Dane'!$M$15 | P28: =N28-E28 | Q28: =F28/J28*2000000/PI() | R28: =G28/J28*2000000/PI() | S28: =H28/K28*2000000/PI() | T28: =I28/K28*2000000/PI()
B29: ='_calc_Dane'!B28 | C29: ='_calc_Dane'!C28 | D29: ='_calc_Dane'!D28 | E29: ='_calc_Dane'!E28 | F29: ='_calc_Dane'!M9-'_calc_Dane'!M13 | G29: ='_calc_Dane'!N9-'_calc_Dane'!N13 | H29: ='_calc_Dane'!M11-'_calc_Dane'!M13 | I29: ='_calc_Dane'!N11-'_calc_Dane'!N13 | J29: =F29^2+G29^2 | K29: =H29^2+I29^2 | L29: =IF(ATAN2(F29,G29)*200/PI()<0,ATAN2(F29,G29)*200/PI()+400,ATAN2(F29,G29)*200/PI()) | M29: =IF(ATAN2(H29,I29)*200/PI()<0,ATAN2(H29,I29)*200/PI()+400,ATAN2(H29,I29)*200/PI()) | N29: =IF(M29-L29<0,M29-L29+400,M29-L29) | O29: ='_calc_Dane'!$M$15 | P29: =N29-E29 | Q29: =F29/J29*2000000/PI() | R29: =G29/J29*2000000/PI() | S29: =H29/K29*2000000/PI() | T29: =I29/K29*2000000/PI()
B30: ='_calc_Dane'!B29 | C30: ='_calc_Dane'!C29 | D30: ='_calc_Dane'!D29 | E30: ='_calc_Dane'!E29 | F30: ='_calc_Dane'!M11-'_calc_Dane'!M13 | G30: ='_calc_Dane'!N11-'_calc_Dane'!N13 | H30: ='_calc_Dane'!M12-'_calc_Dane'!M13 | I30: ='_calc_Dane'!N12-'_calc_Dane'!N13 | J30: =F30^2+G30^2 | K30: =H30^2+I30^2 | L30: =IF(ATAN2(F30,G30)*200/PI()<0,ATAN2(F30,G30)*200/PI()+400,ATAN2(F30,G30)*200/PI()) | M30: =IF(ATAN2(H30,I30)*200/PI()<0,ATAN2(H30,I30)*200/PI()+400,ATAN2(H30,I30)*200/PI()) | N30: =IF(M30-L30<0,M30-L30+400,M30-L30) | O30: ='_calc_Dane'!$M$15 | P30: =N30-E30 | Q30: =F30/J30*2000000/PI() | R30: =G30/J30*2000000/PI() | S30: =H30/K30*2000000/PI() | T30: =I30/K30*2000000/PI()
B31: ='_calc_Dane'!B30 | C31: ='_calc_Dane'!C30 | D31: ='_calc_Dane'!D30 | E31: ='_calc_Dane'!E30 | F31: ='_calc_Dane'!M12-'_calc_Dane'!M13 | G31: ='_calc_Dane'!N12-'_calc_Dane'!N13 | H31: ='_calc_Dane'!M5-'_calc_Dane'!M13 | I31: ='_calc_Dane'!N5-'_calc_Dane'!N13 | J31: =F31^2+G31^2 | K31: =H31^2+I31^2 | L31: =IF(ATAN2(F31,G31)*200/PI()<0,ATAN2(F31,G31)*200/PI()+400,ATAN2(F31,G31)*200/PI()) | M31: =IF(ATAN2(H31,I31)*200/PI()<0,ATAN2(H31,I31)*200/PI()+400,ATAN2(H31,I31)*200/PI()) | N31: =IF(M31-L31<0,M31-L31+400,M31-L31) | O31: ='_calc_Dane'!$M$15 | P31: =N31-E31 | Q31: =F31/J31*2000000/PI() | R31: =G31/J31*2000000/PI() | S31: =H31/K31*2000000/PI() | T31: =I31/K31*2000000/PI()
B32: ='_calc_Dane'!B31 | C32: ='_calc_Dane'!C31 | D32: ='_calc_Dane'!D31 | E32: ='_calc_Dane'!E31 | F32: ='_calc_Dane'!M12-'_calc_Dane'!M10 | G32: ='_calc_Dane'!N12-'_calc_Dane'!N10 | H32: ='_calc_Dane'!M11-'_calc_Dane'!M10 | I32: ='_calc_Dane'!N11-'_calc_Dane'!N10 | J32: =F32^2+G32^2 | K32: =H32^2+I32^2 | L32: =IF(ATAN2(F32,G32)*200/PI()<0,ATAN2(F32,G32)*200/PI()+400,ATAN2(F32,G32)*200/PI()) | M32: =IF(ATAN2(H32,I32)*200/PI()<0,ATAN2(H32,I32)*200/PI()+400,ATAN2(H32,I32)*200/PI()) | N32: =IF(M32-L32<0,M32-L32+400,M32-L32) | O32: ='_calc_Dane'!$M$15 | P32: =N32-E32 | Q32: =F32/J32*2000000/PI() | R32: =G32/J32*2000000/PI() | S32: =H32/K32*2000000/PI() | T32: =I32/K32*2000000/PI()
B33: ='_calc_Dane'!B32 | C33: ='_calc_Dane'!C32 | D33: ='_calc_Dane'!D32 | E33: ='_calc_Dane'!E32 | F33: ='_calc_Dane'!M11-'_calc_Dane'!M10 | G33: ='_calc_Dane'!N11-'_calc_Dane'!N10 | H33: ='_calc_Dane'!M13-'_calc_Dane'!M10 | I33: ='_calc_Dane'!N13-'_calc_Dane'!N10 | J33: =F33^2+G33^2 | K33: =H33^2+I33^2 | L33: =IF(ATAN2(F33,G33)*200/PI()<0,ATAN2(F33,G33)*200/PI()+400,ATAN2(F33,G33)*200/PI()) | M33: =IF(ATAN2(H33,I33)*200/PI()<0,ATAN2(H33,I33)*200/PI()+400,ATAN2(H33,I33)*200/PI()) | N33: =IF(M33-L33<0,M33-L33+400,M33-L33) | O33: ='_calc_Dane'!$M$15 | P33: =N33-E33 | Q33: =F33/J33*2000000/PI() | R33: =G33/J33*2000000/PI() | S33: =H33/K33*2000000/PI() | T33: =I33/K33*2000000/PI()
B34: ='_calc_Dane'!B33 | C34: ='_calc_Dane'!C33 | D34: ='_calc_Dane'!D33 | E34: ='_calc_Dane'!E33 | F34: ='_calc_Dane'!M13-'_calc_Dane'!M10 | G34: ='_calc_Dane'!N13-'_calc_Dane'!N10 | H34: ='_calc_Dane'!M9-'_calc_Dane'!M10 | I34: ='_calc_Dane'!N9-'_calc_Dane'!N10 | J34: =F34^2+G34^2 | K34: =H34^2+I34^2 | L34: =IF(ATAN2(F34,G34)*200/PI()<0,ATAN2(F34,G34)*200/PI()+400,ATAN2(F34,G34)*200/PI()) | M34: =IF(ATAN2(H34,I34)*200/PI()<0,ATAN2(H34,I34)*200/PI()+400,ATAN2(H34,I34)*200/PI()) | N34: =IF(M34-L34<0,M34-L34+400,M34-L34) | O34: ='_calc_Dane'!$M$15 | P34: =N34-E34 | Q34: =F34/J34*2000000/PI() | R34: =G34/J34*2000000/PI() | S34: =H34/K34*2000000/PI() | T34: =I34/K34*2000000/PI()
B35: ='_calc_Dane'!B34 | C35: ='_calc_Dane'!C34 | D35: ='_calc_Dane'!D34 | E35: ='_calc_Dane'!E34 | F35: ='_calc_Dane'!M10-'_calc_Dane'!M9 | G35: ='_calc_Dane'!N10-'_calc_Dane'!N9 | H35: ='_calc_Dane'!M11-'_calc_Dane'!M9 | I35: ='_calc_Dane'!N11-'_calc_Dane'!N9 | J35: =F35^2+G35^2 | K35: =H35^2+I35^2 | L35: =IF(ATAN2(F35,G35)*200/PI()<0,ATAN2(F35,G35)*200/PI()+400,ATAN2(F35,G35)*200/PI()) | M35: =IF(ATAN2(H35,I35)*200/PI()<0,ATAN2(H35,I35)*200/PI()+400,ATAN2(H35,I35)*200/PI()) | N35: =IF(M35-L35<0,M35-L35+400,M35-L35) | O35: ='_calc_Dane'!$M$15 | P35: =N35-E35 | Q35: =F35/J35*2000000/PI() | R35: =G35/J35*2000000/PI() | S35: =H35/K35*2000000/PI() | T35: =I35/K35*2000000/PI()
B36: ='_calc_Dane'!B35 | C36: ='_calc_Dane'!C35 | D36: ='_calc_Dane'!D35 | E36: ='_calc_Dane'!E35 | F36: ='_calc_Dane'!M11-'_calc_Dane'!M9 | G36: ='_calc_Dane'!N11-'_calc_Dane'!N9 | H36: ='_calc_Dane'!M13-'_calc_Dane'!M9 | I36: ='_calc_Dane'!N13-'_calc_Dane'!N9 | J36: =F36^2+G36^2 | K36: =H36^2+I36^2 | L36: =IF(ATAN2(F36,G36)*200/PI()<0,ATAN2(F36,G36)*200/PI()+400,ATAN2(F36,G36)*200/PI()) | M36: =IF(ATAN2(H36,I36)*200/PI()<0,ATAN2(H36,I36)*200/PI()+400,ATAN2(H36,I36)*200/PI()) | N36: =IF(M36-L36<0,M36-L36+400,M36-L36) | O36: ='_calc_Dane'!$M$15 | P36: =N36-E36 | Q36: =F36/J36*2000000/PI() | R36: =G36/J36*2000000/PI() | S36: =H36/K36*2000000/PI() | T36: =I36/K36*2000000/PI()
B37: ='_calc_Dane'!B36 | C37: ='_calc_Dane'!C36 | D37: ='_calc_Dane'!D36 | E37: ='_calc_Dane'!E36 | F37: ='_calc_Dane'!M13-'_calc_Dane'!M9 | G37: ='_calc_Dane'!N13-'_calc_Dane'!N9 | H37: ='_calc_Dane'!M8-'_calc_Dane'!M9 | I37: ='_calc_Dane'!N8-'_calc_Dane'!N9 | J37: =F37^2+G37^2 | K37: =H37^2+I37^2 | L37: =IF(ATAN2(F37,G37)*200/PI()<0,ATAN2(F37,G37)*200/PI()+400,ATAN2(F37,G37)*200/PI()) | M37: =IF(ATAN2(H37,I37)*200/PI()<0,ATAN2(H37,I37)*200/PI()+400,ATAN2(H37,I37)*200/PI()) | N37: =IF(M37-L37<0,M37-L37+400,M37-L37) | O37: ='_calc_Dane'!$M$15 | P37: =N37-E37 | Q37: =F37/J37*2000000/PI() | R37: =G37/J37*2000000/PI() | S37: =H37/K37*2000000/PI() | T37: =I37/K37*2000000/PI()
B39: a | S39: l [m/cc]
B40: dx | C40: dy | D40: dx | E40: dy | F40: dx | G40: dy | H40: dx | I40: dy | J40: dx | K40: dy | L40: dx | M40: dy | N40: dx | O40: dy | P40: dx | Q40: dy
B41: 1 | C41: 1 | D41: 3 | E41: 3 | F41: 4 | G41: 4 | H41: 5 | I41: 5 | J41: 6 | K41: 6 | L41: 7 | M41: 7 | N41: 8 | O41: 8 | P41: 9 | Q41: 9
B42: =IF(B$41=$B4,IF(B$40="dx",-$K4,-$J4),IF(B$41=$C4,IF(B$40="dx",$K4,$J4),0)) | C42: =IF(C$41=$B4,IF(C$40="dx",-$K4,-$J4),IF(C$41=$C4,IF(C$40="dx",$K4,$J4),0)) | D42: =IF(D$41=$B4,IF(D$40="dx",-$K4,-$J4),IF(D$41=$C4,IF(D$40="dx",$K4,$J4),0)) | E42: =IF(E$41=$B4,IF(E$40="dx",-$K4,-$J4),IF(E$41=$C4,IF(E$40="dx",$K4,$J4),0)) | F42: =IF(F$41=$B4,IF(F$40="dx",-$K4,-$J4),IF(F$41=$C4,IF(F$40="dx",$K4,$J4),0)) | G42: =IF(G$41=$B4,IF(G$40="dx",-$K4,-$J4),IF(G$41=$C4,IF(G$40="dx",$K4,$J4),0)) | H42: =IF(H$41=$B4,IF(H$40="dx",-$K4,-$J4),IF(H$41=$C4,IF(H$40="dx",$K4,$J4),0)) | I42: =IF(I$41=$B4,IF(I$40="dx",-$K4,-$J4),IF(I$41=$C4,IF(I$40="dx",$K4,$J4),0)) | ... Q42: =IF(Q$41=$B4,IF(Q$40="dx",-$K4,-$J4),IF(Q$41=$C4,IF(Q$40="dx",$K4,$J4),0)) | S42: =M4
B43: =IF(B$41=$B5,IF(B$40="dx",-$K5,-$J5),IF(B$41=$C5,IF(B$40="dx",$K5,$J5),0)) | C43: =IF(C$41=$B5,IF(C$40="dx",-$K5,-$J5),IF(C$41=$C5,IF(C$40="dx",$K5,$J5),0)) | D43: =IF(D$41=$B5,IF(D$40="dx",-$K5,-$J5),IF(D$41=$C5,IF(D$40="dx",$K5,$J5),0)) | E43: =IF(E$41=$B5,IF(E$40="dx",-$K5,-$J5),IF(E$41=$C5,IF(E$40="dx",$K5,$J5),0)) | F43: =IF(F$41=$B5,IF(F$40="dx",-$K5,-$J5),IF(F$41=$C5,IF(F$40="dx",$K5,$J5),0)) | G43: =IF(G$41=$B5,IF(G$40="dx",-$K5,-$J5),IF(G$41=$C5,IF(G$40="dx",$K5,$J5),0)) | H43: =IF(H$41=$B5,IF(H$40="dx",-$K5,-$J5),IF(H$41=$C5,IF(H$40="dx",$K5,$J5),0)) | I43: =IF(I$41=$B5,IF(I$40="dx",-$K5,-$J5),IF(I$41=$C5,IF(I$40="dx",$K5,$J5),0)) | ... Q43: =IF(Q$41=$B5,IF(Q$40="dx",-$K5,-$J5),IF(Q$41=$C5,IF(Q$40="dx",$K5,$J5),0)) | S43: =M5
B44: =IF(B$41=$B6,IF(B$40="dx",-$K6,-$J6),IF(B$41=$C6,IF(B$40="dx",$K6,$J6),0)) | C44: =IF(C$41=$B6,IF(C$40="dx",-$K6,-$J6),IF(C$41=$C6,IF(C$40="dx",$K6,$J6),0)) | D44: =IF(D$41=$B6,IF(D$40="dx",-$K6,-$J6),IF(D$41=$C6,IF(D$40="dx",$K6,$J6),0)) | E44: =IF(E$41=$B6,IF(E$40="dx",-$K6,-$J6),IF(E$41=$C6,IF(E$40="dx",$K6,$J6),0)) | F44: =IF(F$41=$B6,IF(F$40="dx",-$K6,-$J6),IF(F$41=$C6,IF(F$40="dx",$K6,$J6),0)) | G44: =IF(G$41=$B6,IF(G$40="dx",-$K6,-$J6),IF(G$41=$C6,IF(G$40="dx",$K6,$J6),0)) | H44: =IF(H$41=$B6,IF(H$40="dx",-$K6,-$J6),IF(H$41=$C6,IF(H$40="dx",$K6,$J6),0)) | I44: =IF(I$41=$B6,IF(I$40="dx",-$K6,-$J6),IF(I$41=$C6,IF(I$40="dx",$K6,$J6),0)) | ... Q44: =IF(Q$41=$B6,IF(Q$40="dx",-$K6,-$J6),IF(Q$41=$C6,IF(Q$40="dx",$K6,$J6),0)) | S44: =M6
...

Sheet Wyrównanie wstępne - aktualny
B3: c | C3: l | D3: p | E3: L obs [m] | F3: ∆x | G3: ∆y | H3: L przyb [m] | I3: Az [g] | J3: Sin Az | K3: Cos Az | L3: Błąd [m] | M3: l [m] | P3: Współrzedne przybliżone
B4: ='_calc_Dane'!F5 | C4: ='_calc_Dane'!G5 | D4: ='_calc_Dane'!H5 | E4: ='_calc_Dane'!I5 | F4: ='_calc_Dane'!M5-'_calc_Dane'!M11 | G4: ='_calc_Dane'!N5-'_calc_Dane'!N11 | H4: =SQRT(F4^2+G4^2) | I4: =IF(ATAN2(F4,G4)*200/PI()<0,ATAN2(F4,G4)*200/PI()+400) | J4: =SIN(I4*PI()/200) | K4: =COS(I4*PI()/200) | L4: =0.001+0.000001*E4 | M4: =H4-E4 | P4: NR | Q4: Xo | R4: Yo
B5: ='_calc_Dane'!F6 | C5: ='_calc_Dane'!G6 | D5: ='_calc_Dane'!H6 | E5: ='_calc_Dane'!I6 | F5: ='_calc_Dane'!M9-'_calc_Dane'!M11 | G5: ='_calc_Dane'!N9-'_calc_Dane'!N11 | H5: =SQRT(F5^2+G5^2) | I5: =IF(ATAN2(F5,G5)*200/PI()<0,ATAN2(F5,G5)*200/PI()+400,ATAN2(F5,G5)*200/PI()) | J5: =SIN(I5*PI()/200) | K5: =COS(I5*PI()/200) | L5: =0.001+0.000001*E5 | M5: =H5-E5 | P5: 1 | Q5: 240 | R5: 120
B6: ='_calc_Dane'!F7 | C6: ='_calc_Dane'!G7 | D6: ='_calc_Dane'!H7 | E6: ='_calc_Dane'!I7 | F6: ='_calc_Dane'!M10-'_calc_Dane'!M11 | G6: ='_calc_Dane'!N10-'_calc_Dane'!N11 | H6: =SQRT(F6^2+G6^2) | I6: =IF(ATAN2(F6,G6)*200/PI()<0,ATAN2(F6,G6)*200/PI()+400,ATAN2(F6,G6)*200/PI()) | J6: =SIN(I6*PI()/200) | K6: =COS(I6*PI()/200) | L6: =0.001+0.000001*E6 | M6: =H6-E6 | P6: 2 | Q6: 385 | R6: 145
B7: ='_calc_Dane'!F8 | C7: ='_calc_Dane'!G8 | D7: ='_calc_Dane'!H8 | E7: ='_calc_Dane'!I8 | F7: ='_calc_Dane'!M12-'_calc_Dane'!M11 | G7: ='_calc_Dane'!N12-'_calc_Dane'!N11 | H7: =SQRT(F7^2+G7^2) | I7: =IF(ATAN2(F7,G7)*200/PI()<0,ATAN2(F7,G7)*200/PI()+400) | J7: =SIN(I7*PI()/200) | K7: =COS(I7*PI()/200) | L7: =0.001+0.000001*E7 | M7: =H7-E7 | P7: 3 | Q7: 475 | R7: 245
B8: ='_calc_Dane'!F9 | C8: ='_calc_Dane'!G9 | D8: ='_calc_Dane'!H9 | E8: ='_calc_Dane'!I9 | F8: ='_calc_Dane'!M13-'_calc_Dane'!M11 | G8: ='_calc_Dane'!N13-'_calc_Dane'!N11 | H8: =SQRT(F8^2+G8^2) | I8: =IF(ATAN2(F8,G8)*200/PI()<0,ATAN2(F8,G8)*200/PI()+400) | J8: =SIN(I8*PI()/200) | K8: =COS(I8*PI()/200) | L8: =0.001+0.000001*E8 | M8: =H8-E8 | P8: 4 | Q8: 435 | R8: 435
B9: ='_calc_Dane'!F10 | C9: ='_calc_Dane'!G10 | D9: ='_calc_Dane'!H10 | E9: ='_calc_Dane'!I10 | F9: ='_calc_Dane'!M5-'_calc_Dane'!M12 | G9: ='_calc_Dane'!N5-'_calc_Dane'!N12 | H9: =SQRT(F9^2+G9^2) | I9: =IF(ATAN2(F9,G9)*200/PI()<0,ATAN2(F9,G9)*200/PI()+400) | J9: =SIN(I9*PI()/200) | K9: =COS(I9*PI()/200) | L9: =0.001+0.000001*E9 | M9: =H9-E9 | P9: 5 | Q9: 295 | R9: 490
B10: ='_calc_Dane'!F11 | C10: ='_calc_Dane'!G11 | D10: ='_calc_Dane'!H11 | E10: ='_calc_Dane'!I11 | F10: ='_calc_Dane'!M13-'_calc_Dane'!M12 | G10: ='_calc_Dane'!N13-'_calc_Dane'!N12 | H10: =SQRT(F10^2+G10^2) | I10: =IF(ATAN2(F10,G10)*200/PI()<0,ATAN2(F10,G10)*200/PI()+400,ATAN2(F10,G10)*200/PI()) | J10: =SIN(I10*PI()/200) | K10: =COS(I10*PI()/200) | L10: =0.001+0.000001*E10 | M10: =H10-E10 | P10: 6 | Q10: 145 | R10: 560
B11: ='_calc_Dane'!F12 | C11: ='_calc_Dane'!G12 | D11: ='_calc_Dane'!H12 | E11: ='_calc_Dane'!I12 | F11: ='_calc_Dane'!M11-'_calc_Dane'!M12 | G11: ='_calc_Dane'!N11-'_calc_Dane'!N12 | H11: =SQRT(F11^2+G11^2) | I11: =IF(ATAN2(F11,G11)*200/PI()<0,ATAN2(F11,G11)*200/PI()+400,ATAN2(F11,G11)*200/PI()) | J11: =SIN(I11*PI()/200) | K11: =COS(I11*PI()/200) | L11: =0.001+0.000001*E11 | M11: =H11-E11 | P11: 7 | Q11: 180 | R11: 385
B12: ='_calc_Dane'!F13 | C12: ='_calc_Dane'!G13 | D12: ='_calc_Dane'!H13 | E12: ='_calc_Dane'!I13 | F12: ='_calc_Dane'!M10-'_calc_Dane'!M12 | G12: ='_calc_Dane'!N10-'_calc_Dane'!N12 | H12: =SQRT(F12^2+G12^2) | I12: =IF(ATAN2(F12,G12)*200/PI()<0,ATAN2(F12,G12)*200/PI()+400,ATAN2(F12,G12)*200/PI()) | J12: =SIN(I12*PI()/200) | K12: =COS(I12*PI()/200) | L12: =0.001+0.000001*E12 | M12: =H12-E12 | P12: 8 | Q12: 150 | R12: 240
B13: ='_calc_Dane'!F14 | C13: ='_calc_Dane'!G14 | D13: ='_calc_Dane'!H14 | E13: ='_calc_Dane'!I14 | F13: ='_calc_Dane'!M6-'_calc_Dane'!M5 | G13: ='_calc_Dane'!N6-'_calc_Dane'!N5 | H13: =SQRT(F13^2+G13^2) | I13: =IF(ATAN2(F13,G13)*200/PI()<0,ATAN2(F13,G13)*200/PI()+400,ATAN2(F13,G13)*200/PI()) | J13: =SIN(I13*PI()/200) | K13: =COS(I13*PI()/200) | L13: =0.001+0.000001*E13 | M13: =H13-E13 | P13: 9 | Q13: 314 | R13: 271
B14: ='_calc_Dane'!F15 | C14: ='_calc_Dane'!G15 | D14: ='_calc_Dane'!H15 | E14: ='_calc_Dane'!I15 | F14: ='_calc_Dane'!M13-'_calc_Dane'!M5 | G14: ='_calc_Dane'!N13-'_calc_Dane'!N5 | H14: =SQRT(F14^2+G14^2) | I14: =IF(ATAN2(F14,G14)*200/PI()<0,ATAN2(F14,G14)*200/PI()+400,ATAN2(F14,G14)*200/PI()) | J14: =SIN(I14*PI()/200) | K14: =COS(I14*PI()/200) | L14: =0.001+0.000001*E14 | M14: =H14-E14
B15: ='_calc_Dane'!F16 | C15: ='_calc_Dane'!G16 | D15: ='_calc_Dane'!H16 | E15: ='_calc_Dane'!I16 | F15: ='_calc_Dane'!M11-'_calc_Dane'!M5 | G15: ='_calc_Dane'!N11-'_calc_Dane'!N5 | H15: =SQRT(F15^2+G15^2) | I15: =IF(ATAN2(F15,G15)*200/PI()<0,ATAN2(F15,G15)*200/PI()+400,ATAN2(F15,G15)*200/PI()) | J15: =SIN(I15*PI()/200) | K15: =COS(I15*PI()/200) | L15: =0.001+0.000001*E15 | M15: =H15-E15
B16: ='_calc_Dane'!F17 | C16: ='_calc_Dane'!G17 | D16: ='_calc_Dane'!H17 | E16: ='_calc_Dane'!I17 | F16: ='_calc_Dane'!M12-'_calc_Dane'!M6 | G16: ='_calc_Dane'!N12-'_calc_Dane'!N6 | H16: =SQRT(F16^2+G16^2) | I16: =IF(ATAN2(F16,G16)*200/PI()<0,ATAN2(F16,G16)*200/PI()+400,ATAN2(F16,G16)*200/PI()) | J16: =SIN(I16*PI()/200) | K16: =COS(I16*PI()/200) | L16: =0.001+0.000001*E16 | M16: =H16-E16
B17: ='_calc_Dane'!F18 | C17: ='_calc_Dane'!G18 | D17: ='_calc_Dane'!H18 | E17: ='_calc_Dane'!I18 | F17: ='_calc_Dane'!M13-'_calc_Dane'!M6 | G17: ='_calc_Dane'!N13-'_calc_Dane'!N6 | H17: =SQRT(F17^2+G17^2) | I17: =IF(ATAN2(F17,G17)*200/PI()<0,ATAN2(F17,G17)*200/PI()+400,ATAN2(F17,G17)*200/PI()) | J17: =SIN(I17*PI()/200) | K17: =COS(I17*PI()/200) | L17: =0.001+0.000001*E17 | M17: =H17-E17
B18: ='_calc_Dane'!F19 | C18: ='_calc_Dane'!G19 | D18: ='_calc_Dane'!H19 | E18: ='_calc_Dane'!I19 | F18: ='_calc_Dane'!M8-'_calc_Dane'!M6 | G18: ='_calc_Dane'!N8-'_calc_Dane'!N6 | H18: =SQRT(F18^2+G18^2) | I18: =IF(ATAN2(F18,G18)*200/PI()<0,ATAN2(F18,G18)*200/PI()+400,ATAN2(F18,G18)*200/PI()) | J18: =SIN(I18*PI()/200) | K18: =COS(I18*PI()/200) | L18: =0.001+0.000001*E18 | M18: =H18-E18
B19: ='_calc_Dane'!F20 | C19: ='_calc_Dane'!G20 | D19: ='_calc_Dane'!H20 | E19: ='_calc_Dane'!I20 | F19: ='_calc_Dane'!M9-'_calc_Dane'!M8 | G19: ='_calc_Dane'!N9-'_calc_Dane'!N8 | H19: =SQRT(F19^2+G19^2) | I19: =IF(ATAN2(F19,G19)*200/PI()<0,ATAN2(F19,G19)*200/PI()+400,ATAN2(F19,G19)*200/PI()) | J19: =SIN(I19*PI()/200) | K19: =COS(I19*PI()/200) | L19: =0.001+0.000001*E19 | M19: =H19-E19
B20: ='_calc_Dane'!F21 | C20: ='_calc_Dane'!G21 | D20: ='_calc_Dane'!H21 | E20: ='_calc_Dane'!I21 | F20: ='_calc_Dane'!M11-'_calc_Dane'!M8 | G20: ='_calc_Dane'!N11-'_calc_Dane'!N8 | H20: =SQRT(F20^2+G20^2) | I20: =IF(ATAN2(F20,G20)*200/PI()<0,ATAN2(F20,G20)*200/PI()+400) | J20: =SIN(I20*PI()/200) | K20: =COS(I20*PI()/200) | L20: =0.001+0.000001*E20 | M20: =H20-E20
B21: ='_calc_Dane'!F22 | C21: ='_calc_Dane'!G22 | D21: ='_calc_Dane'!H22 | E21: ='_calc_Dane'!I22 | F21: ='_calc_Dane'!M13-'_calc_Dane'!M8 | G21: ='_calc_Dane'!N13-'_calc_Dane'!N8 | H21: =SQRT(F21^2+G21^2) | I21: =IF(ATAN2(F21,G21)*200/PI()<0,ATAN2(F21,G21)*200/PI()+400) | J21: =SIN(I21*PI()/200) | K21: =COS(I21*PI()/200) | L21: =0.001+0.000001*E21 | M21: =H21-E21
B22: ='_calc_Dane'!F23 | C22: ='_calc_Dane'!G23 | D22: ='_calc_Dane'!H23 | E22: ='_calc_Dane'!I23 | F22: ='_calc_Dane'!M13-'_calc_Dane'!M10 | G22: ='_calc_Dane'!N13-'_calc_Dane'!N10 | H22: =SQRT(F22^2+G22^2) | I22: =IF(ATAN2(F22,G22)*200/PI()<0,ATAN2(F22,G22)*200/PI()+400) | J22: =SIN(I22*PI()/200) | K22: =COS(I22*PI()/200) | L22: =0.001+0.000001*E22 | M22: =H22-E22
B23: ='_calc_Dane'!F24 | C23: ='_calc_Dane'!G24 | D23: ='_calc_Dane'!H24 | E23: ='_calc_Dane'!I24 | F23: ='_calc_Dane'!M9-'_calc_Dane'!M10 | G23: ='_calc_Dane'!N9-'_calc_Dane'!N10 | H23: =SQRT(F23^2+G23^2) | I23: =IF(ATAN2(F23,G23)*200/PI()<0,ATAN2(F23,G23)*200/PI()+400) | J23: =SIN(I23*PI()/200) | K23: =COS(I23*PI()/200) | L23: =0.001+0.000001*E23 | M23: =H23-E23
B25: c | C25: l | D25: p | E25: b obs [g] | F25: ∆xcl | G25: ∆ycl | H25: ∆xcp | I25: ∆ycp | J25: d²cl | K25: d²cp | L25: Az cl [g] | M25: Az cp [g] | N25: b przyb [g] | O25: Błąd [cc] | P25: l [g] | Q25: Acl. | R25: Bcl | S25: Acp | T25: Bcp
B26: ='_calc_Dane'!F25 | C26: ='_calc_Dane'!G25 | D26: ='_calc_Dane'!H25 | E26: ='_calc_Dane'!I25 | F26: ='_calc_Dane'!M5-'_calc_Dane'!M13 | G26: ='_calc_Dane'!N5-'_calc_Dane'!N13 | H26: ='_calc_Dane'!M6-'_calc_Dane'!M13 | I26: ='_calc_Dane'!N6-'_calc_Dane'!N13 | J26: =F26^2+G26^2 | K26: =H26^2+I26^2 | L26: =IF(ATAN2(F26,G26)*200/PI()<0,ATAN2(F26,G26)*200/PI()+400,ATAN2(F26,G26)*200/PI()) | M26: =IF(ATAN2(H26,I26)*200/PI()<0,ATAN2(H26,I26)*200/PI()+400,ATAN2(H26,I26)*200/PI()) | N26: =IF(M26-L26<0,M26-L26+400,M26-L26) | O26: ='_calc_Dane'!$M$15 | P26: =N26-E26 | Q26: =F26/J26*(2000000/PI()) | R26: =G26/J26*2000000/PI() | S26: =H26/K26*2000000/PI() | T26: =I26/K26*2000000/PI()
B27: ='_calc_Dane'!F26 | C27: ='_calc_Dane'!G26 | D27: ='_calc_Dane'!H26 | E27: ='_calc_Dane'!I26 | F27: ='_calc_Dane'!M6-'_calc_Dane'!M13 | G27: ='_calc_Dane'!N6-'_calc_Dane'!N13 | H27: ='_calc_Dane'!M8-'_calc_Dane'!M13 | I27: ='_calc_Dane'!N8-'_calc_Dane'!N13 | J27: =F27^2+G27^2 | K27: =H27^2+I27^2 | L27: =IF(ATAN2(F27,G27)*200/PI()<0,ATAN2(F27,G27)*200/PI()+400,ATAN2(F27,G27)*200/PI()) | M27: =IF(ATAN2(H27,I27)*200/PI()<0,ATAN2(H27,I27)*200/PI()+400,ATAN2(H27,I27)*200/PI()) | N27: =IF(M27-L27<0,M27-L27+400,M27-L27) | O27: ='_calc_Dane'!$M$15 | P27: =N27-E27 | Q27: =F27/J27*(2000000/PI()) | R27: =G27/J27*2000000/PI() | S27: =H27/K27*2000000/PI() | T27: =I27/K27*2000000/PI()
B28: ='_calc_Dane'!F27 | C28: ='_calc_Dane'!G27 | D28: ='_calc_Dane'!H27 | E28: ='_calc_Dane'!I27 | F28: ='_calc_Dane'!M8-'_calc_Dane'!M13 | G28: ='_calc_Dane'!N8-'_calc_Dane'!N13 | H28: ='_calc_Dane'!M9-'_calc_Dane'!M13 | I28: ='_calc_Dane'!N9-'_calc_Dane'!N13 | J28: =F28^2+G28^2 | K28: =H28^2+I28^2 | L28: =IF(ATAN2(F28,G28)*200/PI()<0,ATAN2(F28,G28)*200/PI()+400,ATAN2(F28,G28)*200/PI()) | M28: =IF(ATAN2(H28,I28)*200/PI()<0,ATAN2(H28,I28)*200/PI()+400,ATAN2(H28,I28)*200/PI()) | N28: =IF(M28-L28<0,M28-L28+400,M28-L28) | O28: ='_calc_Dane'!$M$15 | P28: =N28-E28 | Q28: =F28/J28*(2000000/PI()) | R28: =G28/J28*2000000/PI() | S28: =H28/K28*2000000/PI() | T28: =I28/K28*2000000/PI()
B29: ='_calc_Dane'!F28 | C29: ='_calc_Dane'!G28 | D29: ='_calc_Dane'!H28 | E29: ='_calc_Dane'!I28 | F29: ='_calc_Dane'!M9-'_calc_Dane'!M13 | G29: ='_calc_Dane'!N9-'_calc_Dane'!N13 | H29: ='_calc_Dane'!M11-'_calc_Dane'!M13 | I29: ='_calc_Dane'!N11-'_calc_Dane'!N13 | J29: =F29^2+G29^2 | K29: =H29^2+I29^2 | L29: =IF(ATAN2(F29,G29)*200/PI()<0,ATAN2(F29,G29)*200/PI()+400,ATAN2(F29,G29)*200/PI()) | M29: =IF(ATAN2(H29,I29)*200/PI()<0,ATAN2(H29,I29)*200/PI()+400,ATAN2(H29,I29)*200/PI()) | N29: =IF(M29-L29<0,M29-L29+400,M29-L29) | O29: ='_calc_Dane'!$M$15 | P29: =N29-E29 | Q29: =F29/J29*(2000000/PI()) | R29: =G29/J29*2000000/PI() | S29: =H29/K29*2000000/PI() | T29: =I29/K29*2000000/PI()
B30: ='_calc_Dane'!F29 | C30: ='_calc_Dane'!G29 | D30: ='_calc_Dane'!H29 | E30: ='_calc_Dane'!I29 | F30: ='_calc_Dane'!M11-'_calc_Dane'!M13 | G30: ='_calc_Dane'!N11-'_calc_Dane'!N13 | H30: ='_calc_Dane'!M12-'_calc_Dane'!M13 | I30: ='_calc_Dane'!N12-'_calc_Dane'!N13 | J30: =F30^2+G30^2 | K30: =H30^2+I30^2 | L30: =IF(ATAN2(F30,G30)*200/PI()<0,ATAN2(F30,G30)*200/PI()+400,ATAN2(F30,G30)*200/PI()) | M30: =IF(ATAN2(H30,I30)*200/PI()<0,ATAN2(H30,I30)*200/PI()+400,ATAN2(H30,I30)*200/PI()) | N30: =IF(M30-L30<0,M30-L30+400,M30-L30) | O30: ='_calc_Dane'!$M$15 | P30: =N30-E30 | Q30: =F30/J30*(2000000/PI()) | R30: =G30/J30*2000000/PI() | S30: =H30/K30*2000000/PI() | T30: =I30/K30*2000000/PI()
B31: ='_calc_Dane'!F30 | C31: ='_calc_Dane'!G30 | D31: ='_calc_Dane'!H30 | E31: ='_calc_Dane'!I30 | F31: ='_calc_Dane'!M12-'_calc_Dane'!M13 | G31: ='_calc_Dane'!N12-'_calc_Dane'!N13 | H31: ='_calc_Dane'!M5-'_calc_Dane'!M13 | I31: ='_calc_Dane'!N5-'_calc_Dane'!N13 | J31: =F31^2+G31^2 | K31: =H31^2+I31^2 | L31: =IF(ATAN2(F31,G31)*200/PI()<0,ATAN2(F31,G31)*200/PI()+400,ATAN2(F31,G31)*200/PI()) | M31: =IF(ATAN2(H31,I31)*200/PI()<0,ATAN2(H31,I31)*200/PI()+400,ATAN2(H31,I31)*200/PI()) | N31: =IF(M31-L31<0,M31-L31+400,M31-L31) | O31: ='_calc_Dane'!$M$15 | P31: =N31-E31 | Q31: =F31/J31*(2000000/PI()) | R31: =G31/J31*2000000/PI() | S31: =H31/K31*2000000/PI() | T31: =I31/K31*2000000/PI()
B32: ='_calc_Dane'!F31 | C32: ='_calc_Dane'!G31 | D32: ='_calc_Dane'!H31 | E32: ='_calc_Dane'!I31 | F32: ='_calc_Dane'!M12-'_calc_Dane'!M10 | G32: ='_calc_Dane'!N12-'_calc_Dane'!N10 | H32: ='_calc_Dane'!M11-'_calc_Dane'!M10 | I32: ='_calc_Dane'!N11-'_calc_Dane'!N10 | J32: =F32^2+G32^2 | K32: =H32^2+I32^2 | L32: =IF(ATAN2(F32,G32)*200/PI()<0,ATAN2(F32,G32)*200/PI()+400,ATAN2(F32,G32)*200/PI()) | M32: =IF(ATAN2(H32,I32)*200/PI()<0,ATAN2(H32,I32)*200/PI()+400,ATAN2(H32,I32)*200/PI()) | N32: =IF(M32-L32<0,M32-L32+400,M32-L32) | O32: ='_calc_Dane'!$M$15 | P32: =N32-E32 | Q32: =F32/J32*(2000000/PI()) | R32: =G32/J32*2000000/PI() | S32: =H32/K32*2000000/PI() | T32: =I32/K32*2000000/PI()
B33: ='_calc_Dane'!F32 | C33: ='_calc_Dane'!G32 | D33: ='_calc_Dane'!H32 | E33: ='_calc_Dane'!I32 | F33: ='_calc_Dane'!M11-'_calc_Dane'!M10 | G33: ='_calc_Dane'!N11-'_calc_Dane'!N10 | H33: ='_calc_Dane'!M13-'_calc_Dane'!M10 | I33: ='_calc_Dane'!N13-'_calc_Dane'!N10 | J33: =F33^2+G33^2 | K33: =H33^2+I33^2 | L33: =IF(ATAN2(F33,G33)*200/PI()<0,ATAN2(F33,G33)*200/PI()+400,ATAN2(F33,G33)*200/PI()) | M33: =IF(ATAN2(H33,I33)*200/PI()<0,ATAN2(H33,I33)*200/PI()+400,ATAN2(H33,I33)*200/PI()) | N33: =IF(M33-L33<0,M33-L33+400,M33-L33) | O33: ='_calc_Dane'!$M$15 | P33: =N33-E33 | Q33: =F33/J33*(2000000/PI()) | R33: =G33/J33*2000000/PI() | S33: =H33/K33*2000000/PI() | T33: =I33/K33*2000000/PI()
B34: ='_calc_Dane'!F33 | C34: ='_calc_Dane'!G33 | D34: ='_calc_Dane'!H33 | E34: ='_calc_Dane'!I33 | F34: ='_calc_Dane'!M13-'_calc_Dane'!M10 | G34: ='_calc_Dane'!N13-'_calc_Dane'!N10 | H34: ='_calc_Dane'!M9-'_calc_Dane'!M10 | I34: ='_calc_Dane'!N9-'_calc_Dane'!N10 | J34: =F34^2+G34^2 | K34: =H34^2+I34^2 | L34: =IF(ATAN2(F34,G34)*200/PI()<0,ATAN2(F34,G34)*200/PI()+400,ATAN2(F34,G34)*200/PI()) | M34: =IF(ATAN2(H34,I34)*200/PI()<0,ATAN2(H34,I34)*200/PI()+400,ATAN2(H34,I34)*200/PI()) | N34: =IF(M34-L34<0,M34-L34+400,M34-L34) | O34: ='_calc_Dane'!$M$15 | P34: =N34-E34 | Q34: =F34/J34*(2000000/PI()) | R34: =G34/J34*2000000/PI() | S34: =H34/K34*2000000/PI() | T34: =I34/K34*2000000/PI()
B35: ='_calc_Dane'!F34 | C35: ='_calc_Dane'!G34 | D35: ='_calc_Dane'!H34 | E35: ='_calc_Dane'!I34 | F35: ='_calc_Dane'!M10-'_calc_Dane'!M9 | G35: ='_calc_Dane'!N10-'_calc_Dane'!N9 | H35: ='_calc_Dane'!M11-'_calc_Dane'!M9 | I35: ='_calc_Dane'!N11-'_calc_Dane'!N9 | J35: =F35^2+G35^2 | K35: =H35^2+I35^2 | L35: =IF(ATAN2(F35,G35)*200/PI()<0,ATAN2(F35,G35)*200/PI()+400,ATAN2(F35,G35)*200/PI()) | M35: =IF(ATAN2(H35,I35)*200/PI()<0,ATAN2(H35,I35)*200/PI()+400,ATAN2(H35,I35)*200/PI()) | N35: =IF(M35-L35<0,M35-L35+400,M35-L35) | O35: ='_calc_Dane'!$M$15 | P35: =N35-E35 | Q35: =F35/J35*(2000000/PI()) | R35: =G35/J35*2000000/PI() | S35: =H35/K35*2000000/PI() | T35: =I35/K35*2000000/PI()
B36: ='_calc_Dane'!F35 | C36: ='_calc_Dane'!G35 | D36: ='_calc_Dane'!H35 | E36: ='_calc_Dane'!I35 | F36: ='_calc_Dane'!M11-'_calc_Dane'!M9 | G36: ='_calc_Dane'!N11-'_calc_Dane'!N9 | H36: ='_calc_Dane'!M13-'_calc_Dane'!M9 | I36: ='_calc_Dane'!N13-'_calc_Dane'!N9 | J36: =F36^2+G36^2 | K36: =H36^2+I36^2 | L36: =IF(ATAN2(F36,G36)*200/PI()<0,ATAN2(F36,G36)*200/PI()+400,ATAN2(F36,G36)*200/PI()) | M36: =IF(ATAN2(H36,I36)*200/PI()<0,ATAN2(H36,I36)*200/PI()+400,ATAN2(H36,I36)*200/PI()) | N36: =IF(M36-L36<0,M36-L36+400,M36-L36) | O36: ='_calc_Dane'!$M$15 | P36: =N36-E36 | Q36: =F36/J36*(2000000/PI()) | R36: =G36/J36*2000000/PI() | S36: =H36/K36*2000000/PI() | T36: =I36/K36*2000000/PI()
B37: ='_calc_Dane'!F36 | C37: ='_calc_Dane'!G36 | D37: ='_calc_Dane'!H36 | E37: ='_calc_Dane'!I36 | F37: ='_calc_Dane'!M13-'_calc_Dane'!M9 | G37: ='_calc_Dane'!N13-'_calc_Dane'!N9 | H37: ='_calc_Dane'!M8-'_calc_Dane'!M9 | I37: ='_calc_Dane'!N8-'_calc_Dane'!N9 | J37: =F37^2+G37^2 | K37: =H37^2+I37^2 | L37: =IF(ATAN2(F37,G37)*200/PI()<0,ATAN2(F37,G37)*200/PI()+400,ATAN2(F37,G37)*200/PI()) | M37: =IF(ATAN2(H37,I37)*200/PI()<0,ATAN2(H37,I37)*200/PI()+400,ATAN2(H37,I37)*200/PI()) | N37: =IF(M37-L37<0,M37-L37+400,M37-L37) | O37: ='_calc_Dane'!$M$15 | P37: =N37-E37 | Q37: =F37/J37*(2000000/PI()) | R37: =G37/J37*2000000/PI() | S37: =H37/K37*2000000/PI() | T37: =I37/K37*2000000/PI()
B39: a | S39: l [m/cc]
B40: dx | C40: dy | D40: dx | E40: dy | F40: dx | G40: dy | H40: dx | I40: dy | J40: dx | K40: dy | L40: dx | M40: dy | N40: dx | O40: dy | P40: dx | Q40: dy
B41: 1 | C41: 1 | D41: 2 | E41: 2 | F41: 4 | G41: 4 | H41: 5 | I41: 5 | J41: 6 | K41: 6 | L41: 7 | M41: 7 | N41: 8 | O41: 8 | P41: 9 | Q41: 9
B42: =IF(B$41=$B4,IF(B$40="dx",-$K4,-$J4),IF(B$41=$C4,IF(B$40="dx",$K4,$J4),0)) | C42: =IF(C$41=$B4,IF(C$40="dx",-$K4,-$J4),IF(C$41=$C4,IF(C$40="dx",$K4,$J4),0)) | D42: =IF(D$41=$B4,IF(D$40="dx",-$K4,-$J4),IF(D$41=$C4,IF(D$40="dx",$K4,$J4),0)) | E42: =IF(E$41=$B4,IF(E$40="dx",-$K4,-$J4),IF(E$41=$C4,IF(E$40="dx",$K4,$J4),0)) | F42: =IF(F$41=$B4,IF(F$40="dx",-$K4,-$J4),IF(F$41=$C4,IF(F$40="dx",$K4,$J4),0)) | G42: =IF(G$41=$B4,IF(G$40="dx",-$K4,-$J4),IF(G$41=$C4,IF(G$40="dx",$K4,$J4),0)) | H42: =IF(H$41=$B4,IF(H$40="dx",-$K4,-$J4),IF(H$41=$C4,IF(H$40="dx",$K4,$J4),0)) | I42: =IF(I$41=$B4,IF(I$40="dx",-$K4,-$J4),IF(I$41=$C4,IF(I$40="dx",$K4,$J4),0)) | ... Q42: =IF(Q$41=$B4,IF(Q$40="dx",-$K4,-$J4),IF(Q$41=$C4,IF(Q$40="dx",$K4,$J4),0)) | S42: =M4
B43: =IF(B$41=$B5,IF(B$40="dx",-$K5,-$J5),IF(B$41=$C5,IF(B$40="dx",$K5,$J5),0)) | C43: =IF(C$41=$B5,IF(C$40="dx",-$K5,-$J5),IF(C$41=$C5,IF(C$40="dx",$K5,$J5),0)) | D43: =IF(D$41=$B5,IF(D$40="dx",-$K5,-$J5),IF(D$41=$C5,IF(D$40="dx",$K5,$J5),0)) | E43: =IF(E$41=$B5,IF(E$40="dx",-$K5,-$J5),IF(E$41=$C5,IF(E$40="dx",$K5,$J5),0)) | F43: =IF(F$41=$B5,IF(F$40="dx",-$K5,-$J5),IF(F$41=$C5,IF(F$40="dx",$K5,$J5),0)) | G43: =IF(G$41=$B5,IF(G$40="dx",-$K5,-$J5),IF(G$41=$C5,IF(G$40="dx",$K5,$J5),0)) | H43: =IF(H$41=$B5,IF(H$40="dx",-$K5,-$J5),IF(H$41=$C5,IF(H$40="dx",$K5,$J5),0)) | I43: =IF(I$41=$B5,IF(I$40="dx",-$K5,-$J5),IF(I$41=$C5,IF(I$40="dx",$K5,$J5),0)) | ... Q43: =IF(Q$41=$B5,IF(Q$40="dx",-$K5,-$J5),IF(Q$41=$C5,IF(Q$40="dx",$K5,$J5),0)) | S43: =M5
B44: =IF(B$41=$B6,IF(B$40="dx",-$K6,-$J6),IF(B$41=$C6,IF(B$40="dx",$K6,$J6),0)) | C44: =IF(C$41=$B6,IF(C$40="dx",-$K6,-$J6),IF(C$41=$C6,IF(C$40="dx",$K6,$J6),0)) | D44: =IF(D$41=$B6,IF(D$40="dx",-$K6,-$J6),IF(D$41=$C6,IF(D$40="dx",$K6,$J6),0)) | E44: =IF(E$41=$B6,IF(E$40="dx",-$K6,-$J6),IF(E$41=$C6,IF(E$40="dx",$K6,$J6),0)) | F44: =IF(F$41=$B6,IF(F$40="dx",-$K6,-$J6),IF(F$41=$C6,IF(F$40="dx",$K6,$J6),0)) | G44: =IF(G$41=$B6,IF(G$40="dx",-$K6,-$J6),IF(G$41=$C6,IF(G$40="dx",$K6,$J6),0)) | H44: =IF(H$41=$B6,IF(H$40="dx",-$K6,-$J6),IF(H$41=$C6,IF(H$40="dx",$K6,$J6),0)) | I44: =IF(I$41=$B6,IF(I$40="dx",-$K6,-$J6),IF(I$41=$C6,IF(I$40="dx",$K6,$J6),0)) | ... Q44: =IF(Q$41=$B6,IF(Q$40="dx",-$K6,-$J6),IF(Q$41=$C6,IF(Q$40="dx",$K6,$J6),0)) | S44: =M6
...

Sheet Identyfikacja
B2: ATA Wyjściowy | R2: ST | W2: (ATA)-1 | AM2: ST(-1) | AQ2: X | AR2: m0 | AS2: mx
B3: {=_xlfn.ANCHORARRAY('Wyrównanie wstępne - wyjściowy'!B110)} | C3: -1321072 | D3: -727167.85 | E3: -1704466.7 | F3: 0 | G3: 0 | H3: 0 | I3: 0 | J3: 0 | K3: 0 | L3: -60305.207 | M3: 266348 | N3: -551395.99 | O3: 1785040.8 | P3: -2190966.5 | Q3: 974149.92 | R3: {=TRANSPOSE(B19:Q21)} | S3: 0 | T3: 0 | W3: {=MINVERSE(B3:T21)} | X3: 3.0503499e-07 | Y3: 8.0476354e-07 | Z3: 7.1121386e-07 | AA3: 2.9044386e-08 | AB3: 4.5835186e-07 | AC3: 7.5628589e-25 | AD3: 0 | AE3: -5.2969972e-08 | AF3: -2.1385782e-07 | AG3: 1.8340734e-07 | AH3: -1.3557894e-07 | AI3: -1.2827387e-07 | AJ3: -2.2116184e-07 | AK3: 4.9816519e-07 | AL3: 2.3757557e-07 | AM3: 1 | AN3: -6.5960762e-16 | AO3: 0.00058119464 | AQ3: {=-MMULT(W3:AL18,_xlfn.ANCHORARRAY('Wyrównanie wstępne - wyjściowy'!V110))} | AR3: ='Wyrównanie wstępne - wyjściowy'!AB131 | AS3: =SQRT(ROUND(W3,10))*$AR$3
B4: -1321072 | C4: 2986537.5 | D4: -142881.15 | E4: 556830.31 | F4: 0 | G4: 0 | H4: 0 | I4: 0 | J4: 0 | K4: 0 | L4: 266348 | M4: -1176370.3 | N4: 497031.57 | O4: -1166911.2 | P4: 700573.58 | Q4: -1200086.3 | R4: 0 | S4: 0 | T4: 0 | W4: 3.0503499e-07 | X4: 6.8049576e-07 | Y4: 2.767557e-07 | Z4: 2.8212662e-07 | AA4: -1.3430043e-08 | AB4: 1.7923364e-07 | AC4: -4.9659963e-25 | AD4: 0 | AE4: 6.7850241e-09 | AF4: 1.2180243e-07 | AG4: 6.1089864e-08 | AH4: 2.2813556e-07 | AI4: 1.378884e-07 | AJ4: 2.3773862e-07 | AK4: 8.2062481e-08 | AL4: 2.8615567e-07 | AM4: 4.2940048e-16 | AN4: 1 | AO4: -8.6393798e-05 | AQ4: 0.0010198994 | AS4: =SQRT(ROUND(X4,10))*$AR$3
B5: -727167.85 | C5: -142881.15 | D5: 1530177.5 | E5: 258472.98 | F5: 147487.77 | G5: 8701.1162 | H5: -206153.72 | I5: 280598.12 | J5: 0 | K5: 0 | L5: 0 | M5: 0 | N5: 0 | O5: 0 | P5: -744343.67 | Q5: -404891.06 | R5: 0 | S5: 0 | T5: 0 | W5: 8.0476354e-07 | X5: 2.767557e-07 | Y5: 1.234531e-06 | Z5: 4.754452e-07 | AA5: 4.2119237e-08 | AB5: 3.4002796e-07 | AC5: -1.6950924e-24 | AD5: 0 | AE5: -3.2546628e-08 | AF5: -1.303087e-07 | AG5: 1.6896215e-07 | AH5: -4.2844472e-08 | AI5: -3.8342344e-08 | AJ5: -6.610749e-08 | AK5: 4.0236917e-07 | AL5: 2.3924857e-07 | AM5: 1 | AN5: -3.9951618e-16 | AO5: 0.0003848451 | AQ5: 5.0089691e-05 | AS5: =SQRT(ROUND(Y5,10))*$AR$3
B6: -1704466.7 | C6: 556830.31 | D6: 258472.98 | E6: 4459685.7 | F6: 1204860.3 | G6: -1467478.2 | H6: 280598.12 | I6: -381925.22 | J6: 0 | K6: 0 | L6: 0 | M6: 0 | N6: 0 | O6: 0 | P6: -39464.619 | Q6: -3167112.6 | R6: 0 | S6: 0 | T6: 0 | W6: 7.1121386e-07 | X6: 2.8212662e-07 | Y6: 4.754452e-07 | Z6: 9.5235436e-07 | AA6: -1.1396677e-07 | AB6: 5.1928925e-07 | AC6: -3.1931846e-25 | AD6: 0 | AE6: -6.8177416e-08 | AF6: -4.3629493e-08 | AG6: 1.4097498e-07 | AH6: 4.0461408e-08 | AI6: 2.2906047e-08 | AJ6: 3.9493185e-08 | AK6: 3.0154083e-07 | AL6: 4.4320726e-07 | AM6: 1.4236539e-15 | AN6: 1 | AO6: 0.00028274334 | AQ6: 0.0013991059 | AS6: =SQRT(ROUND(Z6,10))*$AR$3
B7: 0 | C7: 0 | D7: 147487.77 | E7: 1204860.3 | F7: 3197552 | G7: -313305.71 | H7: -1228688.4 | I7: -445656.71 | J7: 0 | K7: 0 | L7: -606699.84 | M7: -118960.75 | N7: 0 | O7: 0 | P7: -1509651.6 | Q7: -326937.09 | R7: 0 | S7: 0 | T7: 0 | W7: 2.9044386e-08 | X7: -1.3430043e-08 | Y7: 4.2119237e-08 | Z7: -1.1396677e-07 | AA7: 4.2674811e-07 | AB7: 2.2800094e-08 | AC7: 1.2923634e-25 | AD7: 0 | AE7: 3.1575849e-08 | AF7: -5.1664134e-08 | AG7: 9.1816797e-08 | AH7: -1.4390688e-08 | AI7: 4.5111618e-09 | AJ7: 7.7778652e-09 | AK7: 1.1949721e-07 | AL7: -2.4740349e-08 | AM7: 1 | AN7: 0 | AO7: 8.6393798e-05 | AQ7: 0.00059326847 | AS7: =SQRT(ROUND(AA7,10))*$AR$3
B8: 0 | C8: 0 | D8: 8701.1162 | E8: -1467478.2 | F8: -313305.71 | G8: 3742624 | H8: 1453154.5 | I8: -1670577.4 | J8: 0 | K8: 0 | L8: -118960.75 | M8: -23325.638 | N8: 0 | O8: 0 | P8: -1029589.2 | Q8: -581242.71 | R8: 0 | S8: 0 | T8: 0 | W8: 4.5835186e-07 | X8: 1.7923364e-07 | Y8: 3.4002796e-07 | Z8: 5.1928925e-07 | AA8: 2.2800094e-08 | AB8: 5.9024536e-07 | AC8: 3.1992334e-24 | AD8: 0 | AE8: -3.0826013e-08 | AF8: -5.1702816e-08 | AG8: 1.3311119e-07 | AH8: 2.1377321e-08 | AI8: 2.0357266e-08 | AJ8: 3.5098734e-08 | AK8: 2.5856024e-07 | AL8: 2.7577385e-07 | AM8: 1.0220788e-15 | AN8: 1 | AO8: 0.00021991149 | AQ8: 0.0007324952 | AS8: =SQRT(ROUND(AB8,10))*$AR$3
B9: 0 | C9: 0 | D9: -206153.72 | E9: 280598.12 | F9: -1228688.4 | G9: 1453154.5 | H9: 6377052.1 | I9: 60080.069 | J9: -1392391.9 | K9: -1871079.4 | L9: -2467755.6 | M9: 153229.99 | N9: 0 | O9: 0 | P9: -1082062.5 | Q9: -75983.3 | R9: 1 | S9: 0 | T9: -1905.4767 | W9: -4.5691407e-23 | X9: 0 | Y9: 2.2845703e-23 | Z9: 1.8276563e-22 | AA9: -2.8557129e-23 | AB9: 2.2845703e-23 | AC9: -4.2737398e-24 | AD9: 0 | AE9: 2.2845703e-23 | AF9: -4.5691407e-23 | AG9: 4.5691407e-23 | AH9: 3.4268555e-23 | AI9: -9.1382814e-23 | AJ9: -2.0561133e-22 | AK9: 2.2845703e-23 | AL9: -1.0423352e-22 | AM9: 1 | AN9: -5.7968386e-17 | AO9: -5.6141612e-20 | AQ9: 1.7352572e-20 | AS9: =SQRT(ROUND(AC9,10))*$AR$3
B10: 0 | C10: 0 | D10: 280598.12 | E10: -381925.22 | F10: -445656.71 | G10: -1670577.4 | H10: 60080.069 | I10: 5042162.5 | J10: 206717.33 | K10: -1289173.1 | L10: 419604.13 | M10: -1351047.3 | N10: 0 | O10: 0 | P10: -521342.94 | Q10: -349439.44 | R10: 0 | S10: 1 | T10: 1105.1765 | W10: -2.9960929e-23 | X10: 6.741209e-23 | Y10: 0 | Z10: -2.9960929e-23 | AA10: -1.4980464e-23 | AB10: 8.9882786e-23 | AC10: 4.2939767e-24 | AD10: 0 | AE10: -1.4980464e-23 | AF10: -1.4980464e-23 | AG10: -7.4902322e-24 | AH10: 2.9960929e-23 | AI10: 0 | AJ10: 0 | AK10: -1.4980464e-23 | AL10: -1.4980464e-23 | AM10: 1.1128048e-17 | AN10: 1 | AO10: 7.0109116e-21 | AQ10: -1.1657132e-19 | AS10: =SQRT(ROUND(AD10,10))*$AR$3
B11: 0 | C11: 0 | D11: 0 | E11: 0 | F11: 0 | G11: 0 | H11: -1392391.9 | I11: 206717.33 | J11: 1701793.4 | K11: 7240.326 | L11: -834516.91 | M11: -668089.35 | N11: 333331.82 | O11: 14175.265 | P11: 191783.62 | Q11: 439956.42 | R11: 0 | S11: 0 | T11: 0 | W11: -5.2969972e-08 | X11: 6.7850241e-09 | Y11: -3.2546628e-08 | Z11: -6.8177416e-08 | AA11: 3.1575849e-08 | AB11: -3.0826013e-08 | AC11: 8.7343438e-24 | AD11: 0 | AE11: 6.6033256e-07 | AF11: 1.8384598e-08 | AG11: 7.53799e-08 | AH11: 7.2457265e-08 | AI11: 2.311642e-08 | AJ11: 3.9855897e-08 | AK11: -1.1109107e-08 | AL11: -4.2524288e-08 | AM11: 1 | AN11: 1.2601777e-16 | AO11: -0.00010995574 | AQ11: -1.5341974e-05 | AS11: =SQRT(ROUND(AE11,10))*$AR$3
B12: 0 | C12: 0 | D12: 0 | E12: 0 | F12: 0 | G12: 0 | H12: -1871079.4 | I12: -1289173.1 | J12: 7240.326 | K12: 3931596.8 | L12: 1048095.1 | M12: -1893001.6 | N12: 156700.7 | O12: -571436.67 | P12: 659043.25 | Q12: -177985.49 | R12: 0 | S12: 0 | T12: 0 | W12: -2.1385782e-07 | X12: 1.2180243e-07 | Y12: -1.303087e-07 | Z12: -4.3629493e-08 | AA12: -5.1664134e-08 | AB12: -5.1702816e-08 | AC12: -1.2669869e-25 | AD12: 0 | AE12: 1.8384598e-08 | AF12: 4.3250519e-07 | AG12: -7.9505397e-08 | AH12: 2.1745467e-07 | AI12: 1.1628424e-07 | AJ12: 2.0049007e-07 | AK12: -1.4671616e-07 | AL12: 7.056791e-08 | AM12: -5.2724016e-16 | AN12: 1 | AO12: -0.00023561945 | AQ12: 0.0010149922 | AS12: =SQRT(ROUND(AF12,10))*$AR$3
B13: -60305.207 | C13: 266348 | D13: 0 | E13: 0 | F13: -606699.84 | G13: -118960.75 | H13: -2467755.6 | I13: 419604.13 | J13: -834516.91 | K13: 1048095.1 | L13: 7233417.7 | M13: 183839.17 | N13: -641554.04 | O13: -1300053.6 | P13: -2622586.1 | Q13: -498872.06 | R13: 0 | S13: 0 | T13: 0 | W13: 1.8340734e-07 | X13: 6.1089864e-08 | Y13: 1.6896215e-07 | Z13: 1.4097498e-07 | AA13: 9.1816797e-08 | AB13: 1.3311119e-07 | AC13: 3.577432e-24 | AD13: 0 | AE13: 7.53799e-08 | AF13: -7.9505397e-08 | AG13: 2.5189016e-07 | AH13: 9.3777795e-09 | AI13: 3.7897138e-08 | AJ13: 6.5339893e-08 | AK13: 1.7323402e-07 | AL13: 9.5428646e-08 | AM13: 1 | AN13: -1.0772049e-18 | AO13: 0.00016493361 | AQ13: -0.00034235774 | AS13: =SQRT(ROUND(AG13,10))*$AR$3
B14: 266348 | C14: -1176370.3 | D14: 0 | E14: 0 | F14: -118960.75 | G14: -23325.638 | H14: 153229.99 | I14: -1351047.3 | J14: -668089.35 | K14: -1893001.6 | L14: 183839.17 | M14: 7842926.8 | N14: -227611.34 | O14: -2619099 | P14: 411244.28 | Q14: -780082.94 | R14: 0 | S14: 0 | T14: 0 | W14: -1.3557894e-07 | X14: 2.2813556e-07 | Y14: -4.2844472e-08 | Z14: 4.0461408e-08 | AA14: -1.4390688e-08 | AB14: 2.1377321e-08 | AC14: 2.7540752e-24 | AD14: 0 | AE14: 7.2457265e-08 | AF14: 2.1745467e-07 | AG14: 9.3777795e-09 | AH14: 3.448261e-07 | AI14: 1.6764025e-07 | AJ14: 2.8903491e-07 | AK14: -7.068108e-08 | AL14: 1.5205443e-07 | AM14: -8.3929667e-17 | AN14: 1 | AO14: -0.00018064158 | AQ14: 0.000629695 | AS14: =SQRT(ROUND(AH14,10))*$AR$3
B15: -551395.99 | C15: 497031.57 | D15: 0 | E15: 0 | F15: 0 | G15: 0 | H15: 0 | I15: 0 | J15: 333331.82 | K15: 156700.7 | L15: -641554.04 | M15: -227611.34 | N15: 1603418.2 | O15: -541984.55 | P15: -743800 | Q15: 115863.62 | R15: 0 | S15: 0 | T15: 1905.4767 | W15: -1.2827387e-07 | X15: 1.378884e-07 | Y15: -3.8342344e-08 | Z15: 2.2906047e-08 | AA15: 4.5111618e-09 | AB15: 2.0357266e-08 | AC15: -3.9483791e-24 | AD15: 0 | AE15: 2.311642e-08 | AF15: 1.1628424e-07 | AG15: 3.7897138e-08 | AH15: 1.6764025e-07 | AI15: 1.6554606e-07 | AJ15: 2.8542424e-07 | AK15: -3.3501923e-08 | AL15: 1.1510355e-07 | AM15: 1 | AN15: 1.4595713e-16 | AO15: 0.00039269908 | AQ15: -0.00018942142 | AS15: =SQRT(ROUND(AI15,10))*$AR$3
B16: 1785040.8 | C16: -1166911.2 | D16: 0 | E16: 0 | F16: 0 | G16: 0 | H16: 0 | I16: 0 | J16: 14175.265 | K16: -571436.67 | L16: -1300053.6 | M16: -2619099 | N16: -541984.55 | O16: 5683020.4 | P16: 42822.055 | Q16: -1325573.5 | R16: 0 | S16: 0 | T16: -1105.1765 | W16: -2.2116184e-07 | X16: 2.3773862e-07 | Y16: -6.610749e-08 | Z16: 3.9493185e-08 | AA16: 7.7778652e-09 | AB16: 3.5098734e-08 | AC16: -1.9069057e-24 | AD16: 0 | AE16: 3.9855897e-08 | AF16: 2.0049007e-07 | AG16: 6.5339893e-08 | AH16: 2.8903491e-07 | AI16: 2.8542424e-07 | AJ16: 4.9211076e-07 | AK16: -5.7761937e-08 | AL16: 1.984544e-07 | AM16: 4.973061e-17 | AN16: 1 | AO16: -0.00022776547 | AQ16: -0.00032658866 | AS16: =SQRT(ROUND(AJ16,10))*$AR$3
B17: -2190966.5 | C17: 700573.58 | D17: -744343.67 | E17: -39464.619 | F17: -1509651.6 | G17: -1029589.2 | H17: -1082062.5 | I17: -521342.94 | J17: 191783.62 | K17: 659043.25 | L17: -2622586.1 | M17: 411244.28 | N17: -743800 | O17: 42822.055 | P17: 8701626.8 | Q17: -223286.45 | R17: 0 | S17: 0 | T17: 0 | W17: 4.9816519e-07 | X17: 8.2062481e-08 | Y17: 4.0236917e-07 | Z17: 3.0154083e-07 | AA17: 1.1949721e-07 | AB17: 2.5856024e-07 | AC17: 4.8556681e-25 | AD17: 0 | AE17: -1.1109107e-08 | AF17: -1.4671616e-07 | AG17: 1.7323402e-07 | AH17: -7.068108e-08 | AI17: -3.3501923e-08 | AJ17: -5.7761937e-08 | AK17: 3.8838352e-07 | AL17: 1.2458864e-07 | AM17: 1 | AN17: -3.586757e-16 | AO17: 0.0003424336 | AQ17: -5.8500553e-05 | AS17: =SQRT(ROUND(AK17,10))*$AR$3
B18: 974149.92 | C18: -1200086.3 | D18: -404891.06 | E18: -3167112.6 | F18: -326937.09 | G18: -581242.71 | H18: -75983.3 | I18: -349439.44 | J18: 439956.42 | K18: -177985.49 | L18: -498872.06 | M18: -780082.94 | N18: 115863.62 | O18: -1325573.5 | P18: -223286.45 | Q18: 7581523 | R18: 0 | S18: 0 | T18: 0 | W18: 2.3757557e-07 | X18: 2.8615567e-07 | Y18: 2.3924857e-07 | Z18: 4.4320726e-07 | AA18: -2.4740349e-08 | AB18: 2.7577385e-07 | AC18: -3.4180089e-24 | AD18: 0 | AE18: -4.2524288e-08 | AF18: 7.056791e-08 | AG18: 9.5428646e-08 | AH18: 1.5205443e-07 | AI18: 1.1510355e-07 | AJ18: 1.984544e-07 | AK18: 1.2458864e-07 | AL18: 4.2732527e-07 | AM18: 7.7571281e-16 | AN18: 1 | AO18: 2.8274334e-05 | AQ18: 0.0010518508 | AS18: =SQRT(ROUND(AL18,10))*$AR$3
A19: S | B19: =IF(B$22=$B$49,IF(B$23="dx",1,0),0) | C19: =IF(C$22=$B$49,IF(C$23="dx",1,0),0) | D19: =IF(D$22=$B$49,IF(D$23="dx",1,0),0) | E19: =IF(E$22=$B$49,IF(E$23="dx",1,0),0) | F19: =IF(F$22=$B$49,IF(F$23="dx",1,0),0) | G19: =IF(G$22=$B$49,IF(G$23="dx",1,0),0) | H19: =IF(H$22=$B$49,IF(H$23="dx",1,0),0) | I19: =IF(I$22=$B$49,IF(I$23="dx",1,0),0) | ... Q19: =IF(Q$22=$B$49,IF(Q$23="dx",1,0),0) | R19: 0 | S19: 0 | T19: 0 | V19: S(-1) | W19: 1 | X19: 1.4210855e-16 | Y19: 1 | Z19: 8.5265128e-16 | AA19: 1 | AB19: 6.3948846e-16 | AC19: 1 | AD19: 0 | AE19: 1 | AF19: -2.8421709e-16 | AG19: 1 | AH19: 7.1054274e-17 | AI19: 1 | AJ19: 2.1316282e-16 | AK19: 1 | AL19: 4.9737992e-16 | AM19: 1.3969839e-09 | AN19: 8.3673513e-10 | AO19: 3.9025626e-13
B20: =IF(B$22=$B$49,IF(B$23="dy",1,0),0) | C20: =IF(C$22=$B$49,IF(C$23="dy",1,0),0) | D20: =IF(D$22=$B$49,IF(D$23="dy",1,0),0) | E20: =IF(E$22=$B$49,IF(E$23="dy",1,0),0) | F20: =IF(F$22=$B$49,IF(F$23="dy",1,0),0) | G20: =IF(G$22=$B$49,IF(G$23="dy",1,0),0) | H20: =IF(H$22=$B$49,IF(H$23="dy",1,0),0) | I20: =IF(I$22=$B$49,IF(I$23="dy",1,0),0) | ... Q20: =IF(Q$22=$B$49,IF(Q$23="dy",1,0),0) | R20: 0 | S20: 0 | T20: 0 | W20: 4.0112083e-16 | X20: 1 | Y20: 4.2316636e-16 | Z20: 1 | AA20: 1.4018348e-16 | AB20: 1 | AC20: -8.7366628e-33 | AD20: 1 | AE20: 2.0871177e-17 | AF20: 1 | AG20: 9.8292641e-17 | AH20: 1 | AI20: 3.1477145e-16 | AJ20: 1 | AK20: 1.9507306e-16 | AL20: 1 | AM20: 1.1641532e-09 | AN20: 1.7462298e-09 | AO20: -3.035555e-14
B21: =IF(B22=$B$49,IF(B23="dx",$H$49,$I$49),IF($B$50=B22,IF(B23="dx",-$H$49,-$I$49),0)) | C21: =IF(C22=$B$49,IF(C23="dx",$H$49,$I$49),IF($B$50=C22,IF(C23="dx",-$H$49,-$I$49),0)) | D21: =IF(D22=$B$49,IF(D23="dx",$H$49,$I$49),IF($B$50=D22,IF(D23="dx",-$H$49,-$I$49),0)) | E21: =IF(E22=$B$49,IF(E23="dx",$H$49,$I$49),IF($B$50=E22,IF(E23="dx",-$H$49,-$I$49),0)) | F21: =IF(F22=$B$49,IF(F23="dx",$H$49,$I$49),IF($B$50=F22,IF(F23="dx",-$H$49,-$I$49),0)) | G21: =IF(G22=$B$49,IF(G23="dx",$H$49,$I$49),IF($B$50=G22,IF(G23="dx",-$H$49,-$I$49),0)) | H21: =IF(H22=$B$49,IF(H23="dx",$H$49,$I$49),IF($B$50=H22,IF(H23="dx",-$H$49,-$I$49),0)) | I21: =IF(I22=$B$49,IF(I23="dx",$H$49,$I$49),IF($B$50=I22,IF(I23="dx",-$H$49,-$I$49),0)) | ... Q21: =IF(Q22=$B$49,IF(Q23="dx",$H$49,$I$49),IF($B$50=Q22,IF(Q23="dx",-$H$49,-$I$49),0)) | R21: 0 | S21: 0 | T21: 0 | W21: 0.00058119464 | X21: -8.6393798e-05 | Y21: 0.0003848451 | Z21: 0.00028274334 | AA21: 8.6393798e-05 | AB21: 0.00021991149 | AC21: -1.0899589e-20 | AD21: 0 | AE21: -0.00010995574 | AF21: -0.00023561945 | AG21: 0.00016493361 | AH21: -0.00018064158 | AI21: 0.00039269908 | AJ21: -0.00022776547 | AK21: 0.0003424336 | AL21: 2.8274334e-05 | AM21: 5.723667e-13 | AN21: -3.1967046e-13 | AO21: 2.1824207e-16
B22: 1 | C22: 1 | D22: 3 | E22: 3 | F22: 4 | G22: 4 | H22: 5 | I22: 5 | J22: 6 | K22: 6 | L22: 7 | M22: 7 | N22: 8 | O22: 8 | P22: 9 | Q22: 9
B23: dx | C23: dy | D23: dx | E23: dy | F23: dx | G23: dy | H23: dx | I23: dy | J23: dx | K23: dy | L23: dx | M23: dy | N23: dx | O23: dy | P23: dx | Q23: dy
B25: ATA Aktualny | R25: ST | W25: (ATA)-1 | AM25: ST(-1) | AQ25: X | AR25: m0 | AS25: mx
B26: {=_xlfn.ANCHORARRAY('Wyrównanie wstępne - aktualny'!B110)} | C26: -1452438.9 | D26: -2172492.4 | E26: -940496.29 | F26: 0 | G26: 0 | H26: 0 | I26: 0 | J26: 0 | K26: 0 | L26: -60305.753 | M26: 266350.41 | N26: -551394.9 | O26: 1785039.4 | P26: -997453.87 | Q26: 341545.46 | R26: {=TRANSPOSE(B42:Q44)} | S26: 0 | T26: 0 | W26: {=MINVERSE(B26:T44)} | X26: 3.0064997e-07 | Y26: 6.7088644e-07 | Z26: 4.9658943e-07 | AA26: 1.2676423e-08 | AB26: 4.097723e-07 | AC26: 0 | AD26: 0 | AE26: -4.6481555e-08 | AF26: -1.4248016e-07 | AG26: 1.4675437e-07 | AH26: -7.1980387e-08 | AI26: -7.7016247e-08 | AJ26: -1.3278663e-07 | AK26: 3.8049614e-07 | AL26: 2.4796676e-07 | AM26: 1 | AN26: -1.1698031e-15 | AO26: 0.00058119464 | AQ26: {=-MMULT(W26:AL41,_xlfn.ANCHORARRAY('Wyrównanie wstępne - aktualny'!V110))} | AR26: ='Wyrównanie wstępne - aktualny'!AB131 | AS26: =SQRT(ROUND(W26,10))*$AR$26
B27: -1452438.9 | C27: 2870935.3 | D27: 561691.44 | E27: 368638.03 | F27: 0 | G27: 0 | H27: 0 | I27: 0 | J27: 0 | K27: 0 | L27: 266350.41 | M27: -1176381 | N27: 497030.12 | O27: -1166909.3 | P27: 127366.98 | Q27: -896283.1 | R27: 0 | S27: 0 | T27: 0 | W27: 3.0064997e-07 | X27: 6.9198013e-07 | Y27: 1.6440885e-07 | Z27: 2.2906754e-07 | AA27: -1.9882289e-08 | AB27: 1.895575e-07 | AC27: 0 | AD27: 0 | AE27: 6.9646894e-09 | AF27: 1.273361e-07 | AG27: 5.9566595e-08 | AH27: 2.346938e-07 | AI27: 1.4220969e-07 | AJ27: 2.4518911e-07 | AK27: 7.7075745e-08 | AL27: 2.9109858e-07 | AM27: 2.4702836e-16 | AN27: 1 | AO27: -8.6393798e-05 | AQ27: 0.0056701107 | AS27: =SQRT(ROUND(X27,10))*AR26
B28: -2172492.4 | C28: 561691.44 | D28: 4685409.6 | E28: 1492344.1 | F28: 1037902.8 | G28: -889687.47 | H28: 0 | I28: 0 | J28: 0 | K28: 0 | L28: 0 | M28: 0 | N28: -547057.67 | O28: 221150.97 | P28: -3003762.3 | Q28: -1385499.1 | R28: 0 | S28: 0 | T28: 0 | W28: 6.7088644e-07 | X28: 1.6440885e-07 | Y28: 7.8561752e-07 | Z28: 2.4956128e-07 | AA28: -1.0080786e-08 | AB28: 3.6018676e-07 | AC28: 0 | AD28: 0 | AE28: -3.6424523e-08 | AF28: -1.1381465e-07 | AG28: 1.4882207e-07 | AH28: -4.304718e-08 | AI28: -2.7327167e-08 | AJ28: -4.7115805e-08 | AK28: 3.4698772e-07 | AL28: 2.3065135e-07 | AM28: 1 | AN28: -8.7143664e-16 | AO28: 0.00054192473 | AQ28: -0.002989333 | AS28: =SQRT(ROUND(Y28,10))*AR26
B29: -940496.29 | C29: 368638.03 | D29: 1492344.1 | E29: 2295146.8 | F29: 498233.78 | G29: -1027454.3 | H29: 0 | I29: 0 | J29: 0 | K29: 0 | L29: 0 | M29: 0 | N29: 221150.97 | O29: -89401.457 | P29: -1271232.6 | Q29: -1546929.1 | R29: 0 | S29: 0 | T29: 0 | W29: 4.9658943e-07 | X29: 2.2906754e-07 | Y29: 2.4956128e-07 | Z29: 1.1133599e-06 | AA29: -4.3061833e-08 | AB29: 5.1523618e-07 | AC29: 0 | AD29: 0 | AE29: -5.7524173e-08 | AF29: -1.4466105e-08 | AG29: 1.3845174e-07 | AH29: 6.995759e-08 | AI29: 5.4883488e-08 | AJ29: 9.4626703e-08 | AK29: 2.5445002e-07 | AL29: 4.3604736e-07 | AM29: 1.8330341e-16 | AN29: 1 | AO29: 0.00014137167 | AQ29: 0.0036007983 | AS29: =SQRT(ROUND(Z29,10))*AR26
B30: 0 | C30: 0 | D30: 1037902.8 | E30: 498233.78 | F30: 3185003.4 | G30: -71985.691 | H30: -1228679.7 | I30: -445660.11 | J30: 0 | K30: 0 | L30: -606688.38 | M30: -118958.51 | N30: 0 | O30: 0 | P30: -2387538.1 | Q30: 138370.52 | R30: 0 | S30: 0 | T30: 0 | W30: 1.2676423e-08 | X30: -1.9882289e-08 | Y30: -1.0080786e-08 | Z30: -4.3061833e-08 | AA30: 4.3273014e-07 | AB30: -2.1286316e-09 | AC30: 0 | AD30: 0 | AE30: 3.4986003e-08 | AF30: -5.4884616e-08 | AG30: 9.1132802e-08 | AH30: -1.8449967e-08 | AI30: 2.4793068e-09 | AJ30: 4.2746668e-09 | AK30: 1.2033015e-07 | AL30: -4.4050076e-08 | AM30: 1 | AN30: -6.9768898e-17 | AO30: 8.6393798e-05 | AQ30: 0.0078724888 | AS30: =SQRT(ROUND(AA30,10))*AR26
